Workbook
Name GlobalCompany: Input!$C$6
Name GlobalMethod: Input!$C$8
Name DefaultResidual: Input!$C$9
Name FirstFYEnd: Input!$C$10
Name ReportingFYEnd: Input!$C$11
Name ScheduleIITable: Input!$C$15:$H$32
Name AssetCategories: Input!$C$15:$C$32
Name ITBlockTable: Input!$B$36:$F$47
Name ITBlockList: Input!$B$36:$B$47
Name ITFYEnd: 'Income-Tax Dep Chart'!$E$5
Name TaxRate: 'Book vs Tax (Def. Tax)'!$F$5

Sheet Input
B2: FIXED ASSET REGISTER | CONTROL PANEL
B3: Companies Act, 2013 – Schedule II • Single switch drives the whole register
B5: A. GLOBAL PARAMETERS (edit the yellow cells)
B6: Company Name | C6: ABC Manufacturing Pvt. Ltd. | E6: ↳ free text
B7: Reporting Currency | C7: INR (Rs.) | E7: display only
B8: Depreciation Method (Global) | C8: WDV | E8: ↳ pick SLM or WDV — recalculates everything
B9: Default Residual Value % | C9: 0.05 | E9: ↳ 5% per Schedule II guidance
B10: First Financial Year End | C10: 44286 | E10: ↳ anchor for the year columns
B11: Reporting Financial Year End | C11: 45747 | E11: ↳ must equal one of the FY columns
B12: No. of Year Columns in FAR | C12: 16 | E12: ↳ informational
B13: B. ASSET MASTER – SCHEDULE II USEFUL LIVES + INCOME-TAX BLOCK MAPPING
B14: Sr. | C14: Asset Category | D14: Description / Notes | E14: Useful Life (Years) | F14: Indicative WDV Rate* | G14: Income-Tax Block | H14: IT Dep Rate
B15: 1 | C15: Buildings - RCC Frame | D15: Buildings other than factory (RCC frame) | E15: 60 | F15: =IF(E15=0,0,1-(DefaultResidual)^(1/E15)) | G15: Building (General/Non-residential) | H15: 0.1
B16: 2 | C16: Buildings - Other than RCC | D16: Buildings other than factory (non-RCC) | E16: 30 | F16: =IF(E16=0,0,1-(DefaultResidual)^(1/E16)) | G16: Building (General/Non-residential) | H16: 0.1
B17: 3 | C17: Factory Building | D17: Factory buildings | E17: 30 | F17: =IF(E17=0,0,1-(DefaultResidual)^(1/E17)) | G17: Building (General/Non-residential) | H17: 0.1
B18: 4 | C18: Plant & Machinery - General | D18: General rate plant & machinery | E18: 15 | F18: =IF(E18=0,0,1-(DefaultResidual)^(1/E18)) | G18: Plant & Machinery (General) | H18: 0.15
B19: 5 | C19: Plant & Machinery - Continuous Process | D19: Continuous process plant | E19: 25 | F19: =IF(E19=0,0,1-(DefaultResidual)^(1/E19)) | G19: Plant & Machinery (General) | H19: 0.15
B20: 6 | C20: Furniture & Fittings | D20: General furniture and fittings | E20: 10 | F20: =IF(E20=0,0,1-(DefaultResidual)^(1/E20)) | G20: Furniture & Fittings | H20: 0.1
B21: 7 | C21: Office Equipment | D21: General office equipment | E21: 5 | F21: =IF(E21=0,0,1-(DefaultResidual)^(1/E21)) | G21: Plant & Machinery (General) | H21: 0.15
B22: 8 | C22: Computers - End User Devices | D22: Laptops, desktops, printers | E22: 3 | F22: =IF(E22=0,0,1-(DefaultResidual)^(1/E22)) | G22: Computers & Software | H22: 0.4
B23: 9 | C23: Computers - Servers & Networks | D23: Servers and network equipment | E23: 6 | F23: =IF(E23=0,0,1-(DefaultResidual)^(1/E23)) | G23: Computers & Software | H23: 0.4
B24: 10 | C24: Electrical Installations | D24: Electrical installations & equipment | E24: 10 | F24: =IF(E24=0,0,1-(DefaultResidual)^(1/E24)) | G24: Plant & Machinery (General) | H24: 0.15
B25: 11 | C25: Motor Vehicles - Motor Cars | D25: Cars (other than used in hire business) | E25: 8 | F25: =IF(E25=0,0,1-(DefaultResidual)^(1/E25)) | G25: Motor Vehicles (Non-hire) | H25: 0.15
B26: 12 | C26: Motor Vehicles - Commercial | D26: Buses/lorries used in business of hire | E26: 6 | F26: =IF(E26=0,0,1-(DefaultResidual)^(1/E26)) | G26: Motor Vehicles (Hire/Commercial) | H26: 0.3
... B32: 18 | C32: Leasehold Improvements | D32: Over primary lease period (illustrative) | E32: 10 | F32: =IF(E32=0,0,1-(DefaultResidual)^(1/E32)) | G32: Building (General/Non-residential) | H32: 0.1
B33: *Companies Act indicative WDV rate = 1 − (Residual)^(1/Useful Life). The Income-Tax block & rate (Sec. 32 / Appendix I, WDV) drive the Income-Tax Depreciation Chart. Edit rows freely – FAR & charts follow.
B34: C. INCOME-TAX BLOCK OF ASSETS – WDV RATES (Sec. 32, Appendix I)
B35: Block of Assets | F35: WDV Rate
B36: Building (Residential) | F36: 0.05
B37: Building (General/Non-residential) | F37: 0.1
B38: Building (Temporary Structures) | F38: 0.4
B39: Furniture & Fittings | F39: 0.1
B40: Plant & Machinery (General) | F40: 0.15
B41: Plant & Machinery (Energy-saving/Pollution) | F41: 0.4
B42: Motor Vehicles (Non-hire) | F42: 0.15
B43: Motor Vehicles (Hire/Commercial) | F43: 0.3
B44: Computers & Software | F44: 0.4
B45: Intangible Assets | F45: 0.25
B46: Ships | F46: 0.2
B47: Books (annual publications / lending library) | F47: 0.4

Sheet FAR
A1: REGISTER OF FIXED ASSETS (FAR)
A2: =Input!C6&" | Depreciation Method: "&GlobalMethod&" | Reporting FY ending: "&TEXT(ReportingFYEnd,"dd-mmm-yyyy")&" | Default Residual: "&TEXT(DefaultResidual,"0%")&" | Companies Act, 2013 – Schedule II (see Income-Tax Chart sheet for Sec. 32)"
A3: ASSET MASTER DETAILS | J3: DISPOSAL | K3: COST & DEPRECIATION BASIS | R3: POSITION AS ON REPORTING FY | V3: EXTRA-SHIFT (SCH. II) & CARO 2020 COMPLIANCE | AA3: =EDATE(FirstFYEnd,12*0) | AC3: =EDATE(FirstFYEnd,12*1) | AE3: =EDATE(FirstFYEnd,12*2) | AG3: =EDATE(FirstFYEnd,12*3) | AI3: =EDATE(FirstFYEnd,12*4) | AK3: =EDATE(FirstFYEnd,12*5) | AM3: =EDATE(FirstFYEnd,12*6) | AO3: =EDATE(FirstFYEnd,12*7) | AQ3: =EDATE(FirstFYEnd,12*8) | AS3: =EDATE(FirstFYEnd,12*9) | AU3: =EDATE(FirstFYEnd,12*10) | AW3: =EDATE(FirstFYEnd,12*11) | AY3: =EDATE(FirstFYEnd,12*12) | BA3: =EDATE(FirstFYEnd,12*13) | BC3: =EDATE(FirstFYEnd,12*14) | BE3: =EDATE(FirstFYEnd,12*15)
A4: Asset ID | B4: Asset Description | C4: Asset Category | D4: Location / Cost Centre | E4: Supplier / Vendor | F4: Invoice No. | G4: Date of Purchase | H4: Date Put to Use | I4: Date of Sale / Disposal | J4: Sale Proceeds (Rs.) | K4: Gross Cost (Rs.) | L4: Residual % | M4: Residual Value (Rs.) | N4: Useful Life (Yrs) | O4: Method | P4: WDV Rate | Q4: Depreciable Amt (Rs.) | R4: Dep – Reporting FY (Rs.) | S4: Acc. Dep – Rep. FY (Rs.) | T4: WDV – Reporting FY (Rs.) | U4: Status | V4: Shift Basis | W4: Shift Factor | X4: Date of Physical Verif. | Y4: Title Deed in Co. Name? | Z4: Remarks / Components | AA4: ="Dep "&TEXT(EDATE(FirstFYEnd,12*0),"yyyy") | AB4: ="WDV "&TEXT(EDATE(FirstFYEnd,12*0),"yyyy") | AC4: ="Dep "&TEXT(EDATE(FirstFYEnd,12*1),"yyyy") | AD4: ="WDV "&TEXT(EDATE(FirstFYEnd,12*1),"yyyy") | AE4: ="Dep "&TEXT(EDATE(FirstFYEnd,12*2),"yyyy") | AF4: ="WDV "&TEXT(EDATE(FirstFYEnd,12*2),"yyyy") | AG4: ="Dep "&TEXT(EDATE(FirstFYEnd,12*3),"yyyy") | AH4: ="WDV "&TEXT(EDATE(FirstFYEnd,12*3),"yyyy") | AI4: ="Dep "&TEXT(EDATE(FirstFYEnd,12*4),"yyyy") | AJ4: ="WDV "&TEXT(EDATE(FirstFYEnd,12*4),"yyyy") | AK4: ="Dep "&TEXT(EDATE(FirstFYEnd,12*5),"yyyy") | AL4: ="WDV "&TEXT(EDATE(FirstFYEnd,12*5),"yyyy") | AM4: ="Dep "&TEXT(EDATE(FirstFYEnd,12*6),"yyyy") | AN4: ="WDV "&TEXT(EDATE(FirstFYEnd,12*6),"yyyy") | AO4: ="Dep "&TEXT(EDATE(FirstFYEnd,12*7),"yyyy") | AP4: ="WDV "&TEXT(EDATE(FirstFYEnd,12*7),"yyyy") | AQ4: ="Dep "&TEXT(EDATE(FirstFYEnd,12*8),"yyyy") | AR4: ="WDV "&TEXT(EDATE(FirstFYEnd,12*8),"yyyy") | AS4: ="Dep "&TEXT(EDATE(FirstFYEnd,12*9),"yyyy") | AT4: ="WDV "&TEXT(EDATE(FirstFYEnd,12*9),"yyyy") | AU4: ="Dep "&TEXT(EDATE(FirstFYEnd,12*10),"yyyy") | AV4: ="WDV "&TEXT(EDATE(FirstFYEnd,12*10),"yyyy") | AW4: ="Dep "&TEXT(EDATE(FirstFYEnd,12*11),"yyyy") | AX4: ="WDV "&TEXT(EDATE(FirstFYEnd,12*11),"yyyy") | AY4: ="Dep "&TEXT(EDATE(FirstFYEnd,12*12),"yyyy") | AZ4: ="WDV "&TEXT(EDATE(FirstFYEnd,12*12),"yyyy") | BA4: ="Dep "&TEXT(EDATE(FirstFYEnd,12*13),"yyyy") | BB4: ="WDV "&TEXT(EDATE(FirstFYEnd,12*13),"yyyy") | BC4: ="Dep "&TEXT(EDATE(FirstFYEnd,12*14),"yyyy") | BD4: ="WDV "&TEXT(EDATE(FirstFYEnd,12*14),"yyyy") | BE4: ="Dep "&TEXT(EDATE(FirstFYEnd,12*15),"yyyy") | BF4: ="WDV "&TEXT(EDATE(FirstFYEnd,12*15),"yyyy")
A5: FA-001 | B5: Head Office Building | C5: Buildings - RCC Frame | D5: Mumbai HO | E5: Skyline Constructions | F5: INV-HO-001 | G5: 43922 | H5: 43922 | K5: 50000000 | L5: =DefaultResidual | M5: =IF($K5="","",$K5*$L5) | N5: =IF($C5="","",IFERROR(VLOOKUP($C5,ScheduleIITable,3,FALSE),"#N/A")) | O5: =IF($K5="","",GlobalMethod) | P5: =IF(OR($K5="",$N5="",$N5=0,$M5=0),0,1-($M5/$K5)^(1/$N5)) | Q5: =IF($K5="","",$K5-$M5) | R5: =IF($K5="","",INDEX($AA5:$BF5,1,MATCH(ReportingFYEnd,$AA$3:$BF$3,0))) | S5: =IF($K5="","",IF($U5="Disposed",0,$K5-$T5)) | T5: =IF($K5="","",INDEX($AA5:$BF5,1,MATCH(ReportingFYEnd,$AA$3:$BF$3,0)+1)) | U5: =IF($K5="","",IF(AND($I5<>"",$I5<=ReportingFYEnd),"Disposed",IF(OR($H5="",$H5>ReportingFYEnd),"Not Yet in Use","Active"))) | V5: Single | W5: =IF($V5="Double",1.5,IF($V5="Triple",2,1)) | Y5: =IF($K5="","",IF(OR(ISNUMBER(SEARCH("Build",$C5)),ISNUMBER(SEARCH("Lease",$C5))),"Yes","NA")) | AA5: =IF(OR($K5="",$H5=""),"",MIN(MAX(0,IF($O5="WDV",$K5*$P5*MAX(0,(IF($I5="",AA$3,MIN($I5,AA$3)))-(MAX($H5,(EDATE(AA$3,-12)+1)))+1)/(AA$3-(EDATE(AA$3,-12)+1)+1),IF($N5=0,0,$Q5/$N5*MAX(0,(IF($I5="",AA$3,MIN($I5,AA$3)))-(MAX($H5,(EDATE(AA$3,-12)+1)))+1)/(AA$3-(EDATE(AA$3,-12)+1)+1)))*$W5),MAX(0,$K5-$M5))) | AB5: =IF($K5="","",IF(AND($I5<>"",$I5<=AA$3),0,$K5-AA5)) | AC5: =IF(OR($K5="",$H5=""),"",MIN(MAX(0,IF($O5="WDV",AB5*$P5*MAX(0,(IF($I5="",AC$3,MIN($I5,AC$3)))-(MAX($H5,(EDATE(AC$3,-12)+1)))+1)/(AC$3-(EDATE(AC$3,-12)+1)+1),IF($N5=0,0,$Q5/$N5*MAX(0,(IF($I5="",AC$3,MIN($I5,AC$3)))-(MAX($H5,(EDATE(AC$3,-12)+1)))+1)/(AC$3-(EDATE(AC$3,-12)+1)+1)))*$W5),MAX(0,AB5-$M5))) | AD5: =IF($K5="","",IF(AND($I5<>"",$I5<=AC$3),0,AB5-AC5)) | AE5: =IF(OR($K5="",$H5=""),"",MIN(MAX(0,IF($O5="WDV",AD5*$P5*MAX(0,(IF($I5="",AE$3,MIN($I5,AE$3)))-(MAX($H5,(EDATE(AE$3,-12)+1)))+1)/(AE$3-(EDATE(AE$3,-12)+1)+1),IF($N5=0,0,$Q5/$N5*MAX(0,(IF($I5="",AE$3,MIN($I5,AE$3)))-(MAX($H5,(EDATE(AE$3,-12)+1)))+1)/(AE$3-(EDATE(AE$3,-12)+1)+1)))*$W5),MAX(0,AD5-$M5))) | AF5: =IF($K5="","",IF(AND($I5<>"",$I5<=AE$3),0,AD5-AE5)) | AG5: =IF(OR($K5="",$H5=""),"",MIN(MAX(0,IF($O5="WDV",AF5*$P5*MAX(0,(IF($I5="",AG$3,MIN($I5,AG$3)))-(MAX($H5,(EDATE(AG$3,-12)+1)))+1)/(AG$3-(EDATE(AG$3,-12)+1)+1),IF($N5=0,0,$Q5/$N5*MAX(0,(IF($I5="",AG$3,MIN($I5,AG$3)))-(MAX($H5,(EDATE(AG$3,-12)+1)))+1)/(AG$3-(EDATE(AG$3,-12)+1)+1)))*$W5),MAX(0,AF5-$M5))) | AH5: =IF($K5="","",IF(AND($I5<>"",$I5<=AG$3),0,AF5-AG5)) | AI5: =IF(OR($K5="",$H5=""),"",MIN(MAX(0,IF($O5="WDV",AH5*$P5*MAX(0,(IF($I5="",AI$3,MIN($I5,AI$3)))-(MAX($H5,(EDATE(AI$3,-12)+1)))+1)/(AI$3-(EDATE(AI$3,-12)+1)+1),IF($N5=0,0,$Q5/$N5*MAX(0,(IF($I5="",AI$3,MIN($I5,AI$3)))-(MAX($H5,(EDATE(AI$3,-12)+1)))+1)/(AI$3-(EDATE(AI$3,-12)+1)+1)))*$W5),MAX(0,AH5-$M5))) | AJ5: =IF($K5="","",IF(AND($I5<>"",$I5<=AI$3),0,AH5-AI5)) | AK5: =IF(OR($K5="",$H5=""),"",MIN(MAX(0,IF($O5="WDV",AJ5*$P5*MAX(0,(IF($I5="",AK$3,MIN($I5,AK$3)))-(MAX($H5,(EDATE(AK$3,-12)+1)))+1)/(AK$3-(EDATE(AK$3,-12)+1)+1),IF($N5=0,0,$Q5/$N5*MAX(0,(IF($I5="",AK$3,MIN($I5,AK$3)))-(MAX($H5,(EDATE(AK$3,-12)+1)))+1)/(AK$3-(EDATE(AK$3,-12)+1)+1)))*$W5),MAX(0,AJ5-$M5))) | AL5: =IF($K5="","",IF(AND($I5<>"",$I5<=AK$3),0,AJ5-AK5)) | AM5: =IF(OR($K5="",$H5=""),"",MIN(MAX(0,IF($O5="WDV",AL5*$P5*MAX(0,(IF($I5="",AM$3,MIN($I5,AM$3)))-(MAX($H5,(EDATE(AM$3,-12)+1)))+1)/(AM$3-(EDATE(AM$3,-12)+1)+1),IF($N5=0,0,$Q5/$N5*MAX(0,(IF($I5="",AM$3,MIN($I5,AM$3)))-(MAX($H5,(EDATE(AM$3,-12)+1)))+1)/(AM$3-(EDATE(AM$3,-12)+1)+1)))*$W5),MAX(0,AL5-$M5))) | AN5: =IF($K5="","",IF(AND($I5<>"",$I5<=AM$3),0,AL5-AM5)) | AO5: =IF(OR($K5="",$H5=""),"",MIN(MAX(0,IF($O5="WDV",AN5*$P5*MAX(0,(IF($I5="",AO$3,MIN($I5,AO$3)))-(MAX($H5,(EDATE(AO$3,-12)+1)))+1)/(AO$3-(EDATE(AO$3,-12)+1)+1),IF($N5=0,0,$Q5/$N5*MAX(0,(IF($I5="",AO$3,MIN($I5,AO$3)))-(MAX($H5,(EDATE(AO$3,-12)+1)))+1)/(AO$3-(EDATE(AO$3,-12)+1)+1)))*$W5),MAX(0,AN5-$M5))) | AP5: =IF($K5="","",IF(AND($I5<>"",$I5<=AO$3),0,AN5-AO5)) | AQ5: =IF(OR($K5="",$H5=""),"",MIN(MAX(0,IF($O5="WDV",AP5*$P5*MAX(0,(IF($I5="",AQ$3,MIN($I5,AQ$3)))-(MAX($H5,(EDATE(AQ$3,-12)+1)))+1)/(AQ$3-(EDATE(AQ$3,-12)+1)+1),IF($N5=0,0,$Q5/$N5*MAX(0,(IF($I5="",AQ$3,MIN($I5,AQ$3)))-(MAX($H5,(EDATE(AQ$3,-12)+1)))+1)/(AQ$3-(EDATE(AQ$3,-12)+1)+1)))*$W5),MAX(0,AP5-$M5))) | AR5: =IF($K5="","",IF(AND($I5<>"",$I5<=AQ$3),0,AP5-AQ5)) | AS5: =IF(OR($K5="",$H5=""),"",MIN(MAX(0,IF($O5="WDV",AR5*$P5*MAX(0,(IF($I5="",AS$3,MIN($I5,AS$3)))-(MAX($H5,(EDATE(AS$3,-12)+1)))+1)/(AS$3-(EDATE(AS$3,-12)+1)+1),IF($N5=0,0,$Q5/$N5*MAX(0,(IF($I5="",AS$3,MIN($I5,AS$3)))-(MAX($H5,(EDATE(AS$3,-12)+1)))+1)/(AS$3-(EDATE(AS$3,-12)+1)+1)))*$W5),MAX(0,AR5-$M5))) | AT5: =IF($K5="","",IF(AND($I5<>"",$I5<=AS$3),0,AR5-AS5)) | AU5: =IF(OR($K5="",$H5=""),"",MIN(MAX(0,IF($O5="WDV",AT5*$P5*MAX(0,(IF($I5="",AU$3,MIN($I5,AU$3)))-(MAX($H5,(EDATE(AU$3,-12)+1)))+1)/(AU$3-(EDATE(AU$3,-12)+1)+1),IF($N5=0,0,$Q5/$N5*MAX(0,(IF($I5="",AU$3,MIN($I5,AU$3)))-(MAX($H5,(EDATE(AU$3,-12)+1)))+1)/(AU$3-(EDATE(AU$3,-12)+1)+1)))*$W5),MAX(0,AT5-$M5))) | AV5: =IF($K5="","",IF(AND($I5<>"",$I5<=AU$3),0,AT5-AU5)) | AW5: =IF(OR($K5="",$H5=""),"",MIN(MAX(0,IF($O5="WDV",AV5*$P5*MAX(0,(IF($I5="",AW$3,MIN($I5,AW$3)))-(MAX($H5,(EDATE(AW$3,-12)+1)))+1)/(AW$3-(EDATE(AW$3,-12)+1)+1),IF($N5=0,0,$Q5/$N5*MAX(0,(IF($I5="",AW$3,MIN($I5,AW$3)))-(MAX($H5,(EDATE(AW$3,-12)+1)))+1)/(AW$3-(EDATE(AW$3,-12)+1)+1)))*$W5),MAX(0,AV5-$M5))) | AX5: =IF($K5="","",IF(AND($I5<>"",$I5<=AW$3),0,AV5-AW5)) | AY5: =IF(OR($K5="",$H5=""),"",MIN(MAX(0,IF($O5="WDV",AX5*$P5*MAX(0,(IF($I5="",AY$3,MIN($I5,AY$3)))-(MAX($H5,(EDATE(AY$3,-12)+1)))+1)/(AY$3-(EDATE(AY$3,-12)+1)+1),IF($N5=0,0,$Q5/$N5*MAX(0,(IF($I5="",AY$3,MIN($I5,AY$3)))-(MAX($H5,(EDATE(AY$3,-12)+1)))+1)/(AY$3-(EDATE(AY$3,-12)+1)+1)))*$W5),MAX(0,AX5-$M5))) | AZ5: =IF($K5="","",IF(AND($I5<>"",$I5<=AY$3),0,AX5-AY5)) | BA5: =IF(OR($K5="",$H5=""),"",MIN(MAX(0,IF($O5="WDV",AZ5*$P5*MAX(0,(IF($I5="",BA$3,MIN($I5,BA$3)))-(MAX($H5,(EDATE(BA$3,-12)+1)))+1)/(BA$3-(EDATE(BA$3,-12)+1)+1),IF($N5=0,0,$Q5/$N5*MAX(0,(IF($I5="",BA$3,MIN($I5,BA$3)))-(MAX($H5,(EDATE(BA$3,-12)+1)))+1)/(BA$3-(EDATE(BA$3,-12)+1)+1)))*$W5),MAX(0,AZ5-$M5))) | BB5: =IF($K5="","",IF(AND($I5<>"",$I5<=BA$3),0,AZ5-BA5)) | BC5: =IF(OR($K5="",$H5=""),"",MIN(MAX(0,IF($O5="WDV",BB5*$P5*MAX(0,(IF($I5="",BC$3,MIN($I5,BC$3)))-(MAX($H5,(EDATE(BC$3,-12)+1)))+1)/(BC$3-(EDATE(BC$3,-12)+1)+1),IF($N5=0,0,$Q5/$N5*MAX(0,(IF($I5="",BC$3,MIN($I5,BC$3)))-(MAX($H5,(EDATE(BC$3,-12)+1)))+1)/(BC$3-(EDATE(BC$3,-12)+1)+1)))*$W5),MAX(0,BB5-$M5))) | BD5: =IF($K5="","",IF(AND($I5<>"",$I5<=BC$3),0,BB5-BC5)) | BE5: =IF(OR($K5="",$H5=""),"",MIN(MAX(0,IF($O5="WDV",BD5*$P5*MAX(0,(IF($I5="",BE$3,MIN($I5,BE$3)))-(MAX($H5,(EDATE(BE$3,-12)+1)))+1)/(BE$3-(EDATE(BE$3,-12)+1)+1),IF($N5=0,0,$Q5/$N5*MAX(0,(IF($I5="",BE$3,MIN($I5,BE$3)))-(MAX($H5,(EDATE(BE$3,-12)+1)))+1)/(BE$3-(EDATE(BE$3,-12)+1)+1)))*$W5),MAX(0,BD5-$M5))) | BF5: =IF($K5="","",IF(AND($I5<>"",$I5<=BE$3),0,BD5-BE5))
A6: FA-002 | B6: Factory Shed - Unit 1 | C6: Factory Building | D6: Pune Plant | E6: BuildWell Ltd | F6: INV-FB-014 | G6: 44027 | H6: 44044 | K6: 18000000 | L6: =DefaultResidual | M6: =IF($K6="","",$K6*$L6) | N6: =IF($C6="","",IFERROR(VLOOKUP($C6,ScheduleIITable,3,FALSE),"#N/A")) | O6: =IF($K6="","",GlobalMethod) | P6: =IF(OR($K6="",$N6="",$N6=0,$M6=0),0,1-($M6/$K6)^(1/$N6)) | Q6: =IF($K6="","",$K6-$M6) | R6: =IF($K6="","",INDEX($AA6:$BF6,1,MATCH(ReportingFYEnd,$AA$3:$BF$3,0))) | S6: =IF($K6="","",IF($U6="Disposed",0,$K6-$T6)) | T6: =IF($K6="","",INDEX($AA6:$BF6,1,MATCH(ReportingFYEnd,$AA$3:$BF$3,0)+1)) | U6: =IF($K6="","",IF(AND($I6<>"",$I6<=ReportingFYEnd),"Disposed",IF(OR($H6="",$H6>ReportingFYEnd),"Not Yet in Use","Active"))) | V6: Single | W6: =IF($V6="Double",1.5,IF($V6="Triple",2,1)) | Y6: =IF($K6="","",IF(OR(ISNUMBER(SEARCH("Build",$C6)),ISNUMBER(SEARCH("Lease",$C6))),"Yes","NA")) | AA6: =IF(OR($K6="",$H6=""),"",MIN(MAX(0,IF($O6="WDV",$K6*$P6*MAX(0,(IF($I6="",AA$3,MIN($I6,AA$3)))-(MAX($H6,(EDATE(AA$3,-12)+1)))+1)/(AA$3-(EDATE(AA$3,-12)+1)+1),IF($N6=0,0,$Q6/$N6*MAX(0,(IF($I6="",AA$3,MIN($I6,AA$3)))-(MAX($H6,(EDATE(AA$3,-12)+1)))+1)/(AA$3-(EDATE(AA$3,-12)+1)+1)))*$W6),MAX(0,$K6-$M6))) | AB6: =IF($K6="","",IF(AND($I6<>"",$I6<=AA$3),0,$K6-AA6)) | AC6: =IF(OR($K6="",$H6=""),"",MIN(MAX(0,IF($O6="WDV",AB6*$P6*MAX(0,(IF($I6="",AC$3,MIN($I6,AC$3)))-(MAX($H6,(EDATE(AC$3,-12)+1)))+1)/(AC$3-(EDATE(AC$3,-12)+1)+1),IF($N6=0,0,$Q6/$N6*MAX(0,(IF($I6="",AC$3,MIN($I6,AC$3)))-(MAX($H6,(EDATE(AC$3,-12)+1)))+1)/(AC$3-(EDATE(AC$3,-12)+1)+1)))*$W6),MAX(0,AB6-$M6))) | AD6: =IF($K6="","",IF(AND($I6<>"",$I6<=AC$3),0,AB6-AC6)) | AE6: =IF(OR($K6="",$H6=""),"",MIN(MAX(0,IF($O6="WDV",AD6*$P6*MAX(0,(IF($I6="",AE$3,MIN($I6,AE$3)))-(MAX($H6,(EDATE(AE$3,-12)+1)))+1)/(AE$3-(EDATE(AE$3,-12)+1)+1),IF($N6=0,0,$Q6/$N6*MAX(0,(IF($I6="",AE$3,MIN($I6,AE$3)))-(MAX($H6,(EDATE(AE$3,-12)+1)))+1)/(AE$3-(EDATE(AE$3,-12)+1)+1)))*$W6),MAX(0,AD6-$M6))) | AF6: =IF($K6="","",IF(AND($I6<>"",$I6<=AE$3),0,AD6-AE6)) | AG6: =IF(OR($K6="",$H6=""),"",MIN(MAX(0,IF($O6="WDV",AF6*$P6*MAX(0,(IF($I6="",AG$3,MIN($I6,AG$3)))-(MAX($H6,(EDATE(AG$3,-12)+1)))+1)/(AG$3-(EDATE(AG$3,-12)+1)+1),IF($N6=0,0,$Q6/$N6*MAX(0,(IF($I6="",AG$3,MIN($I6,AG$3)))-(MAX($H6,(EDATE(AG$3,-12)+1)))+1)/(AG$3-(EDATE(AG$3,-12)+1)+1)))*$W6),MAX(0,AF6-$M6))) | AH6: =IF($K6="","",IF(AND($I6<>"",$I6<=AG$3),0,AF6-AG6)) | AI6: =IF(OR($K6="",$H6=""),"",MIN(MAX(0,IF($O6="WDV",AH6*$P6*MAX(0,(IF($I6="",AI$3,MIN($I6,AI$3)))-(MAX($H6,(EDATE(AI$3,-12)+1)))+1)/(AI$3-(EDATE(AI$3,-12)+1)+1),IF($N6=0,0,$Q6/$N6*MAX(0,(IF($I6="",AI$3,MIN($I6,AI$3)))-(MAX($H6,(EDATE(AI$3,-12)+1)))+1)/(AI$3-(EDATE(AI$3,-12)+1)+1)))*$W6),MAX(0,AH6-$M6))) | AJ6: =IF($K6="","",IF(AND($I6<>"",$I6<=AI$3),0,AH6-AI6)) | AK6: =IF(OR($K6="",$H6=""),"",MIN(MAX(0,IF($O6="WDV",AJ6*$P6*MAX(0,(IF($I6="",AK$3,MIN($I6,AK$3)))-(MAX($H6,(EDATE(AK$3,-12)+1)))+1)/(AK$3-(EDATE(AK$3,-12)+1)+1),IF($N6=0,0,$Q6/$N6*MAX(0,(IF($I6="",AK$3,MIN($I6,AK$3)))-(MAX($H6,(EDATE(AK$3,-12)+1)))+1)/(AK$3-(EDATE(AK$3,-12)+1)+1)))*$W6),MAX(0,AJ6-$M6))) | AL6: =IF($K6="","",IF(AND($I6<>"",$I6<=AK$3),0,AJ6-AK6)) | AM6: =IF(OR($K6="",$H6=""),"",MIN(MAX(0,IF($O6="WDV",AL6*$P6*MAX(0,(IF($I6="",AM$3,MIN($I6,AM$3)))-(MAX($H6,(EDATE(AM$3,-12)+1)))+1)/(AM$3-(EDATE(AM$3,-12)+1)+1),IF($N6=0,0,$Q6/$N6*MAX(0,(IF($I6="",AM$3,MIN($I6,AM$3)))-(MAX($H6,(EDATE(AM$3,-12)+1)))+1)/(AM$3-(EDATE(AM$3,-12)+1)+1)))*$W6),MAX(0,AL6-$M6))) | AN6: =IF($K6="","",IF(AND($I6<>"",$I6<=AM$3),0,AL6-AM6)) | AO6: =IF(OR($K6="",$H6=""),"",MIN(MAX(0,IF($O6="WDV",AN6*$P6*MAX(0,(IF($I6="",AO$3,MIN($I6,AO$3)))-(MAX($H6,(EDATE(AO$3,-12)+1)))+1)/(AO$3-(EDATE(AO$3,-12)+1)+1),IF($N6=0,0,$Q6/$N6*MAX(0,(IF($I6="",AO$3,MIN($I6,AO$3)))-(MAX($H6,(EDATE(AO$3,-12)+1)))+1)/(AO$3-(EDATE(AO$3,-12)+1)+1)))*$W6),MAX(0,AN6-$M6))) | AP6: =IF($K6="","",IF(AND($I6<>"",$I6<=AO$3),0,AN6-AO6)) | AQ6: =IF(OR($K6="",$H6=""),"",MIN(MAX(0,IF($O6="WDV",AP6*$P6*MAX(0,(IF($I6="",AQ$3,MIN($I6,AQ$3)))-(MAX($H6,(EDATE(AQ$3,-12)+1)))+1)/(AQ$3-(EDATE(AQ$3,-12)+1)+1),IF($N6=0,0,$Q6/$N6*MAX(0,(IF($I6="",AQ$3,MIN($I6,AQ$3)))-(MAX($H6,(EDATE(AQ$3,-12)+1)))+1)/(AQ$3-(EDATE(AQ$3,-12)+1)+1)))*$W6),MAX(0,AP6-$M6))) | AR6: =IF($K6="","",IF(AND($I6<>"",$I6<=AQ$3),0,AP6-AQ6)) | AS6: =IF(OR($K6="",$H6=""),"",MIN(MAX(0,IF($O6="WDV",AR6*$P6*MAX(0,(IF($I6="",AS$3,MIN($I6,AS$3)))-(MAX($H6,(EDATE(AS$3,-12)+1)))+1)/(AS$3-(EDATE(AS$3,-12)+1)+1),IF($N6=0,0,$Q6/$N6*MAX(0,(IF($I6="",AS$3,MIN($I6,AS$3)))-(MAX($H6,(EDATE(AS$3,-12)+1)))+1)/(AS$3-(EDATE(AS$3,-12)+1)+1)))*$W6),MAX(0,AR6-$M6))) | AT6: =IF($K6="","",IF(AND($I6<>"",$I6<=AS$3),0,AR6-AS6)) | AU6: =IF(OR($K6="",$H6=""),"",MIN(MAX(0,IF($O6="WDV",AT6*$P6*MAX(0,(IF($I6="",AU$3,MIN($I6,AU$3)))-(MAX($H6,(EDATE(AU$3,-12)+1)))+1)/(AU$3-(EDATE(AU$3,-12)+1)+1),IF($N6=0,0,$Q6/$N6*MAX(0,(IF($I6="",AU$3,MIN($I6,AU$3)))-(MAX($H6,(EDATE(AU$3,-12)+1)))+1)/(AU$3-(EDATE(AU$3,-12)+1)+1)))*$W6),MAX(0,AT6-$M6))) | AV6: =IF($K6="","",IF(AND($I6<>"",$I6<=AU$3),0,AT6-AU6)) | AW6: =IF(OR($K6="",$H6=""),"",MIN(MAX(0,IF($O6="WDV",AV6*$P6*MAX(0,(IF($I6="",AW$3,MIN($I6,AW$3)))-(MAX($H6,(EDATE(AW$3,-12)+1)))+1)/(AW$3-(EDATE(AW$3,-12)+1)+1),IF($N6=0,0,$Q6/$N6*MAX(0,(IF($I6="",AW$3,MIN($I6,AW$3)))-(MAX($H6,(EDATE(AW$3,-12)+1)))+1)/(AW$3-(EDATE(AW$3,-12)+1)+1)))*$W6),MAX(0,AV6-$M6))) | AX6: =IF($K6="","",IF(AND($I6<>"",$I6<=AW$3),0,AV6-AW6)) | AY6: =IF(OR($K6="",$H6=""),"",MIN(MAX(0,IF($O6="WDV",AX6*$P6*MAX(0,(IF($I6="",AY$3,MIN($I6,AY$3)))-(MAX($H6,(EDATE(AY$3,-12)+1)))+1)/(AY$3-(EDATE(AY$3,-12)+1)+1),IF($N6=0,0,$Q6/$N6*MAX(0,(IF($I6="",AY$3,MIN($I6,AY$3)))-(MAX($H6,(EDATE(AY$3,-12)+1)))+1)/(AY$3-(EDATE(AY$3,-12)+1)+1)))*$W6),MAX(0,AX6-$M6))) | AZ6: =IF($K6="","",IF(AND($I6<>"",$I6<=AY$3),0,AX6-AY6)) | BA6: =IF(OR($K6="",$H6=""),"",MIN(MAX(0,IF($O6="WDV",AZ6*$P6*MAX(0,(IF($I6="",BA$3,MIN($I6,BA$3)))-(MAX($H6,(EDATE(BA$3,-12)+1)))+1)/(BA$3-(EDATE(BA$3,-12)+1)+1),IF($N6=0,0,$Q6/$N6*MAX(0,(IF($I6="",BA$3,MIN($I6,BA$3)))-(MAX($H6,(EDATE(BA$3,-12)+1)))+1)/(BA$3-(EDATE(BA$3,-12)+1)+1)))*$W6),MAX(0,AZ6-$M6))) | BB6: =IF($K6="","",IF(AND($I6<>"",$I6<=BA$3),0,AZ6-BA6)) | BC6: =IF(OR($K6="",$H6=""),"",MIN(MAX(0,IF($O6="WDV",BB6*$P6*MAX(0,(IF($I6="",BC$3,MIN($I6,BC$3)))-(MAX($H6,(EDATE(BC$3,-12)+1)))+1)/(BC$3-(EDATE(BC$3,-12)+1)+1),IF($N6=0,0,$Q6/$N6*MAX(0,(IF($I6="",BC$3,MIN($I6,BC$3)))-(MAX($H6,(EDATE(BC$3,-12)+1)))+1)/(BC$3-(EDATE(BC$3,-12)+1)+1)))*$W6),MAX(0,BB6-$M6))) | BD6: =IF($K6="","",IF(AND($I6<>"",$I6<=BC$3),0,BB6-BC6)) | BE6: =IF(OR($K6="",$H6=""),"",MIN(MAX(0,IF($O6="WDV",BD6*$P6*MAX(0,(IF($I6="",BE$3,MIN($I6,BE$3)))-(MAX($H6,(EDATE(BE$3,-12)+1)))+1)/(BE$3-(EDATE(BE$3,-12)+1)+1),IF($N6=0,0,$Q6/$N6*MAX(0,(IF($I6="",BE$3,MIN($I6,BE$3)))-(MAX($H6,(EDATE(BE$3,-12)+1)))+1)/(BE$3-(EDATE(BE$3,-12)+1)+1)))*$W6),MAX(0,BD6-$M6))) | BF6: =IF($K6="","",IF(AND($I6<>"",$I6<=BE$3),0,BD6-BE6))
A7: FA-003 | B7: CNC Machine | C7: Plant & Machinery - General | D7: Pune Plant | E7: TechMach India | F7: INV-PM-203 | G7: 44326 | H7: 44348 | K7: 6500000 | L7: =DefaultResidual | M7: =IF($K7="","",$K7*$L7) | N7: =IF($C7="","",IFERROR(VLOOKUP($C7,ScheduleIITable,3,FALSE),"#N/A")) | O7: =IF($K7="","",GlobalMethod) | P7: =IF(OR($K7="",$N7="",$N7=0,$M7=0),0,1-($M7/$K7)^(1/$N7)) | Q7: =IF($K7="","",$K7-$M7) | R7: =IF($K7="","",INDEX($AA7:$BF7,1,MATCH(ReportingFYEnd,$AA$3:$BF$3,0))) | S7: =IF($K7="","",IF($U7="Disposed",0,$K7-$T7)) | T7: =IF($K7="","",INDEX($AA7:$BF7,1,MATCH(ReportingFYEnd,$AA$3:$BF$3,0)+1)) | U7: =IF($K7="","",IF(AND($I7<>"",$I7<=ReportingFYEnd),"Disposed",IF(OR($H7="",$H7>ReportingFYEnd),"Not Yet in Use","Active"))) | V7: Single | W7: =IF($V7="Double",1.5,IF($V7="Triple",2,1)) | Y7: =IF($K7="","",IF(OR(ISNUMBER(SEARCH("Build",$C7)),ISNUMBER(SEARCH("Lease",$C7))),"Yes","NA")) | AA7: =IF(OR($K7="",$H7=""),"",MIN(MAX(0,IF($O7="WDV",$K7*$P7*MAX(0,(IF($I7="",AA$3,MIN($I7,AA$3)))-(MAX($H7,(EDATE(AA$3,-12)+1)))+1)/(AA$3-(EDATE(AA$3,-12)+1)+1),IF($N7=0,0,$Q7/$N7*MAX(0,(IF($I7="",AA$3,MIN($I7,AA$3)))-(MAX($H7,(EDATE(AA$3,-12)+1)))+1)/(AA$3-(EDATE(AA$3,-12)+1)+1)))*$W7),MAX(0,$K7-$M7))) | AB7: =IF($K7="","",IF(AND($I7<>"",$I7<=AA$3),0,$K7-AA7)) | AC7: =IF(OR($K7="",$H7=""),"",MIN(MAX(0,IF($O7="WDV",AB7*$P7*MAX(0,(IF($I7="",AC$3,MIN($I7,AC$3)))-(MAX($H7,(EDATE(AC$3,-12)+1)))+1)/(AC$3-(EDATE(AC$3,-12)+1)+1),IF($N7=0,0,$Q7/$N7*MAX(0,(IF($I7="",AC$3,MIN($I7,AC$3)))-(MAX($H7,(EDATE(AC$3,-12)+1)))+1)/(AC$3-(EDATE(AC$3,-12)+1)+1)))*$W7),MAX(0,AB7-$M7))) | AD7: =IF($K7="","",IF(AND($I7<>"",$I7<=AC$3),0,AB7-AC7)) | AE7: =IF(OR($K7="",$H7=""),"",MIN(MAX(0,IF($O7="WDV",AD7*$P7*MAX(0,(IF($I7="",AE$3,MIN($I7,AE$3)))-(MAX($H7,(EDATE(AE$3,-12)+1)))+1)/(AE$3-(EDATE(AE$3,-12)+1)+1),IF($N7=0,0,$Q7/$N7*MAX(0,(IF($I7="",AE$3,MIN($I7,AE$3)))-(MAX($H7,(EDATE(AE$3,-12)+1)))+1)/(AE$3-(EDATE(AE$3,-12)+1)+1)))*$W7),MAX(0,AD7-$M7))) | AF7: =IF($K7="","",IF(AND($I7<>"",$I7<=AE$3),0,AD7-AE7)) | AG7: =IF(OR($K7="",$H7=""),"",MIN(MAX(0,IF($O7="WDV",AF7*$P7*MAX(0,(IF($I7="",AG$3,MIN($I7,AG$3)))-(MAX($H7,(EDATE(AG$3,-12)+1)))+1)/(AG$3-(EDATE(AG$3,-12)+1)+1),IF($N7=0,0,$Q7/$N7*MAX(0,(IF($I7="",AG$3,MIN($I7,AG$3)))-(MAX($H7,(EDATE(AG$3,-12)+1)))+1)/(AG$3-(EDATE(AG$3,-12)+1)+1)))*$W7),MAX(0,AF7-$M7))) | AH7: =IF($K7="","",IF(AND($I7<>"",$I7<=AG$3),0,AF7-AG7)) | AI7: =IF(OR($K7="",$H7=""),"",MIN(MAX(0,IF($O7="WDV",AH7*$P7*MAX(0,(IF($I7="",AI$3,MIN($I7,AI$3)))-(MAX($H7,(EDATE(AI$3,-12)+1)))+1)/(AI$3-(EDATE(AI$3,-12)+1)+1),IF($N7=0,0,$Q7/$N7*MAX(0,(IF($I7="",AI$3,MIN($I7,AI$3)))-(MAX($H7,(EDATE(AI$3,-12)+1)))+1)/(AI$3-(EDATE(AI$3,-12)+1)+1)))*$W7),MAX(0,AH7-$M7))) | AJ7: =IF($K7="","",IF(AND($I7<>"",$I7<=AI$3),0,AH7-AI7)) | AK7: =IF(OR($K7="",$H7=""),"",MIN(MAX(0,IF($O7="WDV",AJ7*$P7*MAX(0,(IF($I7="",AK$3,MIN($I7,AK$3)))-(MAX($H7,(EDATE(AK$3,-12)+1)))+1)/(AK$3-(EDATE(AK$3,-12)+1)+1),IF($N7=0,0,$Q7/$N7*MAX(0,(IF($I7="",AK$3,MIN($I7,AK$3)))-(MAX($H7,(EDATE(AK$3,-12)+1)))+1)/(AK$3-(EDATE(AK$3,-12)+1)+1)))*$W7),MAX(0,AJ7-$M7))) | AL7: =IF($K7="","",IF(AND($I7<>"",$I7<=AK$3),0,AJ7-AK7)) | AM7: =IF(OR($K7="",$H7=""),"",MIN(MAX(0,IF($O7="WDV",AL7*$P7*MAX(0,(IF($I7="",AM$3,MIN($I7,AM$3)))-(MAX($H7,(EDATE(AM$3,-12)+1)))+1)/(AM$3-(EDATE(AM$3,-12)+1)+1),IF($N7=0,0,$Q7/$N7*MAX(0,(IF($I7="",AM$3,MIN($I7,AM$3)))-(MAX($H7,(EDATE(AM$3,-12)+1)))+1)/(AM$3-(EDATE(AM$3,-12)+1)+1)))*$W7),MAX(0,AL7-$M7))) | AN7: =IF($K7="","",IF(AND($I7<>"",$I7<=AM$3),0,AL7-AM7)) | AO7: =IF(OR($K7="",$H7=""),"",MIN(MAX(0,IF($O7="WDV",AN7*$P7*MAX(0,(IF($I7="",AO$3,MIN($I7,AO$3)))-(MAX($H7,(EDATE(AO$3,-12)+1)))+1)/(AO$3-(EDATE(AO$3,-12)+1)+1),IF($N7=0,0,$Q7/$N7*MAX(0,(IF($I7="",AO$3,MIN($I7,AO$3)))-(MAX($H7,(EDATE(AO$3,-12)+1)))+1)/(AO$3-(EDATE(AO$3,-12)+1)+1)))*$W7),MAX(0,AN7-$M7))) | AP7: =IF($K7="","",IF(AND($I7<>"",$I7<=AO$3),0,AN7-AO7)) | AQ7: =IF(OR($K7="",$H7=""),"",MIN(MAX(0,IF($O7="WDV",AP7*$P7*MAX(0,(IF($I7="",AQ$3,MIN($I7,AQ$3)))-(MAX($H7,(EDATE(AQ$3,-12)+1)))+1)/(AQ$3-(EDATE(AQ$3,-12)+1)+1),IF($N7=0,0,$Q7/$N7*MAX(0,(IF($I7="",AQ$3,MIN($I7,AQ$3)))-(MAX($H7,(EDATE(AQ$3,-12)+1)))+1)/(AQ$3-(EDATE(AQ$3,-12)+1)+1)))*$W7),MAX(0,AP7-$M7))) | AR7: =IF($K7="","",IF(AND($I7<>"",$I7<=AQ$3),0,AP7-AQ7)) | AS7: =IF(OR($K7="",$H7=""),"",MIN(MAX(0,IF($O7="WDV",AR7*$P7*MAX(0,(IF($I7="",AS$3,MIN($I7,AS$3)))-(MAX($H7,(EDATE(AS$3,-12)+1)))+1)/(AS$3-(EDATE(AS$3,-12)+1)+1),IF($N7=0,0,$Q7/$N7*MAX(0,(IF($I7="",AS$3,MIN($I7,AS$3)))-(MAX($H7,(EDATE(AS$3,-12)+1)))+1)/(AS$3-(EDATE(AS$3,-12)+1)+1)))*$W7),MAX(0,AR7-$M7))) | AT7: =IF($K7="","",IF(AND($I7<>"",$I7<=AS$3),0,AR7-AS7)) | AU7: =IF(OR($K7="",$H7=""),"",MIN(MAX(0,IF($O7="WDV",AT7*$P7*MAX(0,(IF($I7="",AU$3,MIN($I7,AU$3)))-(MAX($H7,(EDATE(AU$3,-12)+1)))+1)/(AU$3-(EDATE(AU$3,-12)+1)+1),IF($N7=0,0,$Q7/$N7*MAX(0,(IF($I7="",AU$3,MIN($I7,AU$3)))-(MAX($H7,(EDATE(AU$3,-12)+1)))+1)/(AU$3-(EDATE(AU$3,-12)+1)+1)))*$W7),MAX(0,AT7-$M7))) | AV7: =IF($K7="","",IF(AND($I7<>"",$I7<=AU$3),0,AT7-AU7)) | AW7: =IF(OR($K7="",$H7=""),"",MIN(MAX(0,IF($O7="WDV",AV7*$P7*MAX(0,(IF($I7="",AW$3,MIN($I7,AW$3)))-(MAX($H7,(EDATE(AW$3,-12)+1)))+1)/(AW$3-(EDATE(AW$3,-12)+1)+1),IF($N7=0,0,$Q7/$N7*MAX(0,(IF($I7="",AW$3,MIN($I7,AW$3)))-(MAX($H7,(EDATE(AW$3,-12)+1)))+1)/(AW$3-(EDATE(AW$3,-12)+1)+1)))*$W7),MAX(0,AV7-$M7))) | AX7: =IF($K7="","",IF(AND($I7<>"",$I7<=AW$3),0,AV7-AW7)) | AY7: =IF(OR($K7="",$H7=""),"",MIN(MAX(0,IF($O7="WDV",AX7*$P7*MAX(0,(IF($I7="",AY$3,MIN($I7,AY$3)))-(MAX($H7,(EDATE(AY$3,-12)+1)))+1)/(AY$3-(EDATE(AY$3,-12)+1)+1),IF($N7=0,0,$Q7/$N7*MAX(0,(IF($I7="",AY$3,MIN($I7,AY$3)))-(MAX($H7,(EDATE(AY$3,-12)+1)))+1)/(AY$3-(EDATE(AY$3,-12)+1)+1)))*$W7),MAX(0,AX7-$M7))) | AZ7: =IF($K7="","",IF(AND($I7<>"",$I7<=AY$3),0,AX7-AY7)) | BA7: =IF(OR($K7="",$H7=""),"",MIN(MAX(0,IF($O7="WDV",AZ7*$P7*MAX(0,(IF($I7="",BA$3,MIN($I7,BA$3)))-(MAX($H7,(EDATE(BA$3,-12)+1)))+1)/(BA$3-(EDATE(BA$3,-12)+1)+1),IF($N7=0,0,$Q7/$N7*MAX(0,(IF($I7="",BA$3,MIN($I7,BA$3)))-(MAX($H7,(EDATE(BA$3,-12)+1)))+1)/(BA$3-(EDATE(BA$3,-12)+1)+1)))*$W7),MAX(0,AZ7-$M7))) | BB7: =IF($K7="","",IF(AND($I7<>"",$I7<=BA$3),0,AZ7-BA7)) | BC7: =IF(OR($K7="",$H7=""),"",MIN(MAX(0,IF($O7="WDV",BB7*$P7*MAX(0,(IF($I7="",BC$3,MIN($I7,BC$3)))-(MAX($H7,(EDATE(BC$3,-12)+1)))+1)/(BC$3-(EDATE(BC$3,-12)+1)+1),IF($N7=0,0,$Q7/$N7*MAX(0,(IF($I7="",BC$3,MIN($I7,BC$3)))-(MAX($H7,(EDATE(BC$3,-12)+1)))+1)/(BC$3-(EDATE(BC$3,-12)+1)+1)))*$W7),MAX(0,BB7-$M7))) | BD7: =IF($K7="","",IF(AND($I7<>"",$I7<=BC$3),0,BB7-BC7)) | BE7: =IF(OR($K7="",$H7=""),"",MIN(MAX(0,IF($O7="WDV",BD7*$P7*MAX(0,(IF($I7="",BE$3,MIN($I7,BE$3)))-(MAX($H7,(EDATE(BE$3,-12)+1)))+1)/(BE$3-(EDATE(BE$3,-12)+1)+1),IF($N7=0,0,$Q7/$N7*MAX(0,(IF($I7="",BE$3,MIN($I7,BE$3)))-(MAX($H7,(EDATE(BE$3,-12)+1)))+1)/(BE$3-(EDATE(BE$3,-12)+1)+1)))*$W7),MAX(0,BD7-$M7))) | BF7: =IF($K7="","",IF(AND($I7<>"",$I7<=BE$3),0,BD7-BE7))
A8: FA-004 | B8: Office Furniture (lot) | C8: Furniture & Fittings | D8: Mumbai HO | E8: Featherlite | F8: INV-FF-099 | G8: 44306 | H8: 44306 | K8: 850000 | L8: =DefaultResidual | M8: =IF($K8="","",$K8*$L8) | N8: =IF($C8="","",IFERROR(VLOOKUP($C8,ScheduleIITable,3,FALSE),"#N/A")) | O8: =IF($K8="","",GlobalMethod) | P8: =IF(OR($K8="",$N8="",$N8=0,$M8=0),0,1-($M8/$K8)^(1/$N8)) | Q8: =IF($K8="","",$K8-$M8) | R8: =IF($K8="","",INDEX($AA8:$BF8,1,MATCH(ReportingFYEnd,$AA$3:$BF$3,0))) | S8: =IF($K8="","",IF($U8="Disposed",0,$K8-$T8)) | T8: =IF($K8="","",INDEX($AA8:$BF8,1,MATCH(ReportingFYEnd,$AA$3:$BF$3,0)+1)) | U8: =IF($K8="","",IF(AND($I8<>"",$I8<=ReportingFYEnd),"Disposed",IF(OR($H8="",$H8>ReportingFYEnd),"Not Yet in Use","Active"))) | V8: Single | W8: =IF($V8="Double",1.5,IF($V8="Triple",2,1)) | Y8: =IF($K8="","",IF(OR(ISNUMBER(SEARCH("Build",$C8)),ISNUMBER(SEARCH("Lease",$C8))),"Yes","NA")) | AA8: =IF(OR($K8="",$H8=""),"",MIN(MAX(0,IF($O8="WDV",$K8*$P8*MAX(0,(IF($I8="",AA$3,MIN($I8,AA$3)))-(MAX($H8,(EDATE(AA$3,-12)+1)))+1)/(AA$3-(EDATE(AA$3,-12)+1)+1),IF($N8=0,0,$Q8/$N8*MAX(0,(IF($I8="",AA$3,MIN($I8,AA$3)))-(MAX($H8,(EDATE(AA$3,-12)+1)))+1)/(AA$3-(EDATE(AA$3,-12)+1)+1)))*$W8),MAX(0,$K8-$M8))) | AB8: =IF($K8="","",IF(AND($I8<>"",$I8<=AA$3),0,$K8-AA8)) | AC8: =IF(OR($K8="",$H8=""),"",MIN(MAX(0,IF($O8="WDV",AB8*$P8*MAX(0,(IF($I8="",AC$3,MIN($I8,AC$3)))-(MAX($H8,(EDATE(AC$3,-12)+1)))+1)/(AC$3-(EDATE(AC$3,-12)+1)+1),IF($N8=0,0,$Q8/$N8*MAX(0,(IF($I8="",AC$3,MIN($I8,AC$3)))-(MAX($H8,(EDATE(AC$3,-12)+1)))+1)/(AC$3-(EDATE(AC$3,-12)+1)+1)))*$W8),MAX(0,AB8-$M8))) | AD8: =IF($K8="","",IF(AND($I8<>"",$I8<=AC$3),0,AB8-AC8)) | AE8: =IF(OR($K8="",$H8=""),"",MIN(MAX(0,IF($O8="WDV",AD8*$P8*MAX(0,(IF($I8="",AE$3,MIN($I8,AE$3)))-(MAX($H8,(EDATE(AE$3,-12)+1)))+1)/(AE$3-(EDATE(AE$3,-12)+1)+1),IF($N8=0,0,$Q8/$N8*MAX(0,(IF($I8="",AE$3,MIN($I8,AE$3)))-(MAX($H8,(EDATE(AE$3,-12)+1)))+1)/(AE$3-(EDATE(AE$3,-12)+1)+1)))*$W8),MAX(0,AD8-$M8))) | AF8: =IF($K8="","",IF(AND($I8<>"",$I8<=AE$3),0,AD8-AE8)) | AG8: =IF(OR($K8="",$H8=""),"",MIN(MAX(0,IF($O8="WDV",AF8*$P8*MAX(0,(IF($I8="",AG$3,MIN($I8,AG$3)))-(MAX($H8,(EDATE(AG$3,-12)+1)))+1)/(AG$3-(EDATE(AG$3,-12)+1)+1),IF($N8=0,0,$Q8/$N8*MAX(0,(IF($I8="",AG$3,MIN($I8,AG$3)))-(MAX($H8,(EDATE(AG$3,-12)+1)))+1)/(AG$3-(EDATE(AG$3,-12)+1)+1)))*$W8),MAX(0,AF8-$M8))) | AH8: =IF($K8="","",IF(AND($I8<>"",$I8<=AG$3),0,AF8-AG8)) | AI8: =IF(OR($K8="",$H8=""),"",MIN(MAX(0,IF($O8="WDV",AH8*$P8*MAX(0,(IF($I8="",AI$3,MIN($I8,AI$3)))-(MAX($H8,(EDATE(AI$3,-12)+1)))+1)/(AI$3-(EDATE(AI$3,-12)+1)+1),IF($N8=0,0,$Q8/$N8*MAX(0,(IF($I8="",AI$3,MIN($I8,AI$3)))-(MAX($H8,(EDATE(AI$3,-12)+1)))+1)/(AI$3-(EDATE(AI$3,-12)+1)+1)))*$W8),MAX(0,AH8-$M8))) | AJ8: =IF($K8="","",IF(AND($I8<>"",$I8<=AI$3),0,AH8-AI8)) | AK8: =IF(OR($K8="",$H8=""),"",MIN(MAX(0,IF($O8="WDV",AJ8*$P8*MAX(0,(IF($I8="",AK$3,MIN($I8,AK$3)))-(MAX($H8,(EDATE(AK$3,-12)+1)))+1)/(AK$3-(EDATE(AK$3,-12)+1)+1),IF($N8=0,0,$Q8/$N8*MAX(0,(IF($I8="",AK$3,MIN($I8,AK$3)))-(MAX($H8,(EDATE(AK$3,-12)+1)))+1)/(AK$3-(EDATE(AK$3,-12)+1)+1)))*$W8),MAX(0,AJ8-$M8))) | AL8: =IF($K8="","",IF(AND($I8<>"",$I8<=AK$3),0,AJ8-AK8)) | AM8: =IF(OR($K8="",$H8=""),"",MIN(MAX(0,IF($O8="WDV",AL8*$P8*MAX(0,(IF($I8="",AM$3,MIN($I8,AM$3)))-(MAX($H8,(EDATE(AM$3,-12)+1)))+1)/(AM$3-(EDATE(AM$3,-12)+1)+1),IF($N8=0,0,$Q8/$N8*MAX(0,(IF($I8="",AM$3,MIN($I8,AM$3)))-(MAX($H8,(EDATE(AM$3,-12)+1)))+1)/(AM$3-(EDATE(AM$3,-12)+1)+1)))*$W8),MAX(0,AL8-$M8))) | AN8: =IF($K8="","",IF(AND($I8<>"",$I8<=AM$3),0,AL8-AM8)) | AO8: =IF(OR($K8="",$H8=""),"",MIN(MAX(0,IF($O8="WDV",AN8*$P8*MAX(0,(IF($I8="",AO$3,MIN($I8,AO$3)))-(MAX($H8,(EDATE(AO$3,-12)+1)))+1)/(AO$3-(EDATE(AO$3,-12)+1)+1),IF($N8=0,0,$Q8/$N8*MAX(0,(IF($I8="",AO$3,MIN($I8,AO$3)))-(MAX($H8,(EDATE(AO$3,-12)+1)))+1)/(AO$3-(EDATE(AO$3,-12)+1)+1)))*$W8),MAX(0,AN8-$M8))) | AP8: =IF($K8="","",IF(AND($I8<>"",$I8<=AO$3),0,AN8-AO8)) | AQ8: =IF(OR($K8="",$H8=""),"",MIN(MAX(0,IF($O8="WDV",AP8*$P8*MAX(0,(IF($I8="",AQ$3,MIN($I8,AQ$3)))-(MAX($H8,(EDATE(AQ$3,-12)+1)))+1)/(AQ$3-(EDATE(AQ$3,-12)+1)+1),IF($N8=0,0,$Q8/$N8*MAX(0,(IF($I8="",AQ$3,MIN($I8,AQ$3)))-(MAX($H8,(EDATE(AQ$3,-12)+1)))+1)/(AQ$3-(EDATE(AQ$3,-12)+1)+1)))*$W8),MAX(0,AP8-$M8))) | AR8: =IF($K8="","",IF(AND($I8<>"",$I8<=AQ$3),0,AP8-AQ8)) | AS8: =IF(OR($K8="",$H8=""),"",MIN(MAX(0,IF($O8="WDV",AR8*$P8*MAX(0,(IF($I8="",AS$3,MIN($I8,AS$3)))-(MAX($H8,(EDATE(AS$3,-12)+1)))+1)/(AS$3-(EDATE(AS$3,-12)+1)+1),IF($N8=0,0,$Q8/$N8*MAX(0,(IF($I8="",AS$3,MIN($I8,AS$3)))-(MAX($H8,(EDATE(AS$3,-12)+1)))+1)/(AS$3-(EDATE(AS$3,-12)+1)+1)))*$W8),MAX(0,AR8-$M8))) | AT8: =IF($K8="","",IF(AND($I8<>"",$I8<=AS$3),0,AR8-AS8)) | AU8: =IF(OR($K8="",$H8=""),"",MIN(MAX(0,IF($O8="WDV",AT8*$P8*MAX(0,(IF($I8="",AU$3,MIN($I8,AU$3)))-(MAX($H8,(EDATE(AU$3,-12)+1)))+1)/(AU$3-(EDATE(AU$3,-12)+1)+1),IF($N8=0,0,$Q8/$N8*MAX(0,(IF($I8="",AU$3,MIN($I8,AU$3)))-(MAX($H8,(EDATE(AU$3,-12)+1)))+1)/(AU$3-(EDATE(AU$3,-12)+1)+1)))*$W8),MAX(0,AT8-$M8))) | AV8: =IF($K8="","",IF(AND($I8<>"",$I8<=AU$3),0,AT8-AU8)) | AW8: =IF(OR($K8="",$H8=""),"",MIN(MAX(0,IF($O8="WDV",AV8*$P8*MAX(0,(IF($I8="",AW$3,MIN($I8,AW$3)))-(MAX($H8,(EDATE(AW$3,-12)+1)))+1)/(AW$3-(EDATE(AW$3,-12)+1)+1),IF($N8=0,0,$Q8/$N8*MAX(0,(IF($I8="",AW$3,MIN($I8,AW$3)))-(MAX($H8,(EDATE(AW$3,-12)+1)))+1)/(AW$3-(EDATE(AW$3,-12)+1)+1)))*$W8),MAX(0,AV8-$M8))) | AX8: =IF($K8="","",IF(AND($I8<>"",$I8<=AW$3),0,AV8-AW8)) | AY8: =IF(OR($K8="",$H8=""),"",MIN(MAX(0,IF($O8="WDV",AX8*$P8*MAX(0,(IF($I8="",AY$3,MIN($I8,AY$3)))-(MAX($H8,(EDATE(AY$3,-12)+1)))+1)/(AY$3-(EDATE(AY$3,-12)+1)+1),IF($N8=0,0,$Q8/$N8*MAX(0,(IF($I8="",AY$3,MIN($I8,AY$3)))-(MAX($H8,(EDATE(AY$3,-12)+1)))+1)/(AY$3-(EDATE(AY$3,-12)+1)+1)))*$W8),MAX(0,AX8-$M8))) | AZ8: =IF($K8="","",IF(AND($I8<>"",$I8<=AY$3),0,AX8-AY8)) | BA8: =IF(OR($K8="",$H8=""),"",MIN(MAX(0,IF($O8="WDV",AZ8*$P8*MAX(0,(IF($I8="",BA$3,MIN($I8,BA$3)))-(MAX($H8,(EDATE(BA$3,-12)+1)))+1)/(BA$3-(EDATE(BA$3,-12)+1)+1),IF($N8=0,0,$Q8/$N8*MAX(0,(IF($I8="",BA$3,MIN($I8,BA$3)))-(MAX($H8,(EDATE(BA$3,-12)+1)))+1)/(BA$3-(EDATE(BA$3,-12)+1)+1)))*$W8),MAX(0,AZ8-$M8))) | BB8: =IF($K8="","",IF(AND($I8<>"",$I8<=BA$3),0,AZ8-BA8)) | BC8: =IF(OR($K8="",$H8=""),"",MIN(MAX(0,IF($O8="WDV",BB8*$P8*MAX(0,(IF($I8="",BC$3,MIN($I8,BC$3)))-(MAX($H8,(EDATE(BC$3,-12)+1)))+1)/(BC$3-(EDATE(BC$3,-12)+1)+1),IF($N8=0,0,$Q8/$N8*MAX(0,(IF($I8="",BC$3,MIN($I8,BC$3)))-(MAX($H8,(EDATE(BC$3,-12)+1)))+1)/(BC$3-(EDATE(BC$3,-12)+1)+1)))*$W8),MAX(0,BB8-$M8))) | BD8: =IF($K8="","",IF(AND($I8<>"",$I8<=BC$3),0,BB8-BC8)) | BE8: =IF(OR($K8="",$H8=""),"",MIN(MAX(0,IF($O8="WDV",BD8*$P8*MAX(0,(IF($I8="",BE$3,MIN($I8,BE$3)))-(MAX($H8,(EDATE(BE$3,-12)+1)))+1)/(BE$3-(EDATE(BE$3,-12)+1)+1),IF($N8=0,0,$Q8/$N8*MAX(0,(IF($I8="",BE$3,MIN($I8,BE$3)))-(MAX($H8,(EDATE(BE$3,-12)+1)))+1)/(BE$3-(EDATE(BE$3,-12)+1)+1)))*$W8),MAX(0,BD8-$M8))) | BF8: =IF($K8="","",IF(AND($I8<>"",$I8<=BE$3),0,BD8-BE8))
A9: FA-005 | B9: Laptops (25 nos.) | C9: Computers - End User Devices | D9: Mumbai HO | E9: Dell India | F9: INV-IT-451 | G9: 44713 | H9: 44717 | K9: 1750000 | L9: =DefaultResidual | M9: =IF($K9="","",$K9*$L9) | N9: =IF($C9="","",IFERROR(VLOOKUP($C9,ScheduleIITable,3,FALSE),"#N/A")) | O9: =IF($K9="","",GlobalMethod) | P9: =IF(OR($K9="",$N9="",$N9=0,$M9=0),0,1-($M9/$K9)^(1/$N9)) | Q9: =IF($K9="","",$K9-$M9) | R9: =IF($K9="","",INDEX($AA9:$BF9,1,MATCH(ReportingFYEnd,$AA$3:$BF$3,0))) | S9: =IF($K9="","",IF($U9="Disposed",0,$K9-$T9)) | T9: =IF($K9="","",INDEX($AA9:$BF9,1,MATCH(ReportingFYEnd,$AA$3:$BF$3,0)+1)) | U9: =IF($K9="","",IF(AND($I9<>"",$I9<=ReportingFYEnd),"Disposed",IF(OR($H9="",$H9>ReportingFYEnd),"Not Yet in Use","Active"))) | V9: Single | W9: =IF($V9="Double",1.5,IF($V9="Triple",2,1)) | Y9: =IF($K9="","",IF(OR(ISNUMBER(SEARCH("Build",$C9)),ISNUMBER(SEARCH("Lease",$C9))),"Yes","NA")) | AA9: =IF(OR($K9="",$H9=""),"",MIN(MAX(0,IF($O9="WDV",$K9*$P9*MAX(0,(IF($I9="",AA$3,MIN($I9,AA$3)))-(MAX($H9,(EDATE(AA$3,-12)+1)))+1)/(AA$3-(EDATE(AA$3,-12)+1)+1),IF($N9=0,0,$Q9/$N9*MAX(0,(IF($I9="",AA$3,MIN($I9,AA$3)))-(MAX($H9,(EDATE(AA$3,-12)+1)))+1)/(AA$3-(EDATE(AA$3,-12)+1)+1)))*$W9),MAX(0,$K9-$M9))) | AB9: =IF($K9="","",IF(AND($I9<>"",$I9<=AA$3),0,$K9-AA9)) | AC9: =IF(OR($K9="",$H9=""),"",MIN(MAX(0,IF($O9="WDV",AB9*$P9*MAX(0,(IF($I9="",AC$3,MIN($I9,AC$3)))-(MAX($H9,(EDATE(AC$3,-12)+1)))+1)/(AC$3-(EDATE(AC$3,-12)+1)+1),IF($N9=0,0,$Q9/$N9*MAX(0,(IF($I9="",AC$3,MIN($I9,AC$3)))-(MAX($H9,(EDATE(AC$3,-12)+1)))+1)/(AC$3-(EDATE(AC$3,-12)+1)+1)))*$W9),MAX(0,AB9-$M9))) | AD9: =IF($K9="","",IF(AND($I9<>"",$I9<=AC$3),0,AB9-AC9)) | AE9: =IF(OR($K9="",$H9=""),"",MIN(MAX(0,IF($O9="WDV",AD9*$P9*MAX(0,(IF($I9="",AE$3,MIN($I9,AE$3)))-(MAX($H9,(EDATE(AE$3,-12)+1)))+1)/(AE$3-(EDATE(AE$3,-12)+1)+1),IF($N9=0,0,$Q9/$N9*MAX(0,(IF($I9="",AE$3,MIN($I9,AE$3)))-(MAX($H9,(EDATE(AE$3,-12)+1)))+1)/(AE$3-(EDATE(AE$3,-12)+1)+1)))*$W9),MAX(0,AD9-$M9))) | AF9: =IF($K9="","",IF(AND($I9<>"",$I9<=AE$3),0,AD9-AE9)) | AG9: =IF(OR($K9="",$H9=""),"",MIN(MAX(0,IF($O9="WDV",AF9*$P9*MAX(0,(IF($I9="",AG$3,MIN($I9,AG$3)))-(MAX($H9,(EDATE(AG$3,-12)+1)))+1)/(AG$3-(EDATE(AG$3,-12)+1)+1),IF($N9=0,0,$Q9/$N9*MAX(0,(IF($I9="",AG$3,MIN($I9,AG$3)))-(MAX($H9,(EDATE(AG$3,-12)+1)))+1)/(AG$3-(EDATE(AG$3,-12)+1)+1)))*$W9),MAX(0,AF9-$M9))) | AH9: =IF($K9="","",IF(AND($I9<>"",$I9<=AG$3),0,AF9-AG9)) | AI9: =IF(OR($K9="",$H9=""),"",MIN(MAX(0,IF($O9="WDV",AH9*$P9*MAX(0,(IF($I9="",AI$3,MIN($I9,AI$3)))-(MAX($H9,(EDATE(AI$3,-12)+1)))+1)/(AI$3-(EDATE(AI$3,-12)+1)+1),IF($N9=0,0,$Q9/$N9*MAX(0,(IF($I9="",AI$3,MIN($I9,AI$3)))-(MAX($H9,(EDATE(AI$3,-12)+1)))+1)/(AI$3-(EDATE(AI$3,-12)+1)+1)))*$W9),MAX(0,AH9-$M9))) | AJ9: =IF($K9="","",IF(AND($I9<>"",$I9<=AI$3),0,AH9-AI9)) | AK9: =IF(OR($K9="",$H9=""),"",MIN(MAX(0,IF($O9="WDV",AJ9*$P9*MAX(0,(IF($I9="",AK$3,MIN($I9,AK$3)))-(MAX($H9,(EDATE(AK$3,-12)+1)))+1)/(AK$3-(EDATE(AK$3,-12)+1)+1),IF($N9=0,0,$Q9/$N9*MAX(0,(IF($I9="",AK$3,MIN($I9,AK$3)))-(MAX($H9,(EDATE(AK$3,-12)+1)))+1)/(AK$3-(EDATE(AK$3,-12)+1)+1)))*$W9),MAX(0,AJ9-$M9))) | AL9: =IF($K9="","",IF(AND($I9<>"",$I9<=AK$3),0,AJ9-AK9)) | AM9: =IF(OR($K9="",$H9=""),"",MIN(MAX(0,IF($O9="WDV",AL9*$P9*MAX(0,(IF($I9="",AM$3,MIN($I9,AM$3)))-(MAX($H9,(EDATE(AM$3,-12)+1)))+1)/(AM$3-(EDATE(AM$3,-12)+1)+1),IF($N9=0,0,$Q9/$N9*MAX(0,(IF($I9="",AM$3,MIN($I9,AM$3)))-(MAX($H9,(EDATE(AM$3,-12)+1)))+1)/(AM$3-(EDATE(AM$3,-12)+1)+1)))*$W9),MAX(0,AL9-$M9))) | AN9: =IF($K9="","",IF(AND($I9<>"",$I9<=AM$3),0,AL9-AM9)) | AO9: =IF(OR($K9="",$H9=""),"",MIN(MAX(0,IF($O9="WDV",AN9*$P9*MAX(0,(IF($I9="",AO$3,MIN($I9,AO$3)))-(MAX($H9,(EDATE(AO$3,-12)+1)))+1)/(AO$3-(EDATE(AO$3,-12)+1)+1),IF($N9=0,0,$Q9/$N9*MAX(0,(IF($I9="",AO$3,MIN($I9,AO$3)))-(MAX($H9,(EDATE(AO$3,-12)+1)))+1)/(AO$3-(EDATE(AO$3,-12)+1)+1)))*$W9),MAX(0,AN9-$M9))) | AP9: =IF($K9="","",IF(AND($I9<>"",$I9<=AO$3),0,AN9-AO9)) | AQ9: =IF(OR($K9="",$H9=""),"",MIN(MAX(0,IF($O9="WDV",AP9*$P9*MAX(0,(IF($I9="",AQ$3,MIN($I9,AQ$3)))-(MAX($H9,(EDATE(AQ$3,-12)+1)))+1)/(AQ$3-(EDATE(AQ$3,-12)+1)+1),IF($N9=0,0,$Q9/$N9*MAX(0,(IF($I9="",AQ$3,MIN($I9,AQ$3)))-(MAX($H9,(EDATE(AQ$3,-12)+1)))+1)/(AQ$3-(EDATE(AQ$3,-12)+1)+1)))*$W9),MAX(0,AP9-$M9))) | AR9: =IF($K9="","",IF(AND($I9<>"",$I9<=AQ$3),0,AP9-AQ9)) | AS9: =IF(OR($K9="",$H9=""),"",MIN(MAX(0,IF($O9="WDV",AR9*$P9*MAX(0,(IF($I9="",AS$3,MIN($I9,AS$3)))-(MAX($H9,(EDATE(AS$3,-12)+1)))+1)/(AS$3-(EDATE(AS$3,-12)+1)+1),IF($N9=0,0,$Q9/$N9*MAX(0,(IF($I9="",AS$3,MIN($I9,AS$3)))-(MAX($H9,(EDATE(AS$3,-12)+1)))+1)/(AS$3-(EDATE(AS$3,-12)+1)+1)))*$W9),MAX(0,AR9-$M9))) | AT9: =IF($K9="","",IF(AND($I9<>"",$I9<=AS$3),0,AR9-AS9)) | AU9: =IF(OR($K9="",$H9=""),"",MIN(MAX(0,IF($O9="WDV",AT9*$P9*MAX(0,(IF($I9="",AU$3,MIN($I9,AU$3)))-(MAX($H9,(EDATE(AU$3,-12)+1)))+1)/(AU$3-(EDATE(AU$3,-12)+1)+1),IF($N9=0,0,$Q9/$N9*MAX(0,(IF($I9="",AU$3,MIN($I9,AU$3)))-(MAX($H9,(EDATE(AU$3,-12)+1)))+1)/(AU$3-(EDATE(AU$3,-12)+1)+1)))*$W9),MAX(0,AT9-$M9))) | AV9: =IF($K9="","",IF(AND($I9<>"",$I9<=AU$3),0,AT9-AU9)) | AW9: =IF(OR($K9="",$H9=""),"",MIN(MAX(0,IF($O9="WDV",AV9*$P9*MAX(0,(IF($I9="",AW$3,MIN($I9,AW$3)))-(MAX($H9,(EDATE(AW$3,-12)+1)))+1)/(AW$3-(EDATE(AW$3,-12)+1)+1),IF($N9=0,0,$Q9/$N9*MAX(0,(IF($I9="",AW$3,MIN($I9,AW$3)))-(MAX($H9,(EDATE(AW$3,-12)+1)))+1)/(AW$3-(EDATE(AW$3,-12)+1)+1)))*$W9),MAX(0,AV9-$M9))) | AX9: =IF($K9="","",IF(AND($I9<>"",$I9<=AW$3),0,AV9-AW9)) | AY9: =IF(OR($K9="",$H9=""),"",MIN(MAX(0,IF($O9="WDV",AX9*$P9*MAX(0,(IF($I9="",AY$3,MIN($I9,AY$3)))-(MAX($H9,(EDATE(AY$3,-12)+1)))+1)/(AY$3-(EDATE(AY$3,-12)+1)+1),IF($N9=0,0,$Q9/$N9*MAX(0,(IF($I9="",AY$3,MIN($I9,AY$3)))-(MAX($H9,(EDATE(AY$3,-12)+1)))+1)/(AY$3-(EDATE(AY$3,-12)+1)+1)))*$W9),MAX(0,AX9-$M9))) | AZ9: =IF($K9="","",IF(AND($I9<>"",$I9<=AY$3),0,AX9-AY9)) | BA9: =IF(OR($K9="",$H9=""),"",MIN(MAX(0,IF($O9="WDV",AZ9*$P9*MAX(0,(IF($I9="",BA$3,MIN($I9,BA$3)))-(MAX($H9,(EDATE(BA$3,-12)+1)))+1)/(BA$3-(EDATE(BA$3,-12)+1)+1),IF($N9=0,0,$Q9/$N9*MAX(0,(IF($I9="",BA$3,MIN($I9,BA$3)))-(MAX($H9,(EDATE(BA$3,-12)+1)))+1)/(BA$3-(EDATE(BA$3,-12)+1)+1)))*$W9),MAX(0,AZ9-$M9))) | BB9: =IF($K9="","",IF(AND($I9<>"",$I9<=BA$3),0,AZ9-BA9)) | BC9: =IF(OR($K9="",$H9=""),"",MIN(MAX(0,IF($O9="WDV",BB9*$P9*MAX(0,(IF($I9="",BC$3,MIN($I9,BC$3)))-(MAX($H9,(EDATE(BC$3,-12)+1)))+1)/(BC$3-(EDATE(BC$3,-12)+1)+1),IF($N9=0,0,$Q9/$N9*MAX(0,(IF($I9="",BC$3,MIN($I9,BC$3)))-(MAX($H9,(EDATE(BC$3,-12)+1)))+1)/(BC$3-(EDATE(BC$3,-12)+1)+1)))*$W9),MAX(0,BB9-$M9))) | BD9: =IF($K9="","",IF(AND($I9<>"",$I9<=BC$3),0,BB9-BC9)) | BE9: =IF(OR($K9="",$H9=""),"",MIN(MAX(0,IF($O9="WDV",BD9*$P9*MAX(0,(IF($I9="",BE$3,MIN($I9,BE$3)))-(MAX($H9,(EDATE(BE$3,-12)+1)))+1)/(BE$3-(EDATE(BE$3,-12)+1)+1),IF($N9=0,0,$Q9/$N9*MAX(0,(IF($I9="",BE$3,MIN($I9,BE$3)))-(MAX($H9,(EDATE(BE$3,-12)+1)))+1)/(BE$3-(EDATE(BE$3,-12)+1)+1)))*$W9),MAX(0,BD9-$M9))) | BF9: =IF($K9="","",IF(AND($I9<>"",$I9<=BE$3),0,BD9-BE9))
A10: FA-006 | B10: Application Server | C10: Computers - Servers & Networks | D10: Mumbai HO | E10: HPE | F10: INV-IT-460 | G10: 44816 | H10: 44824 | K10: 1200000 | L10: =DefaultResidual | M10: =IF($K10="","",$K10*$L10) | N10: =IF($C10="","",IFERROR(VLOOKUP($C10,ScheduleIITable,3,FALSE),"#N/A")) | O10: =IF($K10="","",GlobalMethod) | P10: =IF(OR($K10="",$N10="",$N10=0,$M10=0),0,1-($M10/$K10)^(1/$N10)) | Q10: =IF($K10="","",$K10-$M10) | R10: =IF($K10="","",INDEX($AA10:$BF10,1,MATCH(ReportingFYEnd,$AA$3:$BF$3,0))) | S10: =IF($K10="","",IF($U10="Disposed",0,$K10-$T10)) | T10: =IF($K10="","",INDEX($AA10:$BF10,1,MATCH(ReportingFYEnd,$AA$3:$BF$3,0)+1)) | U10: =IF($K10="","",IF(AND($I10<>"",$I10<=ReportingFYEnd),"Disposed",IF(OR($H10="",$H10>ReportingFYEnd),"Not Yet in Use","Active"))) | V10: Single | W10: =IF($V10="Double",1.5,IF($V10="Triple",2,1)) | Y10: =IF($K10="","",IF(OR(ISNUMBER(SEARCH("Build",$C10)),ISNUMBER(SEARCH("Lease",$C10))),"Yes","NA")) | AA10: =IF(OR($K10="",$H10=""),"",MIN(MAX(0,IF($O10="WDV",$K10*$P10*MAX(0,(IF($I10="",AA$3,MIN($I10,AA$3)))-(MAX($H10,(EDATE(AA$3,-12)+1)))+1)/(AA$3-(EDATE(AA$3,-12)+1)+1),IF($N10=0,0,$Q10/$N10*MAX(0,(IF($I10="",AA$3,MIN($I10,AA$3)))-(MAX($H10,(EDATE(AA$3,-12)+1)))+1)/(AA$3-(EDATE(AA$3,-12)+1)+1)))*$W10),MAX(0,$K10-$M10))) | AB10: =IF($K10="","",IF(AND($I10<>"",$I10<=AA$3),0,$K10-AA10)) | AC10: =IF(OR($K10="",$H10=""),"",MIN(MAX(0,IF($O10="WDV",AB10*$P10*MAX(0,(IF($I10="",AC$3,MIN($I10,AC$3)))-(MAX($H10,(EDATE(AC$3,-12)+1)))+1)/(AC$3-(EDATE(AC$3,-12)+1)+1),IF($N10=0,0,$Q10/$N10*MAX(0,(IF($I10="",AC$3,MIN($I10,AC$3)))-(MAX($H10,(EDATE(AC$3,-12)+1)))+1)/(AC$3-(EDATE(AC$3,-12)+1)+1)))*$W10),MAX(0,AB10-$M10))) | AD10: =IF($K10="","",IF(AND($I10<>"",$I10<=AC$3),0,AB10-AC10)) | AE10: =IF(OR($K10="",$H10=""),"",MIN(MAX(0,IF($O10="WDV",AD10*$P10*MAX(0,(IF($I10="",AE$3,MIN($I10,AE$3)))-(MAX($H10,(EDATE(AE$3,-12)+1)))+1)/(AE$3-(EDATE(AE$3,-12)+1)+1),IF($N10=0,0,$Q10/$N10*MAX(0,(IF($I10="",AE$3,MIN($I10,AE$3)))-(MAX($H10,(EDATE(AE$3,-12)+1)))+1)/(AE$3-(EDATE(AE$3,-12)+1)+1)))*$W10),MAX(0,AD10-$M10))) | AF10: =IF($K10="","",IF(AND($I10<>"",$I10<=AE$3),0,AD10-AE10)) | AG10: =IF(OR($K10="",$H10=""),"",MIN(MAX(0,IF($O10="WDV",AF10*$P10*MAX(0,(IF($I10="",AG$3,MIN($I10,AG$3)))-(MAX($H10,(EDATE(AG$3,-12)+1)))+1)/(AG$3-(EDATE(AG$3,-12)+1)+1),IF($N10=0,0,$Q10/$N10*MAX(0,(IF($I10="",AG$3,MIN($I10,AG$3)))-(MAX($H10,(EDATE(AG$3,-12)+1)))+1)/(AG$3-(EDATE(AG$3,-12)+1)+1)))*$W10),MAX(0,AF10-$M10))) | AH10: =IF($K10="","",IF(AND($I10<>"",$I10<=AG$3),0,AF10-AG10)) | AI10: =IF(OR($K10="",$H10=""),"",MIN(MAX(0,IF($O10="WDV",AH10*$P10*MAX(0,(IF($I10="",AI$3,MIN($I10,AI$3)))-(MAX($H10,(EDATE(AI$3,-12)+1)))+1)/(AI$3-(EDATE(AI$3,-12)+1)+1),IF($N10=0,0,$Q10/$N10*MAX(0,(IF($I10="",AI$3,MIN($I10,AI$3)))-(MAX($H10,(EDATE(AI$3,-12)+1)))+1)/(AI$3-(EDATE(AI$3,-12)+1)+1)))*$W10),MAX(0,AH10-$M10))) | AJ10: =IF($K10="","",IF(AND($I10<>"",$I10<=AI$3),0,AH10-AI10)) | AK10: =IF(OR($K10="",$H10=""),"",MIN(MAX(0,IF($O10="WDV",AJ10*$P10*MAX(0,(IF($I10="",AK$3,MIN($I10,AK$3)))-(MAX($H10,(EDATE(AK$3,-12)+1)))+1)/(AK$3-(EDATE(AK$3,-12)+1)+1),IF($N10=0,0,$Q10/$N10*MAX(0,(IF($I10="",AK$3,MIN($I10,AK$3)))-(MAX($H10,(EDATE(AK$3,-12)+1)))+1)/(AK$3-(EDATE(AK$3,-12)+1)+1)))*$W10),MAX(0,AJ10-$M10))) | AL10: =IF($K10="","",IF(AND($I10<>"",$I10<=AK$3),0,AJ10-AK10)) | AM10: =IF(OR($K10="",$H10=""),"",MIN(MAX(0,IF($O10="WDV",AL10*$P10*MAX(0,(IF($I10="",AM$3,MIN($I10,AM$3)))-(MAX($H10,(EDATE(AM$3,-12)+1)))+1)/(AM$3-(EDATE(AM$3,-12)+1)+1),IF($N10=0,0,$Q10/$N10*MAX(0,(IF($I10="",AM$3,MIN($I10,AM$3)))-(MAX($H10,(EDATE(AM$3,-12)+1)))+1)/(AM$3-(EDATE(AM$3,-12)+1)+1)))*$W10),MAX(0,AL10-$M10))) | AN10: =IF($K10="","",IF(AND($I10<>"",$I10<=AM$3),0,AL10-AM10)) | AO10: =IF(OR($K10="",$H10=""),"",MIN(MAX(0,IF($O10="WDV",AN10*$P10*MAX(0,(IF($I10="",AO$3,MIN($I10,AO$3)))-(MAX($H10,(EDATE(AO$3,-12)+1)))+1)/(AO$3-(EDATE(AO$3,-12)+1)+1),IF($N10=0,0,$Q10/$N10*MAX(0,(IF($I10="",AO$3,MIN($I10,AO$3)))-(MAX($H10,(EDATE(AO$3,-12)+1)))+1)/(AO$3-(EDATE(AO$3,-12)+1)+1)))*$W10),MAX(0,AN10-$M10))) | AP10: =IF($K10="","",IF(AND($I10<>"",$I10<=AO$3),0,AN10-AO10)) | AQ10: =IF(OR($K10="",$H10=""),"",MIN(MAX(0,IF($O10="WDV",AP10*$P10*MAX(0,(IF($I10="",AQ$3,MIN($I10,AQ$3)))-(MAX($H10,(EDATE(AQ$3,-12)+1)))+1)/(AQ$3-(EDATE(AQ$3,-12)+1)+1),IF($N10=0,0,$Q10/$N10*MAX(0,(IF($I10="",AQ$3,MIN($I10,AQ$3)))-(MAX($H10,(EDATE(AQ$3,-12)+1)))+1)/(AQ$3-(EDATE(AQ$3,-12)+1)+1)))*$W10),MAX(0,AP10-$M10))) | AR10: =IF($K10="","",IF(AND($I10<>"",$I10<=AQ$3),0,AP10-AQ10)) | AS10: =IF(OR($K10="",$H10=""),"",MIN(MAX(0,IF($O10="WDV",AR10*$P10*MAX(0,(IF($I10="",AS$3,MIN($I10,AS$3)))-(MAX($H10,(EDATE(AS$3,-12)+1)))+1)/(AS$3-(EDATE(AS$3,-12)+1)+1),IF($N10=0,0,$Q10/$N10*MAX(0,(IF($I10="",AS$3,MIN($I10,AS$3)))-(MAX($H10,(EDATE(AS$3,-12)+1)))+1)/(AS$3-(EDATE(AS$3,-12)+1)+1)))*$W10),MAX(0,AR10-$M10))) | AT10: =IF($K10="","",IF(AND($I10<>"",$I10<=AS$3),0,AR10-AS10)) | AU10: =IF(OR($K10="",$H10=""),"",MIN(MAX(0,IF($O10="WDV",AT10*$P10*MAX(0,(IF($I10="",AU$3,MIN($I10,AU$3)))-(MAX($H10,(EDATE(AU$3,-12)+1)))+1)/(AU$3-(EDATE(AU$3,-12)+1)+1),IF($N10=0,0,$Q10/$N10*MAX(0,(IF($I10="",AU$3,MIN($I10,AU$3)))-(MAX($H10,(EDATE(AU$3,-12)+1)))+1)/(AU$3-(EDATE(AU$3,-12)+1)+1)))*$W10),MAX(0,AT10-$M10))) | AV10: =IF($K10="","",IF(AND($I10<>"",$I10<=AU$3),0,AT10-AU10)) | AW10: =IF(OR($K10="",$H10=""),"",MIN(MAX(0,IF($O10="WDV",AV10*$P10*MAX(0,(IF($I10="",AW$3,MIN($I10,AW$3)))-(MAX($H10,(EDATE(AW$3,-12)+1)))+1)/(AW$3-(EDATE(AW$3,-12)+1)+1),IF($N10=0,0,$Q10/$N10*MAX(0,(IF($I10="",AW$3,MIN($I10,AW$3)))-(MAX($H10,(EDATE(AW$3,-12)+1)))+1)/(AW$3-(EDATE(AW$3,-12)+1)+1)))*$W10),MAX(0,AV10-$M10))) | AX10: =IF($K10="","",IF(AND($I10<>"",$I10<=AW$3),0,AV10-AW10)) | AY10: =IF(OR($K10="",$H10=""),"",MIN(MAX(0,IF($O10="WDV",AX10*$P10*MAX(0,(IF($I10="",AY$3,MIN($I10,AY$3)))-(MAX($H10,(EDATE(AY$3,-12)+1)))+1)/(AY$3-(EDATE(AY$3,-12)+1)+1),IF($N10=0,0,$Q10/$N10*MAX(0,(IF($I10="",AY$3,MIN($I10,AY$3)))-(MAX($H10,(EDATE(AY$3,-12)+1)))+1)/(AY$3-(EDATE(AY$3,-12)+1)+1)))*$W10),MAX(0,AX10-$M10))) | AZ10: =IF($K10="","",IF(AND($I10<>"",$I10<=AY$3),0,AX10-AY10)) | BA10: =IF(OR($K10="",$H10=""),"",MIN(MAX(0,IF($O10="WDV",AZ10*$P10*MAX(0,(IF($I10="",BA$3,MIN($I10,BA$3)))-(MAX($H10,(EDATE(BA$3,-12)+1)))+1)/(BA$3-(EDATE(BA$3,-12)+1)+1),IF($N10=0,0,$Q10/$N10*MAX(0,(IF($I10="",BA$3,MIN($I10,BA$3)))-(MAX($H10,(EDATE(BA$3,-12)+1)))+1)/(BA$3-(EDATE(BA$3,-12)+1)+1)))*$W10),MAX(0,AZ10-$M10))) | BB10: =IF($K10="","",IF(AND($I10<>"",$I10<=BA$3),0,AZ10-BA10)) | BC10: =IF(OR($K10="",$H10=""),"",MIN(MAX(0,IF($O10="WDV",BB10*$P10*MAX(0,(IF($I10="",BC$3,MIN($I10,BC$3)))-(MAX($H10,(EDATE(BC$3,-12)+1)))+1)/(BC$3-(EDATE(BC$3,-12)+1)+1),IF($N10=0,0,$Q10/$N10*MAX(0,(IF($I10="",BC$3,MIN($I10,BC$3)))-(MAX($H10,(EDATE(BC$3,-12)+1)))+1)/(BC$3-(EDATE(BC$3,-12)+1)+1)))*$W10),MAX(0,BB10-$M10))) | BD10: =IF($K10="","",IF(AND($I10<>"",$I10<=BC$3),0,BB10-BC10)) | BE10: =IF(OR($K10="",$H10=""),"",MIN(MAX(0,IF($O10="WDV",BD10*$P10*MAX(0,(IF($I10="",BE$3,MIN($I10,BE$3)))-(MAX($H10,(EDATE(BE$3,-12)+1)))+1)/(BE$3-(EDATE(BE$3,-12)+1)+1),IF($N10=0,0,$Q10/$N10*MAX(0,(IF($I10="",BE$3,MIN($I10,BE$3)))-(MAX($H10,(EDATE(BE$3,-12)+1)))+1)/(BE$3-(EDATE(BE$3,-12)+1)+1)))*$W10),MAX(0,BD10-$M10))) | BF10: =IF($K10="","",IF(AND($I10<>"",$I10<=BE$3),0,BD10-BE10))
A11: FA-007 | B11: Director's Car | C11: Motor Vehicles - Motor Cars | D11: Mumbai HO | E11: Toyota | F11: INV-MV-011 | G11: 44941 | H11: 44941 | K11: 2800000 | L11: =DefaultResidual | M11: =IF($K11="","",$K11*$L11) | N11: =IF($C11="","",IFERROR(VLOOKUP($C11,ScheduleIITable,3,FALSE),"#N/A")) | O11: =IF($K11="","",GlobalMethod) | P11: =IF(OR($K11="",$N11="",$N11=0,$M11=0),0,1-($M11/$K11)^(1/$N11)) | Q11: =IF($K11="","",$K11-$M11) | R11: =IF($K11="","",INDEX($AA11:$BF11,1,MATCH(ReportingFYEnd,$AA$3:$BF$3,0))) | S11: =IF($K11="","",IF($U11="Disposed",0,$K11-$T11)) | T11: =IF($K11="","",INDEX($AA11:$BF11,1,MATCH(ReportingFYEnd,$AA$3:$BF$3,0)+1)) | U11: =IF($K11="","",IF(AND($I11<>"",$I11<=ReportingFYEnd),"Disposed",IF(OR($H11="",$H11>ReportingFYEnd),"Not Yet in Use","Active"))) | V11: Single | W11: =IF($V11="Double",1.5,IF($V11="Triple",2,1)) | Y11: =IF($K11="","",IF(OR(ISNUMBER(SEARCH("Build",$C11)),ISNUMBER(SEARCH("Lease",$C11))),"Yes","NA")) | AA11: =IF(OR($K11="",$H11=""),"",MIN(MAX(0,IF($O11="WDV",$K11*$P11*MAX(0,(IF($I11="",AA$3,MIN($I11,AA$3)))-(MAX($H11,(EDATE(AA$3,-12)+1)))+1)/(AA$3-(EDATE(AA$3,-12)+1)+1),IF($N11=0,0,$Q11/$N11*MAX(0,(IF($I11="",AA$3,MIN($I11,AA$3)))-(MAX($H11,(EDATE(AA$3,-12)+1)))+1)/(AA$3-(EDATE(AA$3,-12)+1)+1)))*$W11),MAX(0,$K11-$M11))) | AB11: =IF($K11="","",IF(AND($I11<>"",$I11<=AA$3),0,$K11-AA11)) | AC11: =IF(OR($K11="",$H11=""),"",MIN(MAX(0,IF($O11="WDV",AB11*$P11*MAX(0,(IF($I11="",AC$3,MIN($I11,AC$3)))-(MAX($H11,(EDATE(AC$3,-12)+1)))+1)/(AC$3-(EDATE(AC$3,-12)+1)+1),IF($N11=0,0,$Q11/$N11*MAX(0,(IF($I11="",AC$3,MIN($I11,AC$3)))-(MAX($H11,(EDATE(AC$3,-12)+1)))+1)/(AC$3-(EDATE(AC$3,-12)+1)+1)))*$W11),MAX(0,AB11-$M11))) | AD11: =IF($K11="","",IF(AND($I11<>"",$I11<=AC$3),0,AB11-AC11)) | AE11: =IF(OR($K11="",$H11=""),"",MIN(MAX(0,IF($O11="WDV",AD11*$P11*MAX(0,(IF($I11="",AE$3,MIN($I11,AE$3)))-(MAX($H11,(EDATE(AE$3,-12)+1)))+1)/(AE$3-(EDATE(AE$3,-12)+1)+1),IF($N11=0,0,$Q11/$N11*MAX(0,(IF($I11="",AE$3,MIN($I11,AE$3)))-(MAX($H11,(EDATE(AE$3,-12)+1)))+1)/(AE$3-(EDATE(AE$3,-12)+1)+1)))*$W11),MAX(0,AD11-$M11))) | AF11: =IF($K11="","",IF(AND($I11<>"",$I11<=AE$3),0,AD11-AE11)) | AG11: =IF(OR($K11="",$H11=""),"",MIN(MAX(0,IF($O11="WDV",AF11*$P11*MAX(0,(IF($I11="",AG$3,MIN($I11,AG$3)))-(MAX($H11,(EDATE(AG$3,-12)+1)))+1)/(AG$3-(EDATE(AG$3,-12)+1)+1),IF($N11=0,0,$Q11/$N11*MAX(0,(IF($I11="",AG$3,MIN($I11,AG$3)))-(MAX($H11,(EDATE(AG$3,-12)+1)))+1)/(AG$3-(EDATE(AG$3,-12)+1)+1)))*$W11),MAX(0,AF11-$M11))) | AH11: =IF($K11="","",IF(AND($I11<>"",$I11<=AG$3),0,AF11-AG11)) | AI11: =IF(OR($K11="",$H11=""),"",MIN(MAX(0,IF($O11="WDV",AH11*$P11*MAX(0,(IF($I11="",AI$3,MIN($I11,AI$3)))-(MAX($H11,(EDATE(AI$3,-12)+1)))+1)/(AI$3-(EDATE(AI$3,-12)+1)+1),IF($N11=0,0,$Q11/$N11*MAX(0,(IF($I11="",AI$3,MIN($I11,AI$3)))-(MAX($H11,(EDATE(AI$3,-12)+1)))+1)/(AI$3-(EDATE(AI$3,-12)+1)+1)))*$W11),MAX(0,AH11-$M11))) | AJ11: =IF($K11="","",IF(AND($I11<>"",$I11<=AI$3),0,AH11-AI11)) | AK11: =IF(OR($K11="",$H11=""),"",MIN(MAX(0,IF($O11="WDV",AJ11*$P11*MAX(0,(IF($I11="",AK$3,MIN($I11,AK$3)))-(MAX($H11,(EDATE(AK$3,-12)+1)))+1)/(AK$3-(EDATE(AK$3,-12)+1)+1),IF($N11=0,0,$Q11/$N11*MAX(0,(IF($I11="",AK$3,MIN($I11,AK$3)))-(MAX($H11,(EDATE(AK$3,-12)+1)))+1)/(AK$3-(EDATE(AK$3,-12)+1)+1)))*$W11),MAX(0,AJ11-$M11))) | AL11: =IF($K11="","",IF(AND($I11<>"",$I11<=AK$3),0,AJ11-AK11)) | AM11: =IF(OR($K11="",$H11=""),"",MIN(MAX(0,IF($O11="WDV",AL11*$P11*MAX(0,(IF($I11="",AM$3,MIN($I11,AM$3)))-(MAX($H11,(EDATE(AM$3,-12)+1)))+1)/(AM$3-(EDATE(AM$3,-12)+1)+1),IF($N11=0,0,$Q11/$N11*MAX(0,(IF($I11="",AM$3,MIN($I11,AM$3)))-(MAX($H11,(EDATE(AM$3,-12)+1)))+1)/(AM$3-(EDATE(AM$3,-12)+1)+1)))*$W11),MAX(0,AL11-$M11))) | AN11: =IF($K11="","",IF(AND($I11<>"",$I11<=AM$3),0,AL11-AM11)) | AO11: =IF(OR($K11="",$H11=""),"",MIN(MAX(0,IF($O11="WDV",AN11*$P11*MAX(0,(IF($I11="",AO$3,MIN($I11,AO$3)))-(MAX($H11,(EDATE(AO$3,-12)+1)))+1)/(AO$3-(EDATE(AO$3,-12)+1)+1),IF($N11=0,0,$Q11/$N11*MAX(0,(IF($I11="",AO$3,MIN($I11,AO$3)))-(MAX($H11,(EDATE(AO$3,-12)+1)))+1)/(AO$3-(EDATE(AO$3,-12)+1)+1)))*$W11),MAX(0,AN11-$M11))) | AP11: =IF($K11="","",IF(AND($I11<>"",$I11<=AO$3),0,AN11-AO11)) | AQ11: =IF(OR($K11="",$H11=""),"",MIN(MAX(0,IF($O11="WDV",AP11*$P11*MAX(0,(IF($I11="",AQ$3,MIN($I11,AQ$3)))-(MAX($H11,(EDATE(AQ$3,-12)+1)))+1)/(AQ$3-(EDATE(AQ$3,-12)+1)+1),IF($N11=0,0,$Q11/$N11*MAX(0,(IF($I11="",AQ$3,MIN($I11,AQ$3)))-(MAX($H11,(EDATE(AQ$3,-12)+1)))+1)/(AQ$3-(EDATE(AQ$3,-12)+1)+1)))*$W11),MAX(0,AP11-$M11))) | AR11: =IF($K11="","",IF(AND($I11<>"",$I11<=AQ$3),0,AP11-AQ11)) | AS11: =IF(OR($K11="",$H11=""),"",MIN(MAX(0,IF($O11="WDV",AR11*$P11*MAX(0,(IF($I11="",AS$3,MIN($I11,AS$3)))-(MAX($H11,(EDATE(AS$3,-12)+1)))+1)/(AS$3-(EDATE(AS$3,-12)+1)+1),IF($N11=0,0,$Q11/$N11*MAX(0,(IF($I11="",AS$3,MIN($I11,AS$3)))-(MAX($H11,(EDATE(AS$3,-12)+1)))+1)/(AS$3-(EDATE(AS$3,-12)+1)+1)))*$W11),MAX(0,AR11-$M11))) | AT11: =IF($K11="","",IF(AND($I11<>"",$I11<=AS$3),0,AR11-AS11)) | AU11: =IF(OR($K11="",$H11=""),"",MIN(MAX(0,IF($O11="WDV",AT11*$P11*MAX(0,(IF($I11="",AU$3,MIN($I11,AU$3)))-(MAX($H11,(EDATE(AU$3,-12)+1)))+1)/(AU$3-(EDATE(AU$3,-12)+1)+1),IF($N11=0,0,$Q11/$N11*MAX(0,(IF($I11="",AU$3,MIN($I11,AU$3)))-(MAX($H11,(EDATE(AU$3,-12)+1)))+1)/(AU$3-(EDATE(AU$3,-12)+1)+1)))*$W11),MAX(0,AT11-$M11))) | AV11: =IF($K11="","",IF(AND($I11<>"",$I11<=AU$3),0,AT11-AU11)) | AW11: =IF(OR($K11="",$H11=""),"",MIN(MAX(0,IF($O11="WDV",AV11*$P11*MAX(0,(IF($I11="",AW$3,MIN($I11,AW$3)))-(MAX($H11,(EDATE(AW$3,-12)+1)))+1)/(AW$3-(EDATE(AW$3,-12)+1)+1),IF($N11=0,0,$Q11/$N11*MAX(0,(IF($I11="",AW$3,MIN($I11,AW$3)))-(MAX($H11,(EDATE(AW$3,-12)+1)))+1)/(AW$3-(EDATE(AW$3,-12)+1)+1)))*$W11),MAX(0,AV11-$M11))) | AX11: =IF($K11="","",IF(AND($I11<>"",$I11<=AW$3),0,AV11-AW11)) | AY11: =IF(OR($K11="",$H11=""),"",MIN(MAX(0,IF($O11="WDV",AX11*$P11*MAX(0,(IF($I11="",AY$3,MIN($I11,AY$3)))-(MAX($H11,(EDATE(AY$3,-12)+1)))+1)/(AY$3-(EDATE(AY$3,-12)+1)+1),IF($N11=0,0,$Q11/$N11*MAX(0,(IF($I11="",AY$3,MIN($I11,AY$3)))-(MAX($H11,(EDATE(AY$3,-12)+1)))+1)/(AY$3-(EDATE(AY$3,-12)+1)+1)))*$W11),MAX(0,AX11-$M11))) | AZ11: =IF($K11="","",IF(AND($I11<>"",$I11<=AY$3),0,AX11-AY11)) | BA11: =IF(OR($K11="",$H11=""),"",MIN(MAX(0,IF($O11="WDV",AZ11*$P11*MAX(0,(IF($I11="",BA$3,MIN($I11,BA$3)))-(MAX($H11,(EDATE(BA$3,-12)+1)))+1)/(BA$3-(EDATE(BA$3,-12)+1)+1),IF($N11=0,0,$Q11/$N11*MAX(0,(IF($I11="",BA$3,MIN($I11,BA$3)))-(MAX($H11,(EDATE(BA$3,-12)+1)))+1)/(BA$3-(EDATE(BA$3,-12)+1)+1)))*$W11),MAX(0,AZ11-$M11))) | BB11: =IF($K11="","",IF(AND($I11<>"",$I11<=BA$3),0,AZ11-BA11)) | BC11: =IF(OR($K11="",$H11=""),"",MIN(MAX(0,IF($O11="WDV",BB11*$P11*MAX(0,(IF($I11="",BC$3,MIN($I11,BC$3)))-(MAX($H11,(EDATE(BC$3,-12)+1)))+1)/(BC$3-(EDATE(BC$3,-12)+1)+1),IF($N11=0,0,$Q11/$N11*MAX(0,(IF($I11="",BC$3,MIN($I11,BC$3)))-(MAX($H11,(EDATE(BC$3,-12)+1)))+1)/(BC$3-(EDATE(BC$3,-12)+1)+1)))*$W11),MAX(0,BB11-$M11))) | BD11: =IF($K11="","",IF(AND($I11<>"",$I11<=BC$3),0,BB11-BC11)) | BE11: =IF(OR($K11="",$H11=""),"",MIN(MAX(0,IF($O11="WDV",BD11*$P11*MAX(0,(IF($I11="",BE$3,MIN($I11,BE$3)))-(MAX($H11,(EDATE(BE$3,-12)+1)))+1)/(BE$3-(EDATE(BE$3,-12)+1)+1),IF($N11=0,0,$Q11/$N11*MAX(0,(IF($I11="",BE$3,MIN($I11,BE$3)))-(MAX($H11,(EDATE(BE$3,-12)+1)))+1)/(BE$3-(EDATE(BE$3,-12)+1)+1)))*$W11),MAX(0,BD11-$M11))) | BF11: =IF($K11="","",IF(AND($I11<>"",$I11<=BE$3),0,BD11-BE11))
