Workbook

Sheet Read Me
A1: Smartphone Comparison - Fold vs Ultra vs iPhone
A2: Ten phones, compared for an India purchase decision. All data as of 26 August 2026.
A5: What is in this workbook
A6: Spec Comparison | B6: Every phone as a column, ~55 attributes as rows, grouped by section. This is the main table.
A7: Price and Value | B7: Launch MRP against the best street price found today, the usual bank offer, and how far each phone has fallen.
A8: Scorecard | B8: A weighted decision model. Change the weights in row 4 to match what YOU care about and the ranking re-sorts itself.
A9: Best and Unique | B9: The three things each phone does best, the one thing only it does, and what is wrong with it.
A10: Recommendation | B10: The actual answer: what to buy, at what budget, and why waiting two weeks may save you money.
A12: How to use it
A13: 1. | B13: Read the Recommendation sheet first if you just want an answer.
A14: 2. | B14: Open the Scorecard and change the seven weights in row 4 (yellow cells) so they total 100%. The ranking updates.
A15: 3. | B15: If you have a live quote, overwrite the price in column D of the Price and Value sheet. Everything downstream follows.
A17: Colour legend
A18: Blue text | B18: A hardcoded number or judgement typed in by hand -- an input you may change.
A19: Black text | B19: A formula. Do not overwrite these; they recalculate from the inputs.
A20: Green text | B20: A link pulling a value in from another sheet.
A21: Yellow fill | B21: A cell you are expected to edit -- the scorecard weights.
A23: Where the numbers came from
A24: Prices | B24: Public retail and price-tracker listings on 26 Aug 2026: Flipkart, Amazon India, Croma, Samsung India, Smartprix, 91mobiles, MySmartPrice, PriceHistory, SamMobile, Cashify.
A25: Specifications | B25: Manufacturer spec sheets (Samsung India, Apple India) cross-checked against GSMArena, PhoneArena, TechRadar and 91mobiles.
A26: Ratings | B26: The 1-10 category ratings on the Scorecard are MY judgement, not a measurement. They are typed in blue so you can disagree and overwrite them.
A28: Read this before you spend money
A29: Prices move daily | B29: Indian smartphone street prices swing by Rs 5,000-15,000 on bank offers, exchange bonuses and sale events. Every price here is a snapshot, not a quote. Re-check on the day you buy.
A30: Festive season is coming | B30: Flipkart Big Billion Days and Amazon Great Indian Festival typically land late September / early October. Several phones here will be cheaper then.
A31: Two launches are pending | B31: The Galaxy Z Fold 8 already launched (22 Jul 2026), which is why the Fold 7 is discounted. Apple's next event is expected around 9 Sep 2026 -- roughly two weeks from this workbook's date.
A32: Variant matters | B32: Every price here is the base variant listed in the Price and Value sheet. A 512 GB model typically costs Rs 10,000-20,000 more.

Sheet Recommendation
A1: Recommendation
A2: One buyer's view as of 26 August 2026, for a phone bought in India. The Scorecard exists so you can disagree with it.
A4: The short answer
A5: Buy the Galaxy S25 Ultra at roughly Rs 88,000 effective. It carries the full Ultra camera stack -- 200 MP main, 50 MP autofocus ultra-wide, 3x and 5x optical -- a titanium body, a built-in S Pen and updates running to February 2032, for about Rs 32,000 less than the S26 Ultra that improves on it mainly in main-sensor aperture and charging speed. It ranks second on raw quality on the Scorecard and is the highest-scoring phone available below Rs 90,000.
A6: If you are set on iOS: wait until mid-September. Apple's next event is expected around 9 September 2026, and the iPhone 17 has already traded as low as Rs 75,900. Buying it on 26 August is the single most avoidable mistake in this workbook.
A7: If you want the foldable: the Galaxy Z Fold 7 at roughly Rs 155,000 effective is the one worth owning, but it is a want, not a value buy. It ranks near the bottom of the value column and its 4,400 mAh / 25 W battery is the weakest here.
A9: Pick by budget
A10: Budget (effective) | B10: Buy this | C10: Why | D10: Runner-up | E10: Skip
A11: Under Rs 50,000 | B11: iPhone 15 (Rs 51,999, ~Rs 49,000 after card offer) | C11: Cheapest route to a current iOS build with a 48 MP main camera. Accept that Apple Intelligence will never run on it. | D11: A used or refurbished S23 Ultra at around Rs 53,000 | E11: Nothing new from Samsung's flagship line lands here
A12: Rs 60,000 - 75,000 | B12: Galaxy S24 Ultra (Rs 78,999, ~Rs 75,000 after card offer) | C12: Titanium, 200 MP main, a real 5x periscope, Bluetooth S Pen and updates to January 2031. Nothing else at this price has that camera reach. | D12: iPhone 16 at ~Rs 62,000 if you need iOS | E12: Galaxy S23 Ultra -- same money, a year older, updates end Feb 2028
A13: Rs 75,000 - 95,000 | B13: Galaxy S25 Ultra (Rs 92,990, ~Rs 88,000 after card offer) | C13: The value winner of this entire comparison. Near-flagship in every column at a two-generations-old price. | D13: iPhone 17 -- but only after the September event | E13: Do not stretch to the Fold 5 at Rs 108,990 -- cheaper phones here beat it on every axis
A14: Rs 95,000 - 130,000 | B14: Galaxy S26 Ultra (Rs 124,999, ~Rs 120,000 after card offer) | C14: Best Android phone you can buy today: f/1.4 main, 60 W charging, Privacy Display, updates to Feb 2033. | D14: Galaxy Z Fold 6 at ~Rs 105,000 if you specifically want a foldable | E14: Paying full MRP -- it launched at Rs 139,999 and has fallen Rs 15,000 in six months
A15: Above Rs 150,000 | B15: Galaxy Z Fold 7 (Rs 161,855, ~Rs 155,000 after card offer) | C15: The only foldable here with a flagship 200 MP camera and a cover screen you can actually type on. | D15: Galaxy Z Fold 8 at Rs 179,999 if you want current-generation | E15: Buying a Fold for the camera or the battery -- an S26 Ultra beats it on both for about Rs 35,000 less
A17: Pick by what you actually care about
A18: If this matters most | B18: Buy | C18: Because
A19: Camera, no compromise | B19: Galaxy S26 Ultra | C19: f/1.4 main takes in roughly 47% more light than the S24 Ultra, plus a 50 MP autofocus ultra-wide and 5x periscope. Nothing else here is close in low light.
A20: Zoom reach specifically | B20: Galaxy S23 Ultra (used or discounted) | C20: The only phone in this list with a true 10x optical periscope. Samsung has not shipped one since. Buy it knowing security updates end Feb 2028.
A21: Battery that survives a long day | B21: Galaxy S26 Ultra | C21: 5,000 mAh with 60 W wired and 25 W wireless. Real screen-on time of 8-9 hours -- the folds manage 5-6.
A22: Screen real estate / multitasking | B22: Galaxy Z Fold 7 | C22: An 8-inch 120 Hz tablet in your pocket, plus Samsung DeX. If you read contracts, review spreadsheets or run two apps side by side, nothing else competes.
A23: Lightest phone that still feels premium | B23: iPhone 16 (170 g) or iPhone 17 (177 g) | C23: Every Samsung in this list is 214 g or heavier; the Fold 5 is 253 g.
A24: Longest useful life | B24: Galaxy S26 Ultra | C24: Security updates to Feb 2033 -- about 6.5 years from today. The iPhone 17 is close behind at roughly 5.5.
A25: Resale value | B25: iPhone 17 | C25: iPhones hold roughly 60-65% of MRP at two years against 40-50% for Samsung flagships. Factor that in before comparing sticker prices.
A26: Stylus / handwritten notes | B26: Galaxy S25 Ultra or S24 Ultra | C26: Both have an S Pen in the body. The Fold 7 dropped stylus support entirely, and the S24 Ultra is the last one with Bluetooth Air Actions.
A27: Lowest total spend on iOS | B27: iPhone 15 | C27: Under Rs 52,000 for a Dynamic Island iPhone with USB-C. The catch is permanent: no Apple Intelligence, 60 Hz, and Apple India has discontinued it.
A29: Do not buy these right now
A30: Phone | B30: Why not | C30: What to do instead
A31: Galaxy Z Fold 5 (Rs 108,990) | B31: Costs almost the same as a Fold 6 that is a generation newer, with worse ingress protection (IPX8, no dust rating), 253 g, and updates ending Aug 2028. | C31: Pay Rs 1,000 more for the Fold 6, or wait for it to fall below Rs 85,000.
A32: Galaxy S23 Ultra (Rs 74,999) | B32: Priced level with the S24 Ultra but a year older, with under 18 months of security updates left. | C32: Buy the S24 Ultra, unless you specifically want the 10x periscope -- then buy refurbished at around Rs 53,000.
A33: iPhone 17 at Rs 81,900 today | B33: Apple's next event is expected around 9 September 2026, roughly two weeks away. This phone has already traded at Rs 75,900. | C33: Wait two weeks. If you cannot, at least wait for the festive sale in late September.
A34: Galaxy Z Fold 7 if you want value | B34: Ranks last or near-last on score-per-rupee. You are paying roughly Rs 35,000 more than an S26 Ultra for the hinge. | C34: Buy it because you want a foldable, not because it is the better phone. Otherwise buy the S26 Ultra.
A36: Timing - what is about to happen
A37: • 22 July 2026: the Galaxy Z Fold 8 and Fold 8 Ultra launched in India at Rs 179,999 and Rs 199,999, on sale from 8 August. That is exactly why the Fold 7 fell about Rs 13,000 at Croma with another Rs 7,000 off on HDFC cards.
A38: • ~9 September 2026: Apple's autumn event is expected. Reports point to the iPhone 18 Pro, iPhone 18 Pro Max and a foldable iPhone; the standard iPhone 18 is expected to slip to spring 2027. Note the consequence -- if you want a non-Pro iPhone, the iPhone 17 stays Apple's current base model for another six months, so its price will drop but it will not be superseded.
A39: • Late September / early October 2026: Flipkart Big Billion Days and Amazon Great Indian Festival. Historically the deepest cuts of the year on last-generation flagships -- which is most of this list.
A40: • Roughly February 2027: the Galaxy S27 Ultra cycle. If you are buying an S26 Ultra and can wait, its price will fall meaningfully then. If you are buying an S25 Ultra it is already at that stage of the curve, which is the whole argument for it.
A42: How to actually pay less in India
A43: • Stack the offers: card discount (Rs 3,000-7,000 depending on bank and store), exchange bonus, and no-cost EMI are usually combinable. The listed price is rarely the price you pay.
A44: • Exchange bonuses are the biggest lever on Samsung phones -- Flipkart has advertised up to Rs 63,300 total savings on the Fold 7 with a trade-in. They are excluded from this workbook because the number depends entirely on your old phone.
A45: • Check Croma and Samsung's own store, not just Flipkart and Amazon. The best Fold 7 price today is at Croma, not either marketplace.
A46: • Apple discounts differently: Apple India rarely cuts its own price, but Flipkart and Amazon do, and Apple cuts MRP on older models when a new one launches (as it did for the iPhone 16 after the 17).
...

Sheet Spec Comparison
A1: Full Specification Comparison
A2: Read across a row to compare one attribute; read down a column for one phone. Pricing rows are pulled live from the Price and Value sheet.
A3: Section | B3: Attribute | C3: Galaxy Z Fold 7 | D3: Galaxy Z Fold 6 | E3: Galaxy Z Fold 5 | F3: Galaxy S26 Ultra | G3: Galaxy S25 Ultra | H3: Galaxy S24 Ultra | I3: Galaxy S23 Ultra | J3: iPhone 17 | K3: iPhone 16 | L3: iPhone 15
A4: Identity
B5: Brand / family | C5: Samsung – Galaxy Z (foldable) | D5: Samsung – Galaxy Z (foldable) | E5: Samsung – Galaxy Z (foldable) | F5: Samsung – Galaxy S Ultra | G5: Samsung – Galaxy S Ultra | H5: Samsung – Galaxy S Ultra | I5: Samsung – Galaxy S Ultra | J5: Apple – iPhone (base) | K5: Apple – iPhone (base) | L5: Apple – iPhone (base)
B6: Generation age (from launch) | C6: 1 year | D6: 2 years | E6: 3 years | F6: 6 months | G6: 1.5 years | H6: 2.5 years | I6: 3.5 years | J6: 11 months | K6: 2 years | L6: 3 years
B7: India launch date | C7: 25 Jul 2025 | D7: 24 Jul 2024 | E7: 11 Aug 2023 | F7: 25 Feb 2026 | G7: 6 Feb 2025 | H7: 31 Jan 2024 | I7: 17 Feb 2023 | J7: 19 Sep 2025 | K7: 20 Sep 2024 | L7: 22 Sep 2023
B8: Sales status (Aug 2026) | C8: Outgoing – Fold 8 launched 22 Jul 2026 | D8: Clearance / limited stock | E8: End of life – thin stock, mostly grey/refurb | F8: Current flagship | G8: Widely stocked, heavily discounted | H8: Clearance / limited stock | I8: End of life – thin stock | J8: Current – iPhone 18 Pro expected ~9 Sep 2026 | K8: Still officially sold, price cut | L8: Discontinued by Apple India – channel stock only
B9: Form factor | C9: Book-style foldable | D9: Book-style foldable | E9: Book-style foldable | F9: Slab, flat screen | G9: Slab, flat screen | H9: Slab, flat screen | I9: Slab, curved screen | J9: Slab | K9: Slab | L9: Slab
A10: Pricing (India)
B11: Base variant priced here | C11: 12 GB / 256 GB | D11: 12 GB / 256 GB | E11: 12 GB / 256 GB | F11: 12 GB / 256 GB | G11: 12 GB / 256 GB | H11: 12 GB / 256 GB | I11: 8 GB / 256 GB | J11: 256 GB | K11: 128 GB | L11: 128 GB
B12: Launch MRP (base) | C12: ='Price and Value'!C4 -> 174999 | D12: ='Price and Value'!C5 -> 164999 | E12: ='Price and Value'!C6 -> 154999 | F12: ='Price and Value'!C7 -> 139999 | G12: ='Price and Value'!C8 -> 129999 | H12: ='Price and Value'!C9 -> 129999 | I12: ='Price and Value'!C10 -> 124999 | J12: ='Price and Value'!C11 -> 82900 | K12: ='Price and Value'!C12 -> 79900 | L12: ='Price and Value'!C13 -> 79900
B13: Best street price today | C13: ='Price and Value'!D4 -> 161855 | D13: ='Price and Value'!D5 -> 109999 | E13: ='Price and Value'!D6 -> 108990 | F13: ='Price and Value'!D7 -> 124999 | G13: ='Price and Value'!D8 -> 92990 | H13: ='Price and Value'!D9 -> 78999 | I13: ='Price and Value'!D10 -> 74999 | J13: ='Price and Value'!D11 -> 81900 | K13: ='Price and Value'!D12 -> 65900 | L13: ='Price and Value'!D13 -> 51999
B14: Effective price after bank offer | C14: ='Price and Value'!F4 -> 154855 | D14: ='Price and Value'!F5 -> 104999 | E14: ='Price and Value'!F6 -> 104990 | F14: ='Price and Value'!F7 -> 119999 | G14: ='Price and Value'!F8 -> 87990 | H14: ='Price and Value'!F9 -> 74999 | I14: ='Price and Value'!F10 -> 70999 | J14: ='Price and Value'!F11 -> 77900 | K14: ='Price and Value'!F12 -> 61900 | L14: ='Price and Value'!F13 -> 48999
B15: Fall from launch MRP | C15: ='Price and Value'!G4 -> 0.075109001 | D15: ='Price and Value'!G5 -> 0.33333535 | E15: ='Price and Value'!G6 -> 0.29683417 | F15: ='Price and Value'!G7 -> 0.10714362 | G15: ='Price and Value'!G8 -> 0.28468681 | H15: ='Price and Value'!G9 -> 0.39231071 | I15: ='Price and Value'!G10 -> 0.4000032 | J15: ='Price and Value'!G11 -> 0.012062726 | K15: ='Price and Value'!G12 -> 0.17521902 | L15: ='Price and Value'!G13 -> 0.349199
A16: Display
B17: Main screen size | C17: 8.0" | D17: 7.6" | E17: 7.6" | F17: 6.9" | G17: 6.9" | H17: 6.8" | I17: 6.8" | J17: 6.3" | K17: 6.1" | L17: 6.1"
B18: Main screen resolution | C18: 2184 x 1968 QXGA+ | D18: 2160 x 1856 QXGA+ | E18: 2176 x 1812 QXGA+ | F18: 3120 x 1440 QHD+ | G18: 3120 x 1440 QHD+ | H18: 3120 x 1440 QHD+ | I18: 3088 x 1440 QHD+ | J18: 2622 x 1206 | K18: 2556 x 1179 | L18: 2556 x 1179
B19: Panel type | C19: Dynamic AMOLED 2X (foldable) | D19: Dynamic AMOLED 2X (foldable) | E19: Dynamic AMOLED 2X (foldable) | F19: Dynamic AMOLED 2X | G19: Dynamic AMOLED 2X | H19: Dynamic AMOLED 2X | I19: Dynamic AMOLED 2X | J19: Super Retina XDR OLED | K19: Super Retina XDR OLED | L19: Super Retina XDR OLED
B20: Refresh rate | C20: 1–120 Hz adaptive | D20: 1–120 Hz adaptive | E20: 1–120 Hz adaptive | F20: 1–120 Hz adaptive | G20: 1–120 Hz adaptive | H20: 1–120 Hz adaptive | I20: 1–120 Hz adaptive | J20: 1–120 Hz ProMotion | K20: 60 Hz only | L20: 60 Hz only
B21: Peak brightness (claimed) | C21: 2,600 nits | D21: 2,600 nits | E21: 1,750 nits | F21: 2,600 nits | G21: 2,600 nits | H21: 2,600 nits | I21: 1,750 nits | J21: 3,000 nits | K21: 2,000 nits | L21: 2,000 nits
B22: Always-on display | C22: Yes | D22: Yes | E22: Yes | F22: Yes | G22: Yes | H22: Yes | I22: Yes | J22: Yes | K22: No | L22: No
B23: Cover / secondary screen | C23: 6.5" FHD+ 120 Hz (usable width) | D23: 6.3" 120 Hz (narrow) | E23: 6.2" 120 Hz (very narrow) | F23: n/a | G23: n/a | H23: n/a | I23: n/a | J23: n/a | K23: n/a | L23: n/a
B24: Front glass / protection | C24: Gorilla Glass Ceramic 2 (cover) | D24: Gorilla Glass Victus 2 (cover) | E24: Gorilla Glass Victus 2 (cover) | F24: Gorilla Armor 3 (anti-reflective) | G24: Gorilla Armor 2 (anti-reflective) | H24: Gorilla Armor (anti-reflective) | I24: Gorilla Glass Victus 2 | J24: Ceramic Shield 2 | K24: Ceramic Shield | L24: Ceramic Shield
A25: Performance
B26: Chipset | C26: Snapdragon 8 Elite for Galaxy | D26: Snapdragon 8 Gen 3 for Galaxy | E26: Snapdragon 8 Gen 2 for Galaxy | F26: Snapdragon 8 Elite Gen 5 for Galaxy | G26: Snapdragon 8 Elite for Galaxy | H26: Snapdragon 8 Gen 3 for Galaxy | I26: Snapdragon 8 Gen 2 for Galaxy | J26: Apple A19 | K26: Apple A18 | L26: Apple A16 Bionic
B27: Fabrication node | C27: 3 nm | D27: 4 nm | E27: 4 nm | F27: 3 nm | G27: 3 nm | H27: 4 nm | I27: 4 nm | J27: 3 nm | K27: 3 nm | L27: 4 nm
B28: Peak clock | C28: 4.47 GHz | D28: 3.39 GHz | E28: 3.36 GHz | F28: 4.74 GHz | G28: 4.47 GHz | H28: 3.39 GHz | I28: 3.36 GHz | J28: ~4.3 GHz | K28: ~4.0 GHz | L28: ~3.5 GHz
B29: Geekbench 6 multi-core (indicative) | C29: ~9,700 | D29: ~7,200 | E29: ~5,100 | F29: ~11,400 | G29: ~10,100 | H29: ~7,200 | I29: ~5,000 | J29: ~8,500 | K29: ~8,200 | L29: ~6,600
B30: RAM options | C30: 12 GB / 16 GB | D30: 12 GB | E30: 12 GB | F30: 12 GB / 16 GB | G30: 12 GB | H30: 12 GB | I30: 8 GB / 12 GB | J30: 8 GB | K30: 8 GB | L30: 6 GB
B31: Storage options | C31: 256 GB / 512 GB / 1 TB | D31: 256 GB / 512 GB / 1 TB | E31: 256 GB / 512 GB / 1 TB | F31: 256 GB / 512 GB / 1 TB | G31: 256 GB / 512 GB / 1 TB | H31: 256 GB / 512 GB / 1 TB | I31: 256 GB / 512 GB / 1 TB | J31: 256 GB / 512 GB | K31: 128 / 256 / 512 GB | L31: 128 / 256 / 512 GB
B32: Sustained-load cooling | C32: Vapour chamber (enlarged) | D32: Vapour chamber | E32: Vapour chamber | F32: Vapour chamber (largest in series) | G32: Vapour chamber | H32: Vapour chamber | I32: Vapour chamber | J32: Vapour chamber (new for iPhone 17) | K32: Graphite only | L32: Graphite only
A33: Camera
B34: Main camera | C34: 200 MP f/1.7 OIS | D34: 50 MP f/1.8 OIS | E34: 50 MP f/1.8 OIS | F34: 200 MP f/1.4 OIS | G34: 200 MP f/1.7 OIS | H34: 200 MP f/1.7 OIS | I34: 200 MP f/1.7 OIS | J34: 48 MP f/1.6 Fusion | K34: 48 MP f/1.6 Fusion | L34: 48 MP f/1.6
B35: Ultra-wide | C35: 12 MP f/2.2 | D35: 12 MP f/2.2 | E35: 12 MP f/2.2 | F35: 50 MP f/1.9 with autofocus | G35: 50 MP f/1.9 with autofocus | H35: 12 MP f/2.2 | I35: 12 MP f/2.2 | J35: 48 MP f/2.2 with macro | K35: 12 MP f/2.2 with macro | L35: 12 MP f/2.4
B36: Telephoto 1 | C36: 10 MP 3x f/2.4 | D36: 10 MP 3x f/2.4 | E36: 10 MP 3x f/2.4 | F36: 10 MP 3x f/2.4 | G36: 10 MP 3x f/2.4 | H36: 10 MP 3x f/2.4 | I36: 10 MP 3x f/2.4 | J36: None (2x sensor crop) | K36: None (2x sensor crop) | L36: None (2x sensor crop)
B37: Telephoto 2 (periscope) | C37: None | D37: None | E37: None | F37: 50 MP 5x f/2.8 periscope | G37: 50 MP 5x f/3.4 periscope | H37: 50 MP 5x f/3.4 periscope | I37: 10 MP 10x f/4.9 periscope | J37: None | K37: None | L37: None
B38: Best optical zoom | C38: 3x | D38: 3x | E38: 3x | F38: 5x (100x Space Zoom digital) | G38: 5x (100x digital) | H38: 5x (100x digital) | I38: 10x (100x digital) | J38: 2x (crop) | K38: 2x (crop) | L38: 2x (crop)
B39: Selfie camera | C39: 10 MP cover + 10 MP inner | D39: 10 MP cover + 4 MP under-display | E39: 10 MP cover + 4 MP under-display | F39: 12 MP autofocus | G39: 12 MP autofocus | H39: 12 MP autofocus | I39: 12 MP autofocus | J39: 18 MP Center Stage (square sensor) | K39: 12 MP TrueDepth | L39: 12 MP TrueDepth
B40: Max video | C40: 8K30 / 4K120 | D40: 8K30 / 4K60 | E40: 8K30 / 4K60 | F40: 8K30 / 4K120 (10-bit HDR, LOG) | G40: 8K30 / 4K120 (LOG) | H40: 8K30 / 4K120 | I40: 8K30 / 4K60 | J40: 4K60 Dolby Vision, dual capture | K40: 4K60 Dolby Vision | L40: 4K60 Dolby Vision
...

Sheet Price and Value
A1: Price and Value - India, 26 August 2026
A2: Best mainstream online price found for the base variant. Bank offer is the typical card discount running at that store; exchange bonuses are excluded because they depend on your old phone.
A3: Phone | B3: Base variant | C3: Launch MRP | D3: Best street price today | E3: Typical bank offer | F3: Effective price | G3: Fall from launch MRP | H3: Where | I3: What is going on with this price
A4: Galaxy Z Fold 7 | B4: 12/256 GB | C4: 174999 | D4: 161855 | E4: 7000 | F4: =D4-E4 -> 154855 | G4: =IF(C4=0,"",(C4-D4)/C4) -> 0.075109001 | H4: Croma / Samsung.com | I4: Cut ~Rs 13,000 after the Fold 8 launched on 22 Jul 2026; HDFC card knocks off another Rs 7,000.
A5: Galaxy Z Fold 6 | B5: 12/256 GB | C5: 164999 | D5: 109999 | E5: 5000 | F5: =D5-E5 -> 104999 | G5: =IF(C5=0,"",(C5-D5)/C5) -> 0.33333535 | H5: Amazon | I5: Clearance pricing; stock is thinning. Verify it is a fresh, sealed India unit before paying.
A6: Galaxy Z Fold 5 | B6: 12/256 GB | C6: 154999 | D6: 108990 | E6: 4000 | F6: =D6-E6 -> 104990 | G6: =IF(C6=0,"",(C6-D6)/C6) -> 0.29683417 | H6: Flipkart / Croma | I6: Barely cheaper than a Fold 6 that is a full generation newer -- weak buy at this price.
A7: Galaxy S26 Ultra | B7: 12/256 GB | C7: 139999 | D7: 124999 | E7: 5000 | F7: =D7-E7 -> 119999 | G7: =IF(C7=0,"",(C7-D7)/C7) -> 0.10714362 | H7: Flipkart | I7: Rs 15,000 below February launch MRP after six months. Expect deeper cuts in the festive sale.
A8: Galaxy S25 Ultra | B8: 12/256 GB | C8: 129999 | D8: 92990 | E8: 5000 | F8: =D8-E8 -> 87990 | G8: =IF(C8=0,"",(C8-D8)/C8) -> 0.28468681 | H8: Amazon | I8: Record-low territory; has traded as low as ~Rs 88,500. The value pick of the Ultra line.
A9: Galaxy S24 Ultra | B9: 12/256 GB | C9: 129999 | D9: 78999 | E9: 4000 | F9: =D9-E9 -> 74999 | G9: =IF(C9=0,"",(C9-D9)/C9) -> 0.39231071 | H9: Flipkart | I9: Effective ~Rs 75,000 with bank offer. Still a titanium Ultra with a 5x periscope.
A10: Galaxy S23 Ultra | B10: 8/256 GB | C10: 124999 | D10: 74999 | E10: 4000 | F10: =D10-E10 -> 70999 | G10: =IF(C10=0,"",(C10-D10)/C10) -> 0.4000032 | H10: Amazon / Flipkart | I10: Priced against the S24 Ultra but a year older with ~1.5 yrs of updates left. Refurb ~Rs 53,000.
A11: iPhone 17 | B11: 256 GB | C11: 82900 | D11: 81900 | E11: 4000 | F11: =D11-E11 -> 77900 | G11: =IF(C11=0,"",(C11-D11)/C11) -> 0.012062726 | H11: Flipkart | I11: Has touched Rs 75,900. Apple's next event is ~9 Sep 2026 -- prices historically move then.
A12: iPhone 16 | B12: 128 GB | C12: 79900 | D12: 65900 | E12: 4000 | F12: =D12-E12 -> 61900 | G12: =IF(C12=0,"",(C12-D12)/C12) -> 0.17521902 | H12: Flipkart | I12: Official MRP cut after the iPhone 17 launch; has traded near Rs 62,900.
A13: iPhone 15 | B13: 128 GB | C13: 79900 | D13: 51999 | E13: 3000 | F13: =D13-E13 -> 48999 | G13: =IF(C13=0,"",(C13-D13)/C13) -> 0.349199 | H13: Flipkart / Amazon | I13: Discontinued by Apple India -- channel stock only. No Apple Intelligence, ever.
A15: Cheapest today | C15: =MIN(F4:F13) -> 48999
A16: Dearest today | C16: =MAX(F4:F13) -> 154855
A17: Spread | C17: =C16-C15 -> 105856
A19: Prices are a snapshot taken on 26 August 2026 from public retail and price-tracker listings (Flipkart, Amazon India, Croma, Samsung India, Smartprix, 91mobiles, MySmartPrice, PriceHistory, SamMobile). Overwrite column D with a live quote and every dependent figure in this workbook updates.

Sheet Scorecard
A1: Weighted Scorecard - make it your decision, not mine
A2: The 1-10 ratings are my judgement (blue). The weights in row 4 are yours to change (yellow). Everything in black is a formula and re-ranks the moment you edit a weight.
A4: Weights (edit - must total 100%) | B4: 0.15 | C4: 0.15 | D4: 0.2 | E4: 0.15 | F4: 0.1 | G4: 0.1 | H4: 0.15 | I4: =SUM(B4:H4) -> 1 | J4: =IF(ROUND(SUM(B4:H4),4)=1,"Weights OK","FIX: weights must total 100%") -> Weights OK
A6: Phone | B6: Performance | C6: Display | D6: Camera | E6: Battery & charging | F6: Software support life | G6: Design & portability | H6: Features & ecosystem | I6: Weighted score (0-10) | J6: Rank on score | K6: Effective price | L6: Score per Rs 10,000 | M6: Rank on value
A7: Galaxy Z Fold 7 | B7: 9 | C7: 10 | D7: 8 | E7: 6 | F7: 9 | G7: 8 | H7: 10 | I7: =SUMPRODUCT($B$4:$H$4,B7:H7) -> 8.55 | J7: =RANK(I7,$I$7:$I$16) -> 4 | K7: =INDEX('Price and Value'!$F$4:$F$13,MATCH($A7,'Price and Value'!$A$4:$A$13,0)) -> 154855 | L7: =IF(K7=0,"",I7/(K7/10000)) -> 0.55212941 | M7: =RANK(L7,$L$7:$L$16) -> 10
A8: Galaxy Z Fold 6 | B8: 8 | C8: 9 | D8: 7 | E8: 6 | F8: 8 | G8: 6 | H8: 9 | I8: =SUMPRODUCT($B$4:$H$4,B8:H8) -> 7.6 | J8: =RANK(I8,$I$7:$I$16) -> 8 | K8: =INDEX('Price and Value'!$F$4:$F$13,MATCH($A8,'Price and Value'!$A$4:$A$13,0)) -> 104999 | L8: =IF(K8=0,"",I8/(K8/10000)) -> 0.72381642 | M8: =RANK(L8,$L$7:$L$16) -> 8
A9: Galaxy Z Fold 5 | B9: 7 | C9: 8 | D9: 6.5 | E9: 5.5 | F9: 6 | G9: 5 | H9: 8 | I9: =SUMPRODUCT($B$4:$H$4,B9:H9) -> 6.675 | J9: =RANK(I9,$I$7:$I$16) -> 10 | K9: =INDEX('Price and Value'!$F$4:$F$13,MATCH($A9,'Price and Value'!$A$4:$A$13,0)) -> 104990 | L9: =IF(K9=0,"",I9/(K9/10000)) -> 0.63577484 | M9: =RANK(L9,$L$7:$L$16) -> 9
A10: Galaxy S26 Ultra | B10: 10 | C10: 10 | D10: 10 | E10: 9 | F10: 10 | G10: 8 | H10: 9 | I10: =SUMPRODUCT($B$4:$H$4,B10:H10) -> 9.5 | J10: =RANK(I10,$I$7:$I$16) -> 1 | K10: =INDEX('Price and Value'!$F$4:$F$13,MATCH($A10,'Price and Value'!$A$4:$A$13,0)) -> 119999 | L10: =IF(K10=0,"",I10/(K10/10000)) -> 0.79167326 | M10: =RANK(L10,$L$7:$L$16) -> 7
A11: Galaxy S25 Ultra | B11: 9 | C11: 9.5 | D11: 9.5 | E11: 8 | F11: 9 | G11: 8 | H11: 9 | I11: =SUMPRODUCT($B$4:$H$4,B11:H11) -> 8.925 | J11: =RANK(I11,$I$7:$I$16) -> 2 | K11: =INDEX('Price and Value'!$F$4:$F$13,MATCH($A11,'Price and Value'!$A$4:$A$13,0)) -> 87990 | L11: =IF(K11=0,"",I11/(K11/10000)) -> 1.0143198 | M11: =RANK(L11,$L$7:$L$16) -> 6
A12: Galaxy S24 Ultra | B12: 8 | C12: 9 | D12: 9 | E12: 8 | F12: 8 | G12: 7.5 | H12: 9 | I12: =SUMPRODUCT($B$4:$H$4,B12:H12) -> 8.45 | J12: =RANK(I12,$I$7:$I$16) -> 5 | K12: =INDEX('Price and Value'!$F$4:$F$13,MATCH($A12,'Price and Value'!$A$4:$A$13,0)) -> 74999 | L12: =IF(K12=0,"",I12/(K12/10000)) -> 1.1266817 | M12: =RANK(L12,$L$7:$L$16) -> 3
A13: Galaxy S23 Ultra | B13: 7 | C13: 8 | D13: 8.5 | E13: 8 | F13: 6 | G13: 7 | H13: 8.5 | I13: =SUMPRODUCT($B$4:$H$4,B13:H13) -> 7.725 | J13: =RANK(I13,$I$7:$I$16) -> 7 | K13: =INDEX('Price and Value'!$F$4:$F$13,MATCH($A13,'Price and Value'!$A$4:$A$13,0)) -> 70999 | L13: =IF(K13=0,"",I13/(K13/10000)) -> 1.0880435 | M13: =RANK(L13,$L$7:$L$16) -> 5
A14: iPhone 17 | B14: 9.5 | C14: 9 | D14: 8.5 | E14: 8 | F14: 9 | G14: 9 | H14: 8 | I14: =SUMPRODUCT($B$4:$H$4,B14:H14) -> 8.675 | J14: =RANK(I14,$I$7:$I$16) -> 3 | K14: =INDEX('Price and Value'!$F$4:$F$13,MATCH($A14,'Price and Value'!$A$4:$A$13,0)) -> 77900 | L14: =IF(K14=0,"",I14/(K14/10000)) -> 1.1136072 | M14: =RANK(L14,$L$7:$L$16) -> 4
A15: iPhone 16 | B15: 8.5 | C15: 7 | D15: 7.5 | E15: 7.5 | F15: 8.5 | G15: 9 | H15: 7.5 | I15: =SUMPRODUCT($B$4:$H$4,B15:H15) -> 7.825 | J15: =RANK(I15,$I$7:$I$16) -> 6 | K15: =INDEX('Price and Value'!$F$4:$F$13,MATCH($A15,'Price and Value'!$A$4:$A$13,0)) -> 61900 | L15: =IF(K15=0,"",I15/(K15/10000)) -> 1.2641357 | M15: =RANK(L15,$L$7:$L$16) -> 2
A16: iPhone 15 | B16: 7 | C16: 6.5 | D16: 7 | E16: 6.5 | F16: 6.5 | G16: 9 | H16: 6.5 | I16: =SUMPRODUCT($B$4:$H$4,B16:H16) -> 6.925 | J16: =RANK(I16,$I$7:$I$16) -> 9 | K16: =INDEX('Price and Value'!$F$4:$F$13,MATCH($A16,'Price and Value'!$A$4:$A$13,0)) -> 48999 | L16: =IF(K16=0,"",I16/(K16/10000)) -> 1.4132941 | M16: =RANK(L16,$L$7:$L$16) -> 1
A19: How to read this
A20: Weighted score is the quality of the phone alone, ignoring price -- SUMPRODUCT of the seven ratings against your weights.
A21: Score per Rs 10,000 divides that score by the effective price. Higher is better -- but read it knowing what it rewards: dividing by price structurally favours the cheapest phone, which is why the iPhone 15 tops it. Use it to spot phones that are over-priced for what they are, not as a shopping list.
A22: Effective price is pulled from the Price and Value sheet (best street price minus the typical bank offer).
A24: What the ratings mean
A25: Performance: chipset generation, sustained load behaviour, RAM headroom.
A26: Display: size, resolution, refresh rate, brightness, and for the folds the value of the second screen.
A27: Camera: the whole system -- main sensor, ultra-wide, optical zoom reach, video, processing.
A28: Battery and charging: capacity, real screen-on time, wired and wireless charging speed.
A29: Software support life: how many years of OS and security updates remain from today, not from launch.
A30: Design and portability: weight, thickness, ingress protection, one-handed use, materials.
A31: Features and ecosystem: stylus, DeX or Continuity, multitasking, AI features, accessory ecosystem.
A33: These ratings are judgement, not measurement. Every one of them is a blue input you can overwrite -- if you never use a stylus, drop 'Features and ecosystem' to 5% and watch the order change.

Sheet Best and Unique
A1: Best Features, Unique Features and the Catch
A2: What each phone genuinely does well, the one thing only it does, and what you give up by choosing it.
A3: Phone | B3: Three things it does best | C3: Only on this phone | D3: What you give up | E3: Who it actually suits
A4: Galaxy Z Fold 7 | B4: • 8.0-inch tablet screen that folds into a normal-width 6.5-inch phone • 200 MP Ultra-grade main camera -- the first fold that does not compromise the camera • 4.2 mm unfolded / 215 g -- lighter than most slab flagships | C4: The only foldable here with a genuinely usable cover screen AND a flagship 200 MP sensor. | D4: • 4,400 mAh with only 25 W charging -- weakest battery story in this workbook • S Pen support was removed; IP48 means no dust-tight rating | E4: Someone who reads, edits documents and runs two apps side by side on the move.
A5: Galaxy Z Fold 6 | B5: • Same 7-year update promise as the newest phones, at clearance price • S Pen Fold Edition support for handwritten mark-up • IP48 and a Snapdragon 8 Gen 3 that is still comfortably fast | C5: Cheapest way into a modern, still-supported book foldable with stylus support. | D5: • Narrow 6.3-inch cover screen is awkward for typing • Only a 50 MP main camera and a 4 MP under-display selfie | E5: A foldable-curious buyer who will not pay Fold 7 money.
A6: Galaxy Z Fold 5 | B6: • Lowest entry price into a Galaxy Fold • S Pen supported • Snapdragon 8 Gen 2 still handles everything mainstream | C6: Nothing unique remains -- it is superseded on every axis by the Fold 6. | D6: • Security updates end Aug 2028; only Android 17 to come • IPX8 with no dust rating, 253 g, 13.4 mm folded -- the thickest and heaviest here | E6: Nobody at the current asking price. Only worth it below roughly Rs 85,000.
A7: Galaxy S26 Ultra | B7: • f/1.4 main camera -- about 47% more light than the S24 Ultra, best low-light in this list • 60 W wired and 25 W wireless charging on a 5,000 mAh cell • Privacy Display that narrows the viewing angle at pixel level | C7: The pixel-level Privacy Display -- genuinely useful for reading confidential material in public. | D7: • Costs roughly Rs 32,000 more than an S25 Ultra that does 90% of the same job • Still only a 10 MP 3x tele; the mid-zoom range is unchanged since 2022 | E7: Someone who wants the best Android phone available and keeps a phone 4+ years.
A8: Galaxy S25 Ultra | B8: • Full zoom stack -- 200 MP main, 50 MP ultra-wide with autofocus, 3x and 5x optical • Titanium frame, anti-reflective Gorilla Armor 2 glass, built-in S Pen • Updates to Feb 2032 -- 5.5 years of runway left | C8: Best price-to-capability ratio in the entire workbook at roughly Rs 93,000. | D8: • 45 W charging feels slow next to the S26 Ultra's 60 W • S Pen lost Bluetooth Air Actions from the S24 Ultra | E8: Almost everyone shopping for a premium Android phone right now.
A9: Galaxy S24 Ultra | B9: • 50 MP 5x periscope and 200 MP main -- the same camera hardware philosophy as today's Ultras • First titanium, flat-screen, anti-reflective Ultra • Updates run to Jan 2031 | C9: Cheapest phone here with a true 5x periscope plus a Bluetooth S Pen with Air Actions. | D9: • Snapdragon 8 Gen 3 is two generations behind; runs warmer under sustained load • 232 g and 12 GB RAM ceiling | E9: A value-first buyer who wants Ultra features around Rs 75,000.
A10: Galaxy S23 Ultra | B10: • The only phone in this comparison with a true 10x optical periscope • Bluetooth S Pen with Air Actions • 5,000 mAh with 45 W charging | C10: 10x optical zoom -- Samsung has not shipped it since, so this is the last of its kind. | D10: • Security updates end Feb 2028 -- under 18 months of runway • At roughly Rs 75,000 it is priced against a newer, better S24 Ultra | E10: A zoom specialist who understands the short support window. Otherwise skip.
A11: iPhone 17 | B11: • 120 Hz ProMotion with always-on -- the first non-Pro iPhone to get it • 256 GB base storage at the old 128 GB price • 18 MP Center Stage front camera that auto-frames and shoots landscape while held upright | C11: The Center Stage square front sensor -- no other phone here reframes a selfie without rotating. | D11: • No telephoto lens at all; 2x is a sensor crop • USB-C is still capped at USB 2.0 transfer speeds | E11: Anyone in the Apple ecosystem buying to keep for five or more years.
A12: iPhone 16 | B12: • A18 with Apple Intelligence, the cheapest AI-capable iPhone here • Camera Control button and Action button • 170 g -- the lightest phone in the comparison | C12: Cheapest new iPhone that will run Apple Intelligence for its whole life. | D12: • 60 Hz screen in 2026 at roughly Rs 66,000 • 12 MP ultra-wide and no telephoto | E12: A budget-conscious iPhone buyer who can live without a high refresh rate.
A13: iPhone 15 | B13: • Dynamic Island and a 48 MP main camera under Rs 52,000 • USB-C, so it shares chargers with everything else • Best resale value per rupee spent in this workbook | C13: The cheapest way into a current-generation iOS experience -- but with a hard ceiling. | D13: • Will never run Apple Intelligence -- A16 and 6 GB RAM are below the bar • 60 Hz, discontinued by Apple India, shortest support runway of the three iPhones | E13: A first-time iPhone buyer on a strict budget who does not care about AI features.
