Workbook

Sheet Receipt Details
A1: Ria & Sejal — Birthday Party Receipt Register
A2: Date of party: 23-08-2026 · transcribed from the handwritten register (2 pages) · all amounts in ₹
A4: Sr. No. | B4: Name of giver | C4: Name (as written) | D4: Place / reference | E4: Page | F4: Sejal (₹) | G4: Ria (₹) | H4: Common / not specified (₹) | I4: Total (₹) | J4: Verify? | K4: Remarks
A5: 1 | B5: Kiran Somabhai Vyas | C5: કિરણ સોમાભાઈ વ્યાસ | D5: — | E5: 1 | I5: =SUM(F5:H5) | J5: No | K5: Casserole set given to Sejal — gift in kind, no cash amount
A6: 2 | B6: Kishorbhai Hiralal Patel | C6: કિશોરભાઈ હીરાલાલ પટેલ | D6: Andhavas / sankada | E6: 1 | G6: 5100 | I6: =SUM(F6:H6) | J6: No | K6: Marked 'રાયુ' (Ria)
A7: 3 | B7: Jinal Prajapati | C7: જીનલ પ્રજાપતિ | D7: — | E7: 1 | F7: 500 | I7: =SUM(F7:H7) | J7: No | K7: Marked 'સેજલને'
A8: 4 | B8: Aman Shah / Manasi Soni | C8: અમન શાહ, માનસી સોની | D8: — | E8: 1 | H8: 1000 | I8: =SUM(F8:H8) | J8: Yes | K8: First name unclear
A9: 5 | B9: Dhaval Mukeshbhai Jadhav | C9: ધવલ મુકેશભાઈ જાધવ | D9: 40 Sugandha row, Maravad | E9: 1 | H9: 501 | I9: =SUM(F9:H9) | J9: Yes
A10: 6 | B10: Pravin Rajput (Kiran) | C10: પ્રવીણ રાજપૂત (કીરણ) | D10: Kirtan Kusela | E10: 1 | H10: 501 | I10: =SUM(F10:H10) | J10: Yes
A11: 7 | B11: Lakshmanbhai Agrawal | C11: લક્ષ્મણભાઈ અગ્રવાલ | D11: Sejal kaka | E11: 1 | G11: 1100 | I11: =SUM(F11:H11) | J11: No | K11: Marked 'રાયુ'
A12: 8 | B12: Lakshmanbhai Agrawal | C12: લક્ષ્મણભાઈ અગ્રવાલ | D12: Sejal kaka (ditto) | E12: 1 | F12: 1100 | I12: =SUM(F12:H12) | J12: No
A13: 9 | B13: Flower bouquet (Kirti) | C13: ફૂલોના બુકે (કીર્તિ) | D13: — | E13: 1 | G13: 500 | I13: =SUM(F13:H13) | J13: No
A14: 10 | B14: Flower bouquet (Kirti) | C14: ફૂલોના બુકે (કીર્તિ) | D14: ditto | E14: 1 | F14: 500 | I14: =SUM(F14:H14) | J14: No
A15: 11 | B15: Ketan Dhaneshbhai Agrawal | C15: કેતન ધનેશભાઈ અગ્રવાલ | D15: Sangar kaka | E15: 1 | G15: 1100 | I15: =SUM(F15:H15) | J15: No
A16: 12 | B16: Ketan Dhaneshbhai Agrawal | C16: કેતન ધનેશભાઈ અગ્રવાલ | D16: ditto | E16: 1 | F16: 1100 | I16: =SUM(F16:H16) | J16: No
A17: 13 | B17: Salamsinh Agrawal | C17: સલમસિંહ અગ્રવાલ | D17: Sejal kaka | E17: 1 | G17: 1100 | I17: =SUM(F17:H17) | J17: Yes | K17: Name reading uncertain
A18: 14 | B18: Salamsinh Agrawal | C18: સલમસિંહ અગ્રવાલ | D18: ditto | E18: 1 | F18: 1100 | I18: =SUM(F18:H18) | J18: Yes
A19: 15 | B19: Nilam Dhanendra Gupta | C19: નીલમ ધનેન્દ્ર ગુપ્તા | D19: — | E19: 1 | F19: 500 | G19: 500 | I19: =SUM(F19:H19) | J19: No | K19: Braced in the book as 500 Sejal + 500 Ria
A20: 16 | B20: Kadri Gaurav Agrawal | C20: કાદ્રી ગૌરવ અગ્રવાલ | D20: — | E20: 1 | H20: 500 | I20: =SUM(F20:H20) | J20: Yes | K20: No child named against this entry
A21: 17 | B21: Ravi Shubhamkumar Agrawal | C21: રવિ શુભમકુમાર અગ્રવાલ | D21: — | E21: 1 | F21: 500 | I21: =SUM(F21:H21) | J21: No
A22: 18 | B22: Neha Shubhamkumar Agrawal | C22: નેહા શુભમકુમાર અગ્રવાલ | D22: ditto | E22: 1 | G22: 500 | I22: =SUM(F22:H22) | J22: No
A23: 19 | B23: Niya Pritesh Agrawal | C23: નીયા પ્રીતેશ અગ્રવાલ | D23: — | E23: 1 | F23: 500 | I23: =SUM(F23:H23) | J23: No
A24: 20 | B24: Niya Pritesh Agrawal | C24: નીયા પ્રીતેશ અગ્રવાલ | D24: ditto | E24: 1 | G24: 500 | I24: =SUM(F24:H24) | J24: No
A25: 21 | B25: Keyur Agrawal | C25: કેયૂર અગ્રવાલ | D25: — | E25: 1 | F25: 1100 | I25: =SUM(F25:H25) | J25: No
A26: 22 | B26: Keyur Agrawal | C26: કેયૂર અગ્રવાલ | D26: ditto | E26: 1 | G26: 1100 | I26: =SUM(F26:H26) | J26: No
A27: 23 | B27: Shakeshbhai Agrawal | C27: શાકેશભાઈ અગ્રવાલ | D27: Anjali nayapa | E27: 1 | H27: 701 | I27: =SUM(F27:H27) | J27: Yes
A28: 24 | B28: Rahul Kanjibhai Patel | C28: રાહુલ કાનજીભાઈ પટેલ | D28: Gam Gorasa | E28: 1 | H28: 700 | I28: =SUM(F28:H28) | J28: Yes
A29: 25 | B29: Somaben Vyas | C29: સોમાબેન વ્યાસ | D29: Ambalkaram | E29: 1 | H29: 500 | I29: =SUM(F29:H29) | J29: No
A30: 26 | B30: Nilaben Lad | C30: નીલાબેન લાડ | D30: Ambalkaram | E30: 1 | H30: 500 | I30: =SUM(F30:H30) | J30: No
A31: 27 | B31: Pramilaben Patel | C31: પ્રમીલાબેન પટેલ | D31: Ambalkaram | E31: 1 | H31: 500 | I31: =SUM(F31:H31) | J31: No
A32: 28 | B32: Unnatiben Narendrakumar Patel | C32: ઉન્નતીબેન નરેન્દ્રકુમાર પટેલ | D32: Ahmedabad | E32: 1 | H32: 500 | I32: =SUM(F32:H32) | J32: Yes
A33: 29 | B33: Ochhiben Paragkumar Patel | C33: ઓછીબેન પરાગકુમાર પટેલ | D33: Ahmedabad | E33: 2 | H33: 500 | I33: =SUM(F33:H33) | J33: Yes
A34: 30 | B34: Kaushalyaben Hudiya | C34: કૌશલ્યાબેન હુડીયા | D34: Ambalkaram | E34: 2 | H34: 500 | I34: =SUM(F34:H34) | J34: Yes
A35: 31 | B35: Shariben Pandya | C35: શારીબેન પંડ્યા | D35: Ambalkaram | E35: 2 | H35: 500 | I35: =SUM(F35:H35) | J35: Yes
A36: 32 | B36: Ushaben Joshi | C36: ઉષાબેન જોષી | D36: Ambalkaram | E36: 2 | H36: 501 | I36: =SUM(F36:H36) | J36: No
A37: 33 | B37: Kanjibhai Darji | C37: કાનજીભાઈ દરજી | D37: Ambalkaram | E37: 2 | H37: 501 | I37: =SUM(F37:H37) | J37: No
A38: 34 | B38: Ashokbhai Soni | C38: અશોકભાઈ સોની | D38: Ambalkaram | E38: 2 | H38: 500 | I38: =SUM(F38:H38) | J38: Yes
... A41: 37 | B41: Nilavbhai Darji | C41: નીળવભાઈ દરજી | D41: Ambalkaram | E41: 2 | H41: 1001 | I41: =SUM(F41:H41) | J41: Yes
A42: 38 | B42: Dhanvanarayan Mistri | C42: ધનવનારાયણ મીસ્ત્રી | D42: Kirtan Kumar A/1 | E42: 2 | G42: 501 | I42: =SUM(F42:H42) | J42: No | K42: Marked 'રાયા'
A43: 39 | B43: Ajaybhai Pancholi | C43: અજયભાઈ પંચોલી | D43: Kirtan Kumesh A/2 | E43: 2 | G43: 501 | I43: =SUM(F43:H43) | J43: No | K43: Marked 'રાયા'
...

Sheet Summary
A1: Bifurcation Summary
A2: Every figure below is a formula over the 'Receipt Details' sheet.
A4: Head | B4: Amount (₹) | C4: No. of entries
A5: Sejal | B5: =SUM('Receipt Details'!F5:F63) | C5: =COUNT('Receipt Details'!F5:F63)
A6: Ria | B6: =SUM('Receipt Details'!G5:G63) | C6: =COUNT('Receipt Details'!G5:G63)
A7: Common / not specified | B7: =SUM('Receipt Details'!H5:H63) | C7: =COUNT('Receipt Details'!H5:H63)
A8: Grand total | B8: =SUM(B5:B7) | C8: =SUM(C5:C7)
A10: If the common / unmarked amount is shared equally
A11: Sejal (own + half of common) | B11: =B5+B7/2
A12: Ria (own + half of common) | B12: =B6+B7/2
A14: Reconciliation with the totals written in the register
A15: Page 1 total as per this sheet | B15: =SUMIF('Receipt Details'!E5:E63,1,'Receipt Details'!I5:I63)
A16: Page 1 total written in the register | B16: 24303
A17: Difference (page 1) | B17: =B15-B16
A18: Grand total as per this sheet | B18: =B8
A19: Grand total written in the register | B19: 61985
A20: Difference (grand total) | B20: =B18-B19
A22: Page 1 reconciles exactly. The grand total at the foot of page 2 is partly cut off in the photograph and was read as 61,985 — the difference above is the amount still to be traced, and the rows flagged Verify = Yes on the detail sheet are where it will be.

Sheet Notes
A1: How this sheet was prepared
A3: Source: two photographs of the handwritten register for the Ria & Sejal birthday party, dated 23-08-2026.
A4: Page 1 carries entries 1 to 28 and a page total of 24,303. Page 2 carries that figure forward and runs to entry 59.
A6: Column rules
A7: Sejal — the line is marked 'સેજલ' / 'સેજલને' in the register.
A8: Ria — the line is marked 'રાયા' / 'રાયુ' / 'રાયાને' (written as Raya; recorded here as Ria).
A9: Common / not specified — no child is named on that line in the register.
A10: Total — a formula, Sejal + Ria + Common for that row.
A12: Entry 1 (Kiran Somabhai Vyas) is a casserole set given to Sejal — a gift in kind, so it carries no amount.
A13: Entry 15 (Nilam Dhanendra Gupta) is written with a brace in the book: 500 to Sejal and 500 to Ria.
A14: The register's own numbering skips 50; the numbers here follow the book exactly.
A15: The last line of page 2 (Vishal Patel, 15,000) is unnumbered in the register.
... A19: Amounts are whole rupees; the register writes them as '500=00' style, i.e. rupees and paise.
