Workbook

Sheet Read Me
A1: ESDS Software Solution Limited — IPO Due Diligence
A2: Analysis date | B2: 28 August 2026 (Day 1 of the book)
A3: Issue | B3: ₹720 crore · 100% fresh issue · no OFS · band ₹408–₹429 · 28 Aug – 1 Sep 2026 · lists 4 Sep 2026
A4: Prepared for | B4: Investment assessment — listing gains, 3–5 year hold, and risk-adjusted return
A6: READ THIS BEFORE ANY NUMBER IN THIS WORKBOOK
A7: Outbound network access in the environment where this was prepared was restricted to a web-search index. Every primary-source domain returned EGRESS_BLOCKED: sebi.gov.in, nseindia.com, bseindia.com, esds.co.in and every IPO-data host attempted.
A8: I could NOT open the RHP, the abridged prospectus, the audited financial statements, or any exchange filing. Every figure in this workbook comes from secondary sources quoting the RHP, retrieved on 28 August 2026.
A9: The CASH FLOW STATEMENT is unavailable in its entirety — CFO, capex and free cash flow for every year. For a capital-intensive data-centre business that is the most important gap in this analysis. It has been left empty rather than estimated.
A10: To compensate, the 'Consistency Audit' tab re-computes nine figures that ought to reconcile. All nine pass. That is why the income statement can be relied on despite second-hand provenance — but it is not a substitute for reading the RHP.
A12: TAG KEY — every figure in this workbook carries one
A13: Tag | B13: Meaning
A14: [R] | B14: Reported by a secondary source citing the RHP
A15: [C] | B15: My calculation, derived from [R] inputs — the formula is live in the cell
A16: [NA] | B16: Not available — I could not obtain it. Left blank, never estimated
A17: [!] | B17: Sources conflict, or the figure failed a cross-check. See the note beside it
A19: CELL COLOUR CONVENTION (standard financial-model convention)
A20: Colour | B20: Means
A21: sample | B21: Blue text — a hardcoded input. Every one is sourced on the 'Inputs' tab.
A22: sample | B22: Black text — a live formula. Change an input and this recalculates.
A23: sample | B23: Green text — a link to another sheet in this workbook.
A24: sample | B24: Yellow fill — a key assumption you are meant to challenge or change.
A26: HOW TO USE THIS MODEL
A27: 1. 'Inputs' is the single source of truth. Every hardcoded number lives there, in blue, with its source. Nothing else in the workbook hardcodes a figure.
A28: 2. Change the price on 'Valuation' cell C6 and every multiple, fair value and margin-of-safety number in the workbook updates.
A29: 3. Change the growth, margin and exit-multiple assumptions on 'Scenarios' (yellow cells) and the fair value range and verdict inputs update.
A30: 4. 'Consistency Audit' will show FAIL if you change an input in a way that breaks reconciliation with the reported figures. That is intentional.
A32: Analytical work product, not investment advice. Verify against the RHP before acting. IPO sentiment data cited here is timestamped and perishable.

Sheet Inputs
A1: Inputs — every hardcoded figure in this workbook, with its source
A2: Blue = hardcoded. Nothing else in this workbook hardcodes a number; every other sheet links here. Change a value and the whole model recalculates.
A3: Item | B3: Unit | C3: Value | D3: Tag | E3: Source / note
A4: ISSUE TERMS
A5: Price band — lower | B5: ₹/sh | C5: 408 | D5: [R] | E5: Groww / Bajaj Broking / Upstox IPO pages, 28 Aug 2026
A6: Price band — upper | B6: ₹/sh | C6: 429 | D6: [R] | E6: Groww / Bajaj Broking / Upstox IPO pages, 28 Aug 2026
A7: Issue size (gross) | B7: ₹ cr | C7: 720 | D7: [R] | E7: IPOWatch / Chittorgarh / Zerodha. 100% fresh issue, no OFS
A8: Offer for sale | B8: ₹ cr | C8: 0 | D8: [R] | E8: Nil — every rupee goes to the company
A9: Fresh shares issued (at ₹429) | B9: cr | C9: 1.68 | D9: [R] | E9: Reported as 1.68 crore shares for ₹720 cr
A10: Post-issue market cap @ ₹429 | B10: ₹ cr | C10: 5028 | D10: [R] | E10: Reported. Used to back out the pre-issue share count
A11: Lot size | B11: sh | C11: 34 | D11: [R] | E11: Angel One / Chittorgarh
A12: Face value | B12: ₹/sh | C12: 1 | D12: [R] | E12: ₹1 per equity share
A13: PROFIT & LOSS (₹ crore)
A14: FY23 revenue from operations | B14: ₹ cr | C14: 212.2 | D14: [R] | E14: UnlistedZone FY25 review, citing RHP restated accounts
A15: FY24 revenue from operations | B15: ₹ cr | C15: 286.5 | D15: [C] | E15: Derived: top-10 clients ₹107.10 cr = 37.38% of revenue from ops
A16: FY25 revenue from operations | B16: ₹ cr | C16: 361.3 | D16: [R] | E16: Tradebrains: 'operational revenue rose 30.7% to ₹472.2 cr from ₹361.3 cr'
A17: FY26 revenue from operations | B17: ₹ cr | C17: 472.2 | D17: [R] | E17: Tradebrains, Aug 2026
A18: FY24 total income | B18: ₹ cr | C18: 292.14 | D18: [R] | E18: Tradebrains / Paytm Money IPO review
A19: FY25 total income | B19: ₹ cr | C19: 376.64 | D19: [R] | E19: Tradebrains / Paytm Money IPO review
A20: FY26 total income | B20: ₹ cr | C20: 480.65 | D20: [R] | E20: Tradebrains / Paytm Money IPO review
A21: FY23 EBITDA | B21: ₹ cr | C21: 26.2 | D21: [R] | E21: UnlistedZone: 'up from ₹26.2 cr in the previous year'
A22: FY24 EBITDA | B22: ₹ cr | C22: 76.1 | D22: [R] | E22: UnlistedZone: 'EBITDA surged to ₹76.1 cr, margin ~26%'
A23: FY25 EBITDA | B23: ₹ cr | C23: 154.89 | D23: [R] | E23: Tradebrains: 'EBITDA increased from ₹154.89 cr in FY25'
A24: FY26 EBITDA | B24: ₹ cr | C24: 234.23 | D24: [R] | E24: Tradebrains: '...to ₹234.23 cr in FY26'
A25: FY23 PAT | B25: ₹ cr | C25: -22.5 | D25: [R] | E25: UnlistedZone: loss of ₹22.5 cr in FY23
... A29: FY26 other income | B29: ₹ cr | C29: 8.45 | D29: [C] | E29: Derived: total income ₹480.65 cr less revenue from ops ₹472.20 cr
A30: RATIOS & BALANCE SHEET
A31: FY26 Return on equity | B31: % | C31: 0.2512 | D31: [R] | E31: INDmoney IPO review, citing RHP
A32: FY26 Return on capital employed | B32: % | C32: 0.3278 | D32: [R] | E32: INDmoney IPO review, citing RHP
A33: FY26 Debt / equity | B33: x | C33: 0.08 | D33: [R] | E33: INDmoney: 'D/E declined from 0.66 to 0.08'
A34: FY24 Debt / equity | B34: x | C34: 0.66 | D34: [R] | E34: INDmoney IPO review
A35: FY24 secured borrowings | B35: ₹ cr | C35: 115.44 | D35: [R] | E35: INDmoney IPO review, citing RHP
A36: FY25 secured borrowings | B36: ₹ cr | C36: 62.71 | D36: [R] | E36: INDmoney IPO review, citing RHP
A37: FY26 secured borrowings | B37: ₹ cr | C37: 42.92 | D37: [R] | E37: INDmoney IPO review, citing RHP
A38: FY26 total financial indebtedness | B38: ₹ cr | C38: 102.92 | D38: [R] | E38: INDmoney IPO review, citing RHP
A39: Contingent liabilities / net worth | B39: % | C39: 0.1043 | D39: [R] | E39: FY26; was 30.50% two years prior
A40: FY26 unbilled revenue | B40: ₹ cr | C40: 63.39 | D40: [R] | E40: INDmoney IPO review, citing RHP
A41: FY26 receivable days | B41: days | C41: 79 | D41: [R] | E41: INDmoney: 'about 79 days to collect sales'
A42: Current assets hypothecated | B42: % | C42: 0.9672 | D42: [R] | E42: As at 31 Mar 2026
... A44: Assumed interest rate on borrowings | B44: % | C44: 0.1 | D44: [C] | E44: My assumption for the tax-rate derivation. Challenge it.
...

Sheet IPO Snapshot
A1: IPO Snapshot
A3: Item | B3: At ₹408 (lower) | C3: At ₹429 (upper) | D3: Tag | E3: Note
A4: Company | B4: ESDS Software Solution Limited | D4: [R] | E4: Incorporated 2005, headquartered Nashik
A5: Sector | B5: Data centres · cloud (IaaS) · managed services · SaaS | D5: [R]
A6: IPO type | B6: 100% FRESH ISSUE — NO OFS | D6: [R] | E6: Every rupee goes to the company
A7: Issue size (gross) | B7: =Inputs!$C$7 | D7: [R] | E7: ₹ crore
A8: Offer for sale | B8: =Inputs!$C$8 | D8: [R] | E8: Nil
A9: Price | B9: =Inputs!$C$5 | C9: =Inputs!$C$6 | D9: [R] | E9: ₹ per share
A10: Face value | B10: =Inputs!$C$12 | D10: [R] | E10: ₹ per share
A11: Lot size | B11: =Inputs!$C$11 | D11: [R] | E11: shares
A12: Minimum investment (retail) | B12: =Inputs!$C$11*Inputs!$C$5 | C12: =Inputs!$C$11*Inputs!$C$6 | D12: [C] | E12: Lot size x price
A13: Anchor book date | B13: 27 Aug 2026 | D13: [R]
A14: Issue opens | B14: Friday 28 August 2026 | D14: [R]
A15: Issue closes | B15: Tuesday 1 September 2026 | D15: [R]
A16: Basis of allotment | B16: 2 September 2026 | D16: [R]
A17: Listing | B17: 4 September 2026 — BSE and NSE | D17: [R]
A19: SHARE COUNT AND MARKET CAPITALISATION — derived, shown in full
A20: Item | B20: At ₹408 (lower) | C20: At ₹429 (upper) | D20: Tag | E20: Working
A21: Pre-issue shares outstanding | B21: =Inputs!$C$10/Inputs!$C$6-Inputs!$C$9 | D21: [C] | E21: Reported m-cap ₹5,028 cr / ₹429 = 11.72 cr post-issue, less 1.68 cr fresh
A22: Fresh shares issued | B22: =Inputs!$C$7/Inputs!$C$5 | C22: =Inputs!$C$7/Inputs!$C$6 | D22: [C] | E22: ₹720 cr / price. Assumes the raise is fixed in rupees and share count flexes.
A23: Post-issue shares outstanding | B23: =$B$21+B22 | C23: =$B$21+C22 | D23: [C] | E23: crore shares
A24: Implied market capitalisation | B24: =B23*Inputs!$C$5 | C24: =C23*Inputs!$C$6 | D24: [C] | E24: ₹ crore. The ₹429 figure reproduces the reported ₹5,028 cr exactly — see Consistency Audit.
A25: FY26 EPS on post-issue base | B25: =Inputs!$C$28/B23 | C25: =Inputs!$C$28/C23 | D25: [C] | E25: ₹ per share
A27: OWNERSHIP
A28: Item | B28: Pre-issue | C28: Post-issue | D28: Tag | E28: Note
A29: Promoter holding | B29: =Inputs!$C$59 | C29: =Inputs!$C$59*$B$21/$C$23 | D29: [R] [C] | E29: Post = pre-issue promoter shares / post-issue total. Promoters sell nothing.
A30: Public holding | B30: =Inputs!$C$60 | D30: [!] | E30: 46.06% + 52.65% = 98.71%. The residual 1.29% is unexplained in my sources.
A31: Promoters | B31: Piyush Prakashchandra Somani (CMD) · Komal Piyush Somani (WTD) · P.O. Somani Family Trust | D31: [R]
A32: Anchor investors | B32: =Inputs!$C$69 | D32: [R] | E32: ₹ crore from 19 investors at ₹429; 81.94% to domestic mutual funds
A33: Anchor mutual funds | B33: Motilal Oswal · Bandhan · Quant · ITI · JM Financial · Samco | D33: [R] | E33: 6 houses, 13 schemes
A34: Lead managers | B34: DAM Capital Advisors · Systematix Corporate Services | D34: [R]
A35: Registrar | B35: MUFG Intime India (formerly Link Intime India) | D35: [R]
A36: Reservation | B36: QIB 50% · NII 15% · Retail 35% | D36: [R] | E36: Standard book-built structure
A38: LOCK-IN: promoters hold under 50% pre-IPO, reflecting years of pre-listing fundraising and an active unlisted market in the shares. Under SEBI ICDR, pre-issue capital other than promoter contribution is generally locked in for six months from allotment — so that overhang surfaces around March 2027, not at listing. This is the general regulatory rule applied by me; the RHP's specific lock-in disclosures were not verifiable.

Sheet Consistency Audit
A1: Consistency Audit — can these second-hand numbers be trusted?
A2: Because the RHP could not be opened, I tested whether independently-sourced figures reconcile. Each row below RE-COMPUTES a figure from other inputs and compares it to what was reported. All nine pass. Change an input on the Inputs tab and any broken reconciliation will show FAIL.
A3: # | B3: Check | C3: Computed | D3: Reported | E3: Result | F3: Why it matters
A4: 1 | B4: Post-issue share count (crore) | C4: ='IPO Snapshot'!C23 | D4: =Inputs!$C$10/Inputs!$C$6 | E4: =IF(ABS(C4-D4)<=0.01,"PASS","FAIL") | F4: Reported market cap divided by the upper band must give the post-issue share count.
A5: 2 | B5: Pre-issue share count (crore) | C5: ='IPO Snapshot'!B21 | D5: =Inputs!$C$10/Inputs!$C$6-Inputs!$C$9 | E5: =IF(ABS(C5-D5)<=0.01,"PASS","FAIL") | F5: Post-issue count less the fresh shares.
A6: 3 | B6: P/E at the upper band | C6: =Inputs!$C$6/('IPO Snapshot'!C25) | D6: 41.61 | E6: =IF(ABS(C6-D6)<=0.1,"PASS","FAIL") | F6: STRONGEST CHECK. My derived EPS of ₹10.31 x reported P/E must reproduce ₹429. It does, to two decimals.
A7: 4 | B7: EBITDA margin, FY26 | C7: =Inputs!$C$24/Inputs!$C$17 | D7: 0.496 | E7: =IF(ABS(C7-D7)<=0.0005,"PASS","FAIL") | F7: EXACT. Confirms EBITDA is struck on revenue from operations, not total income.
A8: 5 | B8: PAT margin, FY26 | C8: =Inputs!$C$28/Inputs!$C$17 | D8: 0.2559 | E8: =IF(ABS(C8-D8)<=0.0005,"PASS","FAIL") | F8: EXACT. Same denominator convention.
A9: 6 | B9: Revenue growth, FY25 to FY26 | C9: =Inputs!$C$20/Inputs!$C$19-1 | D9: 0.28 | E9: =IF(ABS(C9-D9)<=0.005,"PASS","FAIL") | F9: Reported as '+28%' on total income. Computes to 27.6%.
A10: 7 | B10: PAT growth, FY25 to FY26 | C10: =Inputs!$C$28/Inputs!$C$27-1 | D10: 1.17 | E10: =IF(ABS(C10-D10)<=0.005,"PASS","FAIL") | F10: Reported as '+117%'. Computes to 117.3%.
A11: 8 | B11: Top-10 client concentration, FY26 | C11: =Inputs!$C$49/Inputs!$C$17 | D11: =Inputs!$C$48 | E11: =IF(ABS(C11-D11)<=0.0005,"PASS","FAIL") | F11: The source listed the three years out of order. This check identifies which year is which.
A12: 9 | B12: Debt / equity, FY26 | C12: =Inputs!$C$37/(Inputs!$C$28/Inputs!$C$31) | D12: 0.08 | E12: =IF(ABS(C12-D12)<=0.02,"PASS","FAIL") | F12: Uses net worth backed out of ROE. Confirms the ~₹481-536 cr equity base.
B14: Checks passed | C14: =COUNTIF(E4:E12,"PASS")&" of "&COUNTA(E4:E12) | F14: Nine of nine reconcile, three of them exactly. The income statement and per-share data can be relied on.
B16: WHAT THIS DOES NOT PROVE
B17: A green audit proves the reported figures are internally coherent. It cannot prove they match the RHP, and it says nothing about the balance sheet or cash flow, where far fewer figures were available to cross-check. Confidence: HIGH on the income statement, MODERATE on the balance sheet, NONE on cash flow.

Sheet Financials
A1: Financials — four years (FY22 is not available)
A2: All ₹ crore unless stated. Black = live formula off the Inputs tab. FY22 could not be obtained, so the brief's five-year study is delivered as a four-year study — flagged rather than filled.
A3: ₹ crore | B3: FY23 | C3: FY24 | D3: FY25 | E3: FY26 | F3: Tag | G3: Note
A4: INCOME STATEMENT
A5: Revenue from operations | B5: =Inputs!$C$14 | C5: =Inputs!$C$15 | D5: =Inputs!$C$16 | E5: =Inputs!$C$17 | F5: [R] [C] | G5: FY24 derived: top-10 ₹107.10 cr / 37.38%
A6: Total income | B6: n/a | C6: =Inputs!$C$18 | D6: =Inputs!$C$19 | E6: =Inputs!$C$20 | F6: [R]
A7: Revenue growth, y/y | B7: n/a | C7: =C5/B5-1 | D7: =D5/C5-1 | E7: =E5/D5-1 | F7: [C] | G7: On revenue from operations
A8: EBITDA | B8: =Inputs!$C$21 | C8: =Inputs!$C$22 | D8: =Inputs!$C$23 | E8: =Inputs!$C$24 | F8: [R]
A9: EBITDA margin | B9: =B8/B5 | C9: =C8/C5 | D9: =D8/D5 | E9: =E8/E5 | F9: [C] | G9: THE CENTRAL FACT: 12.3% to 49.6% in three years
A10: Depreciation & amortisation | B10: n/a | C10: n/a | D10: n/a | E10: =Derivations!C10 | F10: [C] | G10: Derived from ROCE — see the Derivations tab
A11: EBIT | B11: n/a | C11: n/a | D11: n/a | E11: =Derivations!C9 | F11: [C] | G11: Derived
A12: PBT | B12: n/a | C12: n/a | D12: n/a | E12: =Derivations!C24 | F12: [C] | G12: Derived
A13: PAT | B13: =Inputs!$C$25 | C13: =Inputs!$C$26 | D13: =Inputs!$C$27 | E13: =Inputs!$C$28 | F13: [R]
A14: PAT margin | B14: n/a | C14: =C13/C5 | D14: =D13/D5 | E14: =E13/E5 | F14: [C] | G14: FY23 was a loss
A15: EPS on post-issue base (₹) | B15: n/a | C15: =C13/'IPO Snapshot'!$C$23 | D15: =D13/'IPO Snapshot'!$C$23 | E15: =E13/'IPO Snapshot'!$C$23 | F15: [C] | G15: Post-issue share count held constant to show the earnings trajectory
A17: COMPOUND GROWTH — the most important table in this workbook
A18: Metric | B18: From | C18: To | D18: Years | E18: CAGR | F18: Tag | G18: Note
A19: Revenue from operations | B19: =B5 | C19: =E5 | D19: 3 | E19: =(C19/B19)^(1/D19)-1 | F19: [C] | G19: FY23 to FY26. Good, but ordinary.
A20: EBITDA | B20: =B8 | C20: =E8 | D20: 3 | E20: =(C20/B20)^(1/D20)-1 | F20: [C] | G20: FY23 to FY26. 3.5x FASTER THAN REVENUE — the whole story.
A21: PAT | B21: =C13 | C21: =E13 | D21: 2 | E21: =(C21/B21)^(1/D21)-1 | F21: [C] | G21: FY24 to FY26 only. FY23 was a loss, so a CAGR from it is undefined.
A23: EBITDA CAGR / Revenue CAGR | E23: =E20/E19 | G23: Profit growth here is overwhelmingly a MARGIN story, and margin stories are finite by construction. Margin cannot expand from 49.6% to 150%.
A26: BALANCE SHEET
A27: ₹ crore | B27: FY24 | C27: FY25 | D27: FY26 | F27: Tag | G27: Note
A28: Secured borrowings | B28: =Inputs!$C$35 | C28: =Inputs!$C$36 | D28: =Inputs!$C$37 | F28: [R] | G28: Down 63% in two years while the business grew 30% p.a.
A29: Total financial indebtedness | B29: n/a | C29: n/a | D29: =Inputs!$C$38 | F29: [R]
A30: Net worth (closing, derived) | B30: n/a | C30: n/a | D30: =Inputs!$C$37/Inputs!$C$33 | F30: [C] | G30: Secured borrowings / reported D/E of 0.08
A31: Net worth (average, derived) | B31: n/a | C31: n/a | D31: =Inputs!$C$28/Inputs!$C$31 | F31: [C] | G31: PAT / reported ROE of 25.12%
A32: Debt / equity | B32: =Inputs!$C$34 | C32: n/a | D32: =Inputs!$C$33 | F32: [R] | G32: 0.66 to 0.08
A33: Contingent liabilities (% of net worth) | B33: n/a | C33: n/a | D33: =Inputs!$C$39 | F33: [R] | G33: Was 30.50% two years prior — improving
A34: Contingent liabilities (₹ cr, derived) | B34: n/a | C34: n/a | D34: =Inputs!$C$39*D30 | F34: [C]
A35: Unbilled revenue | B35: n/a | C35: n/a | D35: =Inputs!$C$40 | F35: [R] | G35: 13.4% of FY26 revenue — the earnings-quality flag
A36: Current assets hypothecated | B36: n/a | C36: n/a | D36: =Inputs!$C$42 | F36: [R] | G36: Normal for working-capital facilities, but little unpledged collateral remains
A37: Total assets / cash / inventory | B37: n/a | C37: n/a | D37: n/a | F37: [NA] | G37: NOT AVAILABLE — could not be obtained
A39: POST-IPO BALANCE SHEET — the dilution nobody mentions
A40: Net worth post-IPO (before issue expenses) | B40: =D30+Inputs!$C$7 | F40: [C] | G40: ₹536 cr existing plus the ₹720 cr raise
A41: ROE, pre-IPO (reported) | B41: =Inputs!$C$31 | F41: [R]
A42: ROE, post-IPO pro forma | B42: =Inputs!$C$28/B40 | F42: [C] | G42: The headline 25% ROE will not exist by the December 2026 quarter. It falls to under 10% the moment the money lands, and stays there until the ₹576 cr earns a return.
A45: CASH FLOW
A46: ₹ crore | B46: FY24 | C46: FY25 | D46: FY26 | F46: Tag | G46: Note
A47: Cash flow from operations (CFO) | B47: NOT AVAILABLE | C47: NOT AVAILABLE | D47: NOT AVAILABLE | F47: [NA]
...

Sheet Derivations
A1: Derivations — the depreciation problem
A2: The most important non-obvious finding in this analysis. Reported D&A was not available, so it is backed out of the reported ROCE. Moderate confidence — every step is shown so it can be challenged.
B3: Step | C3: Value | D3: Unit | E3: Working / comment
A4: STEP 1 — back out the capital base and EBIT
B5: Average equity | C5: =Inputs!$C$28/Inputs!$C$31 | D5: ₹ cr | E5: PAT ₹120.82 cr / ROE 25.12%
B6: Closing equity | C6: =Inputs!$C$37/Inputs!$C$33 | D6: ₹ cr | E6: Secured borrowings ₹42.92 cr / D/E 0.08
B7: Average debt | C7: =(Inputs!$C$36+Inputs!$C$37)/2 | D7: ₹ cr | E7: Mean of FY25 ₹62.71 cr and FY26 ₹42.92 cr
B8: Average capital employed | C8: =C5+C7 | D8: ₹ cr | E8: Equity plus debt
B9: EBIT | C9: =Inputs!$C$32*C8 | D9: ₹ cr | E9: ROCE 32.78% x capital employed
B10: Depreciation & amortisation | C10: =Inputs!$C$24-C9 | D10: ₹ cr | E10: EBITDA less EBIT
B11: D&A as % of revenue | C11: =C10/Inputs!$C$17 | D11: % | E11: Comparable colocation operators typically run 20–30%
B13: ₹59 crore of depreciation across five Tier-3 data centres is low — strikingly so. Three explanations are possible: (1) LEGACY ASSETS ARE LARGELY WRITTEN DOWN. ESDS has operated since 2005; the Nashik facility is old. Assets past their depreciable life carry revenue but no charge. Most likely, and it fits the margin curve exactly. (2) LEASED rather than owned capacity, shifting cost from D&A into operating expense. (3) LONG ASSUMED USEFUL LIVES — which would be an accounting-aggressiveness flag. I cannot distinguish between these without the RHP's fixed-asset schedule. [NA] — and it is the single most valuable thing an investor could check before applying.
A19: STEP 2 — does the profit surge survive a tax check?
B20: EBITDA | C20: =Inputs!$C$24 | D20: ₹ cr | E20: Reported
B21: less D&A (derived) | C21: =-C10 | D21: ₹ cr | E21: From step 1
B22: less interest | C22: =-Inputs!$C$44*C7 | D22: ₹ cr | E22: Assumed 10% on average debt — a yellow input on the Inputs tab
B23: plus other income | C23: =Inputs!$C$29 | D23: ₹ cr | E23: Total income less revenue from operations
B24: =PBT | C24: =Inputs!$C$24-C10-Inputs!$C$44*C7+Inputs!$C$29 | D24: ₹ cr
B25: less PAT (reported) | C25: =-Inputs!$C$28 | D25: ₹ cr | E25: Reported
B26: =Implied tax charge | C26: =C24-Inputs!$C$28 | D26: ₹ cr
B27: Implied effective tax rate | C27: =C26/C24 | D27: %
B28: Statutory rate for comparison | C28: =Inputs!$C$43 | D28: % | E28: s.115BAA concessional regime
B29: Verdict | C29: =IF(C27>Inputs!$C$43,"ABOVE statutory","BELOW statutory") | E29: An effective rate ABOVE statutory is the opposite of a tax-flattered result. The obvious suspicion — that PAT rose 117% while EBITDA rose 51% because of deferred-tax-asset recognition against the FY23 loss — does not survive this check.
B33: Caveat: this chain rests on a derived D&A figure. If actual D&A is LOWER, the implied tax rate rises further, strengthening the conclusion. If D&A is materially HIGHER, PBT falls and the implied rate drops. The conclusion is robust in one direction and sensitive in the other.
A36: STEP 3 — the forward consequence: the depreciation wave
B37: New annual D&A from the ₹576 cr capex | C37: =Inputs!$C$58/Inputs!$C$61 | D37: ₹ cr | E37: ₹576 cr over an assumed 5.5-year server life. Yellow input — change it on the Inputs tab.
B38: Current D&A for comparison | C38: =C10 | D38: ₹ cr | E38: From step 1
B39: Total D&A once deployed | C39: =C10+C37 | D39: ₹ cr | E39: Roughly three times current
B40: New D&A as % of FY26 PAT | C40: =C37/Inputs!$C$28 | D40: % | E40: The increment alone is comparable to the whole of FY26 profit
A42: Sizing the offset if the capacity actually fills
B43: Revenue capacity at target MW | C43: =Inputs!$C$17*Inputs!$C$55/Inputs!$C$54 | D43: ₹ cr | E43: Assumes revenue scales linearly with IT load — a simplification
B44: Incremental revenue at full utilisation | C44: =C43-Inputs!$C$17 | D44: ₹ cr
B45: x incremental EBITDA margin (50%) | C45: =C44*0.5 | D45: ₹ cr | E45: Near the current 49.6% margin
B46: less incremental D&A | C46: =C45-C37 | D46: ₹ cr | E46: INCREMENTAL EBIT at full utilisation
B48: THE CENTRAL CONCLUSION: the capex is strongly accretive at full utilisation and strongly dilutive at low utilisation. The entire equity story reduces to one number — capacity utilisation — which ESDS does not publish. That is why the long-term verdict is Neutral rather than Positive: not a judgment about quality, but an admission that the decisive variable is unobservable from outside.

Sheet Valuation
A1: Valuation
A2: Change the price in the yellow cell below and every multiple on this sheet, plus the margin-of-safety grid on 'Fair Value', recalculates.
A4: PRICE DRIVER
A5: Price under test (₹ per share) | B5: =Inputs!$C$6 | C5: <- change this | F5: Defaults to the upper band. Try ₹408 for the lower band, or any secondary-market price.
A7: Metric | B7: At ₹408 (lower) | C7: At ₹429 (upper) | D7: At price under test | E7: Tag | F7: Note
A8: Post-issue shares (crore) | B8: ='IPO Snapshot'!B23 | C8: ='IPO Snapshot'!C23 | D8: ='IPO Snapshot'!$B$21+Inputs!$C$7/$B$5 | E8: [C] | F8: Pre-issue count plus ₹720 cr / price
A9: Market capitalisation (₹ cr) | B9: ='IPO Snapshot'!B24 | C9: ='IPO Snapshot'!C24 | D9: =D8*$B$5 | E9: [C] | F9: The ₹429 figure reproduces the reported ₹5,028 cr
A10: Enterprise value (₹ cr) | B10: =B9+Inputs!$C$38 | C10: =C9+Inputs!$C$38 | D10: =D9+Inputs!$C$38 | E10: [C] | F10: Understates by the cash balance, which is [NA]
A11: FY26 EPS (₹) | B11: =Inputs!$C$28/B8 | C11: =Inputs!$C$28/C8 | D11: =Inputs!$C$28/D8 | E11: [C]
A13: MULTIPLES
A14: P / E (FY26) | B14: =Inputs!$C$5/B11 | C14: =Inputs!$C$6/C11 | D14: =$B$5/D11 | E14: [C] | F14: Reported as 41.61x at the upper band — reproduced exactly
A15: EV / EBITDA (FY26) | B15: =B10/Inputs!$C$24 | C15: =C10/Inputs!$C$24 | D15: =D10/Inputs!$C$24 | E15: [C] | F15: THE MORE RELIABLE ANCHOR — sits above the depreciation line, so it is not contaminated by the timing of asset deployment
A16: EV / Sales (FY26) | B16: =B10/Inputs!$C$17 | C16: =C10/Inputs!$C$17 | D16: =D10/Inputs!$C$17 | E16: [C]
A17: P / Sales (FY26) | B17: =B9/Inputs!$C$17 | C17: =C9/Inputs!$C$17 | D17: =D9/Inputs!$C$17 | E17: [C]
A18: P / B (post-money) | B18: =B9/Financials!$B$40 | C18: =C9/Financials!$B$40 | D18: =D9/Financials!$B$40 | E18: [C] | F18: Post-money book = ₹536 cr existing + ₹720 cr raise
A19: PEG (vs revenue CAGR) | B19: =B14/(Financials!$E$19*100) | C19: =C14/(Financials!$E$19*100) | D19: =D14/(Financials!$E$19*100) | E19: [C] | F19: Against REVENUE growth of 30.6%. Against FY26 earnings growth of 117% the PEG looks trivially cheap — but that growth is arithmetically unrepeatable, so that PEG is a mirage.
A20: FCF yield | B20: n/a | C20: n/a | D20: n/a | E20: [NA] | F20: Free cash flow unavailable, and negative through the build
A22: AGAINST THE PEER — E2E Networks, the only listed comparable
A23: Metric | B23: ESDS at ₹429 | C23: E2E Networks | D23: ESDS as % of peer | E23: Tag | F23: Note
A24: E2E annualised revenue (₹ cr) | B24: =Inputs!$C$81*4 | C24: E2E annualised EBITDA | D24: =Inputs!$C$82*4 | E24: PAT | F24: =Inputs!$C$83*4
A25: Annualising Q1 FY27 is mine [C] and assumes the run-rate holds — a simplification given E2E's trajectory. It is used only to show that even on a forward basis the gap does not close.
A26: Metric | B26: ESDS at ₹429 | C26: E2E Networks | D26: ESDS as % of peer | E26: Tag | F26: Note
A27: P / E | B27: =C14 | C27: =Inputs!$C$74 | D27: =IFERROR(B27/C27,"n/a") | F27: E2E on trailing earnings. Forward is ~72x.
A28: P / E, forward (annualised) | B28: =C14 | C28: =Inputs!$C$73/(Inputs!$C$83*4) | D28: =IFERROR(B28/C28,"n/a") | F28: The fairer comparison
A29: EV / EBITDA | B29: =C15 | C29: =Inputs!$C$75 | D29: =IFERROR(B29/C29,"n/a")
A30: EV / EBITDA, forward | B30: =C15 | C30: =Inputs!$C$73/(Inputs!$C$82*4) | D30: =IFERROR(B30/C30,"n/a") | F30: The gap narrows but does not close
A31: P / B | B31: =C9/Financials!$B$40 | C31: =Inputs!$C$76 | D31: =IFERROR(B31/C31,"n/a")
A32: EBITDA margin | B32: =Financials!E9 | C32: =Inputs!$C$82/Inputs!$C$81 | D32: =IFERROR(B32/C32,"n/a") | F32: E2E structurally higher on GPU mix
A33: Return on equity | B33: =Inputs!$C$31 | C33: =Inputs!$C$77 | D33: =IFERROR(B33/C33,"n/a") | E33: ESDS | F33: ESDS DECISIVELY BETTER
A34: Return on capital employed | B34: =Inputs!$C$32 | C34: =Inputs!$C$78 | D34: =IFERROR(B34/C34,"n/a") | E34: ESDS | F34: ESDS DECISIVELY BETTER
A35: Debt / equity | B35: =Inputs!$C$33 | C35: =Inputs!$C$79 | D35: =IFERROR(B35/C35,"n/a") | F35: Both near debt-free
A36: Receivable days | B36: =Inputs!$C$41 | C36: =Inputs!$C$80 | D36: =IFERROR(B36/C36,"n/a") | E36: E2E | F36: ESDS MATERIALLY WORSE
A37: Market capitalisation (₹ cr) | B37: =C9 | C37: =Inputs!$C$73 | D37: =IFERROR(B37/C37,"n/a")
A39: WHY I DECLINE TO CONCLUDE 'UNDERVALUED' FROM THIS
A40: E2E trades at 404x trailing earnings. A comparison against a stock priced on an AI narrative sets a SENTIMENT ceiling, not a fair value. The brief specifically warns against using a convenient peer to make a valuation look attractive, and anchoring fair value to E2E would do exactly that. E2E is also a genuinely different business — it has pivoted hard into GPU/AI compute, which carries 75% EBITDA margins and a different multiple entirely. The honest reading: relative valuation is supportive of listing-day sentiment, and close to uninformative about intrinsic value. ON ABSOLUTE MERIT, 41.6x trailing earnings, 21.9x EV/EBITDA and 10.6x sales for a ₹472 crore capital-intensive business is A FULL PRICE.

Sheet Scenarios
A1: Scenario valuation — FY29
A2: All three are MY models [C]. Yellow cells are assumptions — change them and the fair value, returns and probability-weighted value all update. These are not forecasts. Common assumption: no further equity dilution, which is itself optimistic since a second capacity doubling would need more capital.
A3: Assumption / output | B3: Bear | C3: Base | D3: Bull | E3: Unit | F3: Rationale
A4: ASSUMPTIONS — challenge these
A5: Revenue CAGR, FY26 to FY29 | B5: 0.12 | C5: 0.22 | D5: 0.32 | E5: % | F5: Bear: new capacity fills slowly, enterprise price war, a top-3 account lost. Base: capacity doubles and fills over ~3 years, tracking the ~20% industry rate. Bull: fills fast, AI/GPU and sovereign-cloud mandates accelerate.
A6: EBITDA margin, FY29 | B6: 0.4 | C6: 0.47 | D6: 0.52 | E6: % | F6: Bear: ~₹105 cr of fresh D&A lands on a half-empty build. Base: slight compression from 49.6% as new assets carry a full charge. Bull: utilisation offsets depreciation; mix shifts to managed services and SaaS.
A7: PAT margin, FY29 | B7: 0.14 | C7: 0.2 | D7: 0.24 | E7: % | F7: Follows the EBITDA margin, net of the new depreciation wave and a normal tax charge.
A8: Exit P/E multiple | B8: 22 | C8: 30 | D8: 40 | E8: x | F8: Bear: de-rated to an infrastructure multiple. Base: a quality-growth infrastructure multiple. Bull: re-rated toward the AI/cloud cohort.
A10: OUTPUTS — all formulas
A11: FY29 revenue (₹ cr) | B11: =Inputs!$C$17*(1+B5)^Inputs!$C$86 | C11: =Inputs!$C$17*(1+C5)^Inputs!$C$86 | D11: =Inputs!$C$17*(1+D5)^Inputs!$C$86 | E11: ₹ cr | F11: FY26 revenue compounded at the scenario CAGR
A12: FY29 EBITDA (₹ cr) | B12: =B11*B6 | C12: =C11*C6 | D12: =D11*D6 | E12: ₹ cr
A13: FY29 PAT (₹ cr) | B13: =B11*B7 | C13: =C11*C7 | D13: =D11*D7 | E13: ₹ cr
A14: FY29 EPS (₹) | B14: =B13/'IPO Snapshot'!$C$23 | C14: =C13/'IPO Snapshot'!$C$23 | D14: =D13/'IPO Snapshot'!$C$23 | E14: ₹ | F14: Post-issue share count held constant
A15: FY29 market cap (₹ cr) | B15: =B13*B8 | C15: =C13*C8 | D15: =D13*D8 | E15: ₹ cr
A16: FY29 value per share (₹) | B16: =B14*B8 | C16: =C14*C8 | D16: =D14*D8 | E16: ₹
A17: Present value today (₹) | B17: =B16/(1+Inputs!$C$85)^Inputs!$C$86 | C17: =C16/(1+Inputs!$C$85)^Inputs!$C$86 | D17: =D16/(1+Inputs!$C$85)^Inputs!$C$86 | E17: ₹ | F17: Discounted at 14%
A19: RETURNS FROM THE PRICE UNDER TEST
A20: Total return over 3 years | B20: =B16/Valuation!$B$5-1 | C20: =C16/Valuation!$B$5-1 | D20: =D16/Valuation!$B$5-1 | E20: % | F20: Against the price on the Valuation tab
A21: Annualised return | B21: =(1+B20)^(1/Inputs!$C$86)-1 | C21: =(1+C20)^(1/Inputs!$C$86)-1 | D21: =(1+D20)^(1/Inputs!$C$86)-1 | E21: %
A23: Probability weight | B23: =Inputs!$C$87 | C23: =Inputs!$C$88 | D23: =Inputs!$C$89 | E23: % | F23: My judgment. Change on the Inputs tab.
A24: PROBABILITY-WEIGHTED VALUE (₹/share) | B24: =SUMPRODUCT(B17:D17,B23:D23) | F24: Feeds the Fair Value tab
A26: READ THE BASE CASE CAREFULLY. It returns under 1% per annum over three years from ₹429. That is not a prediction — it is what the arithmetic says when reasonable, industry-consistent assumptions are plugged in. The IPO price already discounts the base case. The bull case pays well; the bear case is brutal. This is a wide, right-skewed distribution priced near the middle.

Sheet Fair Value
A1: Fair value and margin of safety
A3: METHODS — used and rejected
A4: Method | B4: Used? | F4: Rationale
A5: EV / EBITDA | B5: PRIMARY | F5: Sits above the depreciation line — essential when a capex wave is about to distort reported earnings
A6: Scenario model | B6: PRIMARY | F6: Explicit assumptions, discounted at 14%. See the Scenarios tab.
A7: P / E | B7: Secondary | F7: Standard, but the FY26 base is flattered by low legacy depreciation
A8: P / Sales | B8: Cross-check | F8: Useful given margin uncertainty
A9: P / B | B9: Limited | F9: Post-money book is distorted by the raise itself
A10: Full DCF | B10: REJECTED | F10: Requires CFO and capex, both [NA]. Building one would mean inventing the inputs.
A12: TRIANGULATION
A13: Method | B13: Assumption | C13: Fair value (₹/sh) | E13: Tag | F13: Note
A14: Scenario model, weighted | B14: 25 / 50 / 25 | C14: =Scenarios!B24 | E14: [C] | F14: From the Scenarios tab
A15: P/E on FY26 earnings | B15: 35x fair multiple | C15: =35*Valuation!C11 | E15: [C] | F15: A fair multiple for a 25–30% grower with these risks
A16: P/E on FY27 estimate | B16: 35x, PAT ~₹150 cr | C16: =35*150/'IPO Snapshot'!$C$23 | E16: [C] | F16: FY27 PAT estimate is mine and unverified
A17: EV/EBITDA on FY27 estimate | B17: 18x, EBITDA ~₹300 cr | C17: =(18*300-Inputs!$C$38)/'IPO Snapshot'!$C$23 | E17: [C] | F17: Less net debt
A18: P/Sales cross-check | B18: 8x FY26 revenue | C18: =8*Inputs!$C$17/'IPO Snapshot'!$C$23 | E18: [C]
A20: Fair value — low end | C20: =MIN(C14:C18) | F20: The width of this range is honest, not evasive — it reflects genuine uncertainty about the FY27 depreciation charge and the utilisation ramp, neither of which is disclosed.
A21: Fair value — high end | C21: =MAX(C14:C18)
A22: FAIR VALUE — MIDPOINT | C22: =AVERAGE(C20,C21)
A24: MARGIN OF SAFETY = (Fair value − IPO price) / Fair value
A25: Against | B25: At ₹408 (lower) | C25: At ₹429 (upper) | D25: At price under test | E25: Tag | F25: Note
A26: Low end | B26: =($C20-Inputs!$C$5)/$C20 | C26: =($C20-Inputs!$C$6)/$C20 | D26: =($C20-Valuation!$B$5)/$C20 | E26: [C]
A27: MIDPOINT | B27: =($C22-Inputs!$C$5)/$C22 | C27: =($C22-Inputs!$C$6)/$C22 | D27: =($C22-Valuation!$B$5)/$C22 | E27: [C] | F27: NEGATIVE AT BOTH ENDS OF THE BAND. There is no meaningful margin of safety.
A28: High end | B28: =($C21-Inputs!$C$5)/$C21 | C28: =($C21-Inputs!$C$6)/$C21 | D28: =($C21-Valuation!$B$5)/$C21 | E28: [C]
A30: This is the central finding of the valuation work, and it is what separates the listing verdict from the investment verdict. The IPO may well list at a premium — sentiment, anchor support and the absence of an OFS all point that way. But a listing pop is a transfer from the next buyer, not a return generated by the business. For a three-to-five year holder, the entry price leaves nothing in reserve.

Sheet Scores
A1: Scores — moat, management, business quality, and the IPO scorecard
A2: Scores out of 10, with the evidence beside each. Totals are AVERAGE formulas — change a score and the total updates.
A3: MOAT — classification: WEAK-TO-MODERATE, narrow but real
A4: Factor | B4: Score /10 | F4: Evidence
A5: Regulatory barriers | B5: 7 | F5: THE STRONGEST PILLAR. Data-localisation and sovereign-cloud rules structurally exclude offshore hyperscalers from government/BFSI workloads = 44.9% of revenue. Compliance credentials take years to build.
A6: Switching costs | B6: 7 | F6: Migrating a production BFSI or government workload is expensive, risky and requires re-certification. Genuinely sticky once embedded.
A7: Customer relationships | B7: 6 | F7: 1,300+ clients over 21 years; 99.995% uptime is a real, evidenced credential in a trust-driven purchase.
A8: Intellectual property | B8: 5 | F8: Patents granted in India AND the United States for vertical auto-scaling. Real and verifiable — but a feature, not a platform.
A9: Technology | B9: 5 | F9: SWARAJ/eNlight is differentiated; not decisively ahead of well-funded rivals.
A10: Brand | B10: 4 | F10: Recognised in the Indian mid-market and government; negligible outside it.
A11: Distribution | B11: 4 | F11: Direct enterprise sales, five-city footprint. No structural distribution edge.
A12: Access to capital | B12: 4 | F12: Improves materially post-IPO, but remains far below CtrlS / Nxtra / Yotta.
A13: Cost advantage | B13: 3 | F13: No purchasing scale; USD-imported hardware; higher unit costs than larger rivals.
A14: Scale | B14: 2 | F14: THE CRITICAL WEAKNESS. ~7 MW against competitors deploying hundreds. Sub-scale in procurement, power negotiation and financing.
A15: Network effects | B15: 2 | F15: Essentially none — cloud infrastructure has weak network effects.
A16: OVERALL | B16: =AVERAGE(B5:B15) | F16: Narrow but genuine regulatory and switching-cost moat around sovereign/BFSI. Outside that perimeter — the 55.09% of revenue that is general enterprise — ESDS has essentially no moat and is a price-taker.
A18: MANAGEMENT QUALITY
A19: Factor | B19: Score /10 | F19: Evidence
A20: Financial discipline | B20: 8 | F20: D/E from 0.66 to 0.08 while growing 30% p.a. The single most impressive verifiable fact about this management team.
A21: Shareholder treatment | B21: 8 | F21: ZERO OFS. Promoters sell nothing. 100% of proceeds to the company. In the Indian IPO market this is genuinely uncommon.
A22: Capital allocation | B22: 7 | F22: Turned a loss-making business into 32.78% ROCE; deleveraged 63% in two years; declined to IPO in 2021–22 at a weak valuation and waited until PAT was 5.4x higher.
A23: Execution | B23: 7 | F23: Revenue 30.6% CAGR; EBITDA margin 12.3% to 49.6%; uptime at least 99.995%; 21 years of continuous operation.
A24: Track record | B24: 7 | F24: Piyush Somani has run this since 2005; built a patented platform from Nashik.
A25: Transparency | B25: 5 | F25: Standard RHP disclosure. CAPACITY UTILISATION — the key metric — is not disclosed. Guidance cites the top of the industry growth range (20.70% vs a 13.6–20.1% third-party spread).
A26: Corporate governance | B26: 5 | F26: No adverse findings, but my verification is FY22-vintage and incomplete. Scored as UNVERIFIED, not as clean.
A27: OVERALL | B27: =AVERAGE(B20:B26) | F27: Above average. Genuinely strong on capital discipline and alignment; unverified on governance; opaque on the one metric that matters most.
A29: BUSINESS QUALITY
A30: Factor | B30: Score /10 | F30: Evidence
A31: Balance sheet | B31: 9 | F31: D/E 0.08; interest coverage ~35x; net-cash post-IPO.
A32: Growth | B32: 8 | F32: 30.6% revenue CAGR; secular, legislation-backed demand.
A33: Profitability | B33: 8 | F33: 49.6% EBITDA, 25.6% PAT, 32.78% ROCE — genuinely strong.
A34: Industry attractiveness | B34: 8 | F34: Secular growth with a legislated demand floor — but consolidating around capital.
A35: Management quality | B35: 7 | F35: Strong capital discipline and alignment.
A36: Governance | B36: 5 | F36: No adverse findings; verification absent.
A37: Cash generation | B37: 4 | F37: [NA] AND HEAVILY PENALISED FOR IT. DSO 79 days; unbilled 13.4%; FCF negative by design during the build.
A38: Competitive advantage | B38: 4 | F38: Narrow regulatory/switching moat; structurally sub-scale.
A39: OVERALL | B39: =AVERAGE(B31:B38) | F39: A good business with two real structural constraints: scale and working capital. The cash-generation score is the one most likely to be wrong in either direction — if the RHP shows CFO/PAT above 1.0x it rises to 7 and the overall to ~7.0; if CFO is below PAT it falls to 3.
A41: IPO INVESTMENT SCORECARD
A42: Factor | B42: Score /10 | F42: Evidence
A43: Profit growth | B43: 9 | F43: +788% over two years — exceptional, though unrepeatable.
...

Sheet Risk Matrix
A1: Risk matrix
A3: Risk | B3: Probability | C3: Impact | D3: Severity | E3: Evidence
A4: Business — new capacity underutilised | B4: Medium-High | C4: High | D4: CRITICAL | E4: ₹576 cr capex doubling 7 MW to 14–20 MW; ~₹96–115 cr of new annual D&A; utilisation [NA]
A5: Valuation — 41.6x embeds execution | B5: High | C5: High | D5: CRITICAL | E5: Base-case scenario returns +0.9% p.a. from ₹429; margin of safety −10%
A6: Competitive — structurally sub-scale | B6: High | C6: High | D6: CRITICAL | E6: ~7 MW against India's multi-GW base; CtrlS/Nxtra/Yotta deploy in hundreds of MW
A7: Customer concentration | B7: Medium | C7: High | D7: HIGH | E7: Top client 15.93%; top 10 45.36% of FY26 revenue
A8: Financial — working capital | B8: High | C8: Medium | D8: HIGH | E8: DSO 79 days vs peer 25; unbilled revenue ₹63.39 cr = 13.4% of revenue
A9: Margin normalisation | B9: High | C9: Medium | D9: HIGH | E9: 12.3% to 49.6% in three years; partly a legacy-asset artefact the IPO itself unwinds
A10: Technology obsolescence | B10: Medium | C10: High | D10: HIGH | E10: 5–6 year server lives; GPU generations turn faster; ₹576 cr at risk of stranding
A11: Cybersecurity / data breach | B11: Medium | C11: Very High | D11: HIGH | E11: Explicitly disclosed. Hosts BFSI and government data — reputational loss would be terminal for the niche
A12: Supplier concentration | B12: Medium | C12: Medium | D12: MEDIUM | E12: Dependent on major equipment suppliers; no purchasing scale; USD-priced
A13: Regulatory | B13: Low | C13: Medium | D13: MEDIUM | E13: Net-positive today (localisation aids ESDS); a policy reversal would remove the moat
A14: Promoter / governance | B14: Low | C14: Medium | D14: MEDIUM | E14: No adverse findings, but verification [NA]; one ex-employee equity claim
... A17: Cyclicality | B17: Low | C17: Low | D17: LOW | E17: Secular, legislation-backed demand
A19: THE FIVE RISKS THAT ACTUALLY DECIDE THE OUTCOME
A20: 1. UTILISATION OF THE NEW BUILD. Everything else is secondary. ₹576 cr of equipment carrying ~₹105 cr of annual depreciation is transformative if filled and value-destructive if not. It is not disclosed and cannot be verified before applying.
A22: 2. THE VALUATION ALREADY ASSUMES SUCCESS. At 41.6x, my base case returns under 1% a year. You are not being paid to take the execution risk — you are paying for the execution to work.
A24: 3. STRUCTURAL SUB-SCALE. After spending the entire IPO, ESDS remains a sub-1% player against competitors with vastly deeper capital. Its defence is regulatory, and regulation can change.
A26: 4. WORKING CAPITAL CONSUMES GROWTH. ~₹165 cr tied in receivables and unbilled revenue — 1.4x FY26 PAT — with no cash-flow statement to size the drag.
A28: 5. THE MARGIN RAMP IS PARTLY A LEGACY-ASSET ARTEFACT. Some of the 49.6% EBITDA margin exists BECAUSE the old assets are written down. The IPO buys new assets that are not. Investors extrapolating current margins onto a doubled asset base are double-counting.

Sheet Red Flags
A1: Red-flag investigation — actively searched, not summarised from the prospectus
A2: Including, explicitly, what could NOT be checked. Absence of evidence is weak evidence when the primary documents were unreachable.
A3: Flag | B3: Status | C3: Detail
A4: Large OFS | B4: CLEAR — POSITIVE | C4: ZERO OFS. 100% fresh issue.
A5: Promoter selling | B5: CLEAR — POSITIVE | C5: Promoters sell nothing. They dilute from 46.06% to ~39.5% to fund capacity.
A6: Debt defaults | B6: None found | C6: Borrowings fell 63% in two years.
A7: Contingent liabilities | B7: Improving | C7: 10.43% of net worth, down from 30.50% two years prior.
A8: Regulatory investigations | B8: None found | C8: No adverse search results against the company or promoters.
A9: Negative industry developments | B9: None | C9: Sector tailwind intact.
A10: Sudden profit growth | B10: INVESTIGATED | C10: +788% over two years — BUT the derived effective tax rate of ~32% argues against accounting manipulation. See the Derivations tab.
A11: Tax disputes | B11: Disclosed, unquantified | C11: 'Ongoing legal and tax disputes' referenced in the risk factors; amounts [NA].
A12: Excessive IPO valuation | B12: Full, not egregious | C12: 41.6x P/E; cheaper than the only listed peer; margin of safety negative.
A13: Frequent equity dilution | B13: Historically yes | C13: Promoter under 50% pre-IPO implies extensive prior raises. Further capital likely for the next expansion.
A14: Related-party transactions | B14: STALE EVIDENCE | C14: FY22 annual report: 'no materially significant related party transactions'. FY26 position [NA] — four years stale.
... A27: Inventory problems | B27: Not applicable | C27: Services business.
A29: NET ASSESSMENT: no red flag rises to disqualifying. The cluster that matters is WORKING CAPITAL and STRUCTURAL SCALE, not fraud or governance. The structural positives — zero OFS, no promoter selling, genuine deleveraging, an above-statutory effective tax rate — are unusually strong for an Indian mid-cap IPO and deserve weight.

Sheet Sentiment
A1: Grey market and subscription — sentiment only, never valuation evidence
A2: All figures timestamped 27–28 August 2026 and highly perishable. Treat GMP and subscription as sentiment indicators, not fundamental evidence.
A3: Indicator | B3: Value | C3: Derived | D3: Tag | E3: As at / note
A4: Grey market premium (₹/share) | B4: =Inputs!$C$64 | D4: [!] | E4: Sahi.com, 28 Aug 2026
A5: Implied listing price | B5: =Inputs!$C$6+Inputs!$C$64 | D5: [C] | E5: Upper band plus GMP
A6: Implied listing gain | B6: =Inputs!$C$64/Inputs!$C$6 | D6: [C] | E6: NOT CREDIBLE — see the analysis below
A7: Implied listing P/E | B7: =(Inputs!$C$6+Inputs!$C$64)/Valuation!C11 | D7: [C] | E7: The GMP asks the market to believe ESDS should list at this multiple of FY26 earnings
A9: Day 1 subscription — overall | B9: =Inputs!$C$65 | D9: [R] | E9: Goodreturns, 28 Aug 2026 intra-day
A10: Day 1 subscription — retail | B10: =Inputs!$C$66 | D10: [R] | E10: 28 Aug 2026 intra-day
A11: Day 1 subscription — NII / HNI | B11: =Inputs!$C$67 | D11: [R] | E11: 28 Aug 2026 intra-day
A12: Day 1 subscription — QIB ex-anchor | B12: =Inputs!$C$68 | D12: [R] | E12: Nil. Mainboard QIB books are back-loaded to the final day, so this is uninformative rather than bearish.
A13: Earlier Day 1 reading | B13: 0.12 | D13: [R] | E13: HDFC Sky, earlier on 28 Aug — different timestamp, same day
A15: Anchor book raised (₹ cr) | B15: =Inputs!$C$69 | D15: [R] | E15: Inc42, 27 Aug 2026
A16: Anchor as % of issue | B16: =Inputs!$C$69/Inputs!$C$7 | D16: [C] | E16: The full 30% permitted (60% of the 50% QIB portion) was taken — the anchor book was fully placed at the top of the band.
A17: Anchor allocation to mutual funds | B17: =Inputs!$C$70 | D17: [R] | E17: 6 fund houses across 13 schemes: Motilal Oswal, Bandhan, Quant, ITI, JM Financial, Samco
A18: Employee quota | B18: n/a | D18: [NA] | E18: Not obtainable
A20: THE CONTRADICTION, AND HOW TO READ IT
A21: A GMP implying +77% is not consistent with a 0.40x Day-1 book. One of these signals is wrong, and it is almost certainly the GMP.
A23: 1. A 0.40x DAY-1 BOOK IS UNREMARKABLE. Mainboard books build back-loaded — institutions almost always bid on the final day, which is why the QIB column reads nil. Day 1 at 0.40x is not a bearish signal; it is simply an uninformative one.
A25: 2. A +77% GMP IS EXTRAORDINARY. For a ₹720 crore issue at 41.6x earnings in a sector whose only listed comparable is already at 404x, a grey market pricing 77% of instant upside asks the market to believe ESDS should list at roughly 72x FY26 earnings.
A27: 3. THE GREY MARKET FOR A MID-SIZE ISSUE IS THIN AND CHEAPLY MOVED. Small notional volumes set the quoted premium. It is not a regulated, transparent or deep market. If a genuine +77% pop were broadly expected, retail would not be at 0.54x on Day 1 — that money would already be in. The inconsistency is itself the tell.
A29: THE ANCHOR BOOK IS THE SIGNAL WORTH WEIGHTING. ₹216 crore is the full 30% permitted, placed at the top of the band, with 81.94% going to domestic mutual funds — institutions doing genuine diligence and accepting a lock-in. Six fund houses committing at ₹429 is meaningfully more informative than an anonymous grey-market quote.
A31: PRACTICAL CONCLUSION: expect a positive listing, size expectations far below +77%, and do not let the GMP influence position sizing.
A33: WHAT TO WATCH WHEN THE BOOK CLOSES ON 1 SEPTEMBER
A34: Pattern | B34: Interpretation
A35: QIB above 20x | B35: Institutional conviction at ₹429 — the most meaningful confirmation available. Would support an upgrade.
A36: QIB 3x to 10x | B36: Adequate; consistent with a modest listing gain.
A37: QIB below 3x | B37: Institutions are unconvinced by the valuation. WEIGHT THIS HEAVILY AGAINST THE GMP. Would support a downgrade to Avoid at IPO price.
A38: NII above 30x | B38: Largely leveraged funding demand chasing the GMP — noise, not conviction.
A39: Retail above 5x | B39: Retail is following the GMP, which raises listing-day volatility in both directions.
A41: Do NOT read high subscription as evidence of good fundamentals. Subscription measures how many people want to flip an allotment, not what the business is worth. In issues with an inflated GMP the two are often inversely related — the GMP itself manufactures the oversubscription that appears to validate it.

Sheet Other Open IPOs
A1: The other IPOs open in this window — comparative screen, not full diligence
A2: ESDS received the full treatment as the flagship opening today. This is a screen of the rest of the window. It is NOT due diligence and is not a substitute for it.
B3: ESDS Software | C3: Lumino Industries | D3: Priority Jewels | E3: Annu Projects | F3: Symbiotec Pharmalab
A4: Business | B4: Data centres / cloud | C4: Electrical & power infra | D4: Jewellery | E4: EPC — telecom, sewerage, gas | F4: API / pharma
A5: Issue size (₹ cr) | B5: 720 | C5: 700 | D5: 91.5 | E5: 175.06 | F5: 1757
A6: Structure | B6: 100% FRESH — no OFS | C6: ₹500 cr fresh + ₹200 cr OFS | D6: n/a | E6: 100% fresh | F6: ₹150 cr fresh + ₹1,607 cr OFS
A7: OFS as % of issue | B7: 0 | C7: 0.28571429 | D7: n/a | E7: 0 | F7: 0.91462721
A8: Price band (₹) | B8: 408 – 429 | C8: 78 – 82 | D8: 190 – 200 | E8: 94 – 99 | F8: 938 – 988
A9: Lot size | B9: 34 | C9: 182 | D9: 75 | E9: 151 | F9: n/a
A10: Minimum investment (₹) | B10: 14586 | C10: 14196 | D10: 15000 | E10: 14949 | F10: n/a
A11: Open – close | B11: 28 Aug – 1 Sep | C11: 27 – 31 Aug | D11: 28 Aug – 1 Sep | E11: 25 – 28 Aug (CLOSES TODAY) | F11: 24 – 27 Aug (CLOSED)
A12: Listing date | B12: 4 Sep | C12: 3 Sep | D12: 4 Sep | E12: 2 Sep | F12: 1 Sep
A13: FY26 revenue (₹ cr) | B13: 472.2 | C13: 2089.31 | D13: n/a | E13: 244.59 | F13: n/a
A14: FY25 revenue (₹ cr) | B14: 361.3 | C14: 1946.68 | D14: n/a | E14: 182.35 | F14: n/a
A15: Revenue growth | B15: 0.30694714 | C15: 0.073268334 | D15: n/a | E15: 0.34132163 | F15: n/a
A16: FY26 PAT (₹ cr) | B16: 120.82 | C16: 160 | D16: n/a | E16: 33.03 | F16: n/a
A17: FY25 PAT (₹ cr) | B17: 55.61 | C17: 124.59 | D17: n/a | E17: 21.1 | F17: n/a
A18: PAT growth | B18: 1.1726308 | C18: 0.28421222 | D18: n/a | E18: 0.56540284 | F18: n/a
A19: PAT margin, FY26 | B19: 0.25586616 | C19: 0.076580306 | D19: n/a | E19: 0.13504232 | F19: n/a
A20: Reported GMP | B20: +76.9% [!] | C20: ₹56 [!] | D20: +18.5% | E20: +6.4% | F20: n/a
A21: Latest subscription | B21: 0.40x (Day 1) | C21: n/a | D21: n/a | E21: 2.95x (Day 2) | F21: n/a
A22: Anchor book (₹ cr) | B22: 216 | C22: n/a | D22: n/a | E22: n/a | F22: 526.2
A24: OBSERVATIONS
A25: LUMINO INDUSTRIES has by far the largest revenue base (₹2,089 cr) but grew only ~7.3% at a 7.7% PAT margin — a low-margin infrastructure contractor, a fundamentally different proposition from ESDS. It also carries a ₹200 cr OFS (29% of the issue), so nearly a third of subscriber money goes to selling shareholders rather than the business. Its reported GMP of ₹56 against an ₹82 upper band implies +68% and an ~₹138 listing price — I regard this as unreliable, for the same reasons as the ESDS GMP.
A27: ANNU PROJECTS shows the best growth-to-size ratio (+34.1% revenue, +56.5% PAT, 13.5% margin) on a small ₹175 cr all-fresh issue, and is the only one with a meaningful subscription reading (2.95x on Day 2). It CLOSES TODAY — no time for the diligence it would deserve.
A29: PRIORITY JEWELS — financials [NA] entirely. I will not comment on an issue whose income statement I have not seen.
A31: SYMBIOTEC PHARMALAB closed on 27 August and lists 1 September. ₹1,607 cr of its ₹1,757 cr — 91% — was OFS, the structural opposite of ESDS.
A33: ON ISSUE STRUCTURE ALONE, ESDS IS THE MOST SHAREHOLDER-ALIGNED ISSUE IN THIS WINDOW. That is one input among many, but in a month where 91%-OFS issues are being sold, it deserves saying.

Sheet Verdict
A1: Verdict and investor decision table
A3: FOUR SEPARATE QUESTIONS, FOUR SEPARATE ANSWERS
A4: Question | B4: Verdict | C4: Key number | E4: Reasoning
A5: For listing gains | B5: APPLY WITH CAUTION | C5: =Sentiment!B6 | E5: Zero OFS, a fully-placed MF-heavy anchor book, a modest float and a defensible relative valuation support a positive debut. The +77% GMP does not. Apply for one lot; treat any premium as a windfall.
A6: For a 3–5 year hold | B6: NEUTRAL | C6: =Scenarios!C21 | E6: Genuine quality at a full price, with no cash-flow statement available and the decisive operating variable undisclosed. Better approached on the secondary market after two or three quarters of listed results. (Key number = base-case annualised return.)
A7: At ₹408 (lower band) | B7: APPLY WITH CAUTION | C7: =Valuation!B14 | E7: About 39.8x FY26 earnings — roughly at my fair-value midpoint of ₹390. Marginally acceptable.
A8: At ₹429 (upper band) | B8: LISTING GAINS ONLY | C8: =Valuation!C14 | E8: 41.6x, about 10% above my midpoint. Adequate for a flip; insufficient for a hold.
A10: HEADLINE NUMBERS — all live
A11: Metric | B11: Value | D11: Tag | E11: Note
A12: Market cap at ₹429 (₹ cr) | B12: =Valuation!C9 | D12: [C] | E12: Reproduces the reported ₹5,028 cr
A13: P/E at ₹429 | B13: =Valuation!C14 | D13: [C] | E13: Against a peer at 404x trailing / ~72x forward
A14: EV/EBITDA at ₹429 | B14: =Valuation!C15 | D14: [C] | E14: The more reliable anchor — above the depreciation line
A15: Fair value — midpoint (₹) | B15: ='Fair Value'!C22 | D15: [C] | E15: Triangulated across five methods
A16: Margin of safety at ₹408 | B16: =('Fair Value'!$C$22-Inputs!$C$5)/'Fair Value'!$C$22 | D16: [C] | E16: NEGATIVE
A17: Margin of safety at ₹429 | B17: =('Fair Value'!$C$22-Inputs!$C$6)/'Fair Value'!$C$22 | D17: [C] | E17: NEGATIVE
A18: Base-case annualised return | B18: =Scenarios!C21 | D18: [C] | E18: Over three years from the price under test
A19: ROE post-IPO pro forma | B19: =Financials!B42 | D19: [C] | E19: Falls from 25.1% the moment the money lands
A20: Derived D&A as % of revenue | B20: =Derivations!C11 | D20: [C] | E20: Low for five data centres — see Derivations
A21: New annual D&A from the capex (₹ cr) | B21: =Derivations!C37 | D21: [C] | E21: About twice the current charge
A22: Implied effective tax rate | B22: =Derivations!C27 | D22: [C] | E22: ABOVE statutory — argues against accounting flattery
A24: INVESTOR DECISION TABLE
A25: Question | B25: Answer
A26: Is the business fundamentally strong? | B26: YES, with a structural caveat — 32.78% ROCE and 49.6% EBITDA margin, but sub-scale at ~7 MW
A27: Is revenue growth attractive? | B27: YES — 30.6% CAGR over three years, verified and internally consistent
A28: Are profits high quality? | B28: PROBABLY — the derived ~32% effective tax rate argues against manipulation; unbilled revenue at 13.4% is a flag
A29: Is cash flow healthy? | B29: UNKNOWN — [NA]. Debt falling 63% is supportive indirect evidence; 79-day DSO is not.
A30: Is debt manageable? | B30: YES, comfortably — D/E 0.08, interest coverage ~35x, net-cash post-IPO
A31: Does the company have a moat? | B31: NARROW BUT REAL — regulatory and switching costs in sovereign/BFSI; none in general enterprise
A32: Is management trustworthy? | B32: EVIDENCE FAVOURABLE — 21-year record, zero OFS, deleveraged, declined a cheap 2021 IPO
A33: Is governance satisfactory? | B33: UNVERIFIED — no adverse findings, but my documentary evidence is FY22-vintage
A34: Is the industry attractive? | B34: YES — secular and legislation-backed; but consolidating around capital
A35: Is IPO valuation reasonable? | B35: FAIR, NOT CHEAP — 41.6x P/E, 21.9x EV/EBITDA; cheaper than the only listed peer
A36: Is there sufficient margin of safety? | B36: NO. −4.6% at ₹408, −10.0% at ₹429 against my ₹390 midpoint.
... A41: FINAL VERDICT | B41: APPLY / BUY WITH CAUTION — one lot for listing; revisit for investment after two quarters of disclosed results
A43: WHAT WOULD CHANGE THIS CONCLUSION
A44: Direction | B44: Trigger
A45: UPGRADE to BUY | B45: The RHP shows CFO/PAT above 1.0x for FY25 and FY26 — this single disclosure would move business quality from 6.6 to ~7.0 and remove my largest reservation
A46: UPGRADE to BUY | B46: QIB subscription exceeds 20x, confirming institutional conviction at ₹429
A47: UPGRADE to BUY | B47: Capacity utilisation is disclosed above 80%, indicating the new build addresses proven demand
A48: UPGRADE to BUY | B48: Contracted revenue or a committed order book for the new capacity is disclosed
...

Sheet Ten Things
A1: The ten things to know before applying
A3: 1 | B3: It is a 100% FRESH ISSUE WITH ZERO OFS. Every rupee goes to the company; the promoters sell nothing and dilute from 46.06% to ~39.5%. In a month where a ₹1,757 cr peer issue was 91% OFS, this is a genuinely strong alignment signal.
A7: 2 | B7: PROFIT GROWTH IS A MARGIN STORY, NOT A VOLUME STORY — AND MARGIN STORIES END. Revenue compounded at 30.6%; EBITDA at 107.6%. EBITDA margin went 12.3% to 49.6% in three years. It cannot go to 150%. Anyone extrapolating the +117% PAT growth is extrapolating an arithmetic impossibility.
A11: 3 | B11: PART OF THAT MARGIN IS A LEGACY-ASSET ARTEFACT THIS VERY IPO WILL UNWIND. Derived D&A is only ~12.5% of revenue — low for five data centres, and consistent with assets built years ago and largely written down. The ₹576 cr of new equipment adds ~₹96–115 cr of fresh annual depreciation, roughly 80–95% of all of FY26 PAT.
A15: 4 | B15: THE WHOLE INVESTMENT REDUCES TO ONE UNDISCLOSED NUMBER: CAPACITY UTILISATION. Doubling 7 MW to 14 MW is strongly accretive if filled and strongly dilutive if not. ESDS does not disclose it, and you cannot know it before applying.
A19: 5 | B19: ROE DROPS FROM 25.1% TO ABOUT 9.7% THE DAY THE MONEY LANDS. The raise nearly triples book value. The headline return ratio in the marketing will not exist by the December 2026 quarter.
A23: 6 | B23: THE CASH FLOW STATEMENT WAS UNAVAILABLE, AND THAT IS THE BIGGEST GAP IN THIS ANALYSIS. Receivables run at 79 days versus 25 for the listed peer, with ₹63.39 cr of unbilled revenue — roughly ₹165 cr, or 1.4x FY26 PAT, tied up in working capital. Debt falling 63% in two years is supportive indirect evidence, but it is not verification.
A27: 7 | B27: THE +77% GMP IS NOT CREDIBLE, AND THE DAY-1 BOOK QUIETLY SAYS SO. A ₹330 premium implies listing at roughly 72x FY26 earnings. Retail sat at 0.54x on Day 1. A genuinely expected 77% pop does not produce that book. The grey market for a ₹720 cr issue is thin and easily moved.
A31: 8 | B31: THE ANCHOR BOOK IS THE SIGNAL ACTUALLY WORTH WEIGHTING. ₹216 cr fully placed with 19 investors at the top of the band, 81.94% to domestic mutual funds across six fund houses — institutions that did real diligence and accepted a lock-in.
A35: 9 | B35: ESDS IS STRUCTURALLY SUB-SCALE, AND THE IPO DOES NOT FIX IT. At ~7 MW it holds well under 1% of Indian data-centre capacity while CtrlS, Nxtra and Yotta deploy in the hundreds of megawatts. Its defence is regulatory — sovereign and BFSI workloads offshore hyperscalers legally cannot take — covering 44.9% of revenue. The other 55.09% has no moat.
A39: 10 | B39: THERE IS NO MARGIN OF SAFETY AT EITHER END OF THE BAND. Fair value ₹330–450, midpoint ~₹390, against a band of ₹408–429 — −4.6% at the floor, −10.0% at the cap. My base case returns +0.9% per annum over three years. The business is good; the price already assumes it.

Sheet Sources
A1: Source appendix
A2: Analysis date: 28 August 2026. All sources retrieved on that date unless otherwise stated.
A4: PRIMARY SOURCES — REFERENCED BUT NOT ACCESSED
A5: These documents exist and are the correct authority. Network restrictions prevented opening any of them. Every figure attributed to them reached me via secondary reporting.
A6: Document | B6: Location | C6: Status
A7: RHP — ESDS Software Solution Ltd | B7: sebi.gov.in/filings/public-issues/aug-2026/esds-software-solution-limited-rhp_103893.html | C7: EGRESS_BLOCKED
A8: Abridged Prospectus | B8: sebi.gov.in/sebi_data/commondocs/aug-2026/ | C8: EGRESS_BLOCKED
A9: DRHP (filed 30 March 2025) | B9: bseindia.com/corporates/download/330873/ · esds.co.in/investors/pdf/ESDS_DRHP.pdf | C9: EGRESS_BLOCKED
A10: Annual Report FY22 | B10: esds.co.in/policies_document/Annual Reports/Annual Report-FY-22.pdf | C10: EGRESS_BLOCKED
